[2025-07-30T16:32:49Z] INFO bot [inst=DOGE-USDT-SWAP] [sess=22d61ff280694966bf46bae0acde1f54] [mode=START] [err=-]: ‚è≤Ô∏è Time offset set to -625 ms
[2025-07-30T16:32:50Z] INFO bot [inst=DOGE-USDT-SWAP] [sess=22d61ff280694966bf46bae0acde1f54] [mode=START] [err=-]: üìà Initial snapshot fetched
[2025-07-30T16:32:50Z] INFO bot [inst=DOGE-USDT-SWAP] [sess=22d61ff280694966bf46bae0acde1f54] [mode=REINVEST] [err=-]: [REINVEST] enabled=True, pct=90.00%, min_lot=0.01
[2025-07-30T16:32:50Z] INFO bot [inst=DOGE-USDT-SWAP] [sess=22d61ff280694966bf46bae0acde1f54] [mode=START] [err=-]: Orchestrator started
[2025-07-30T16:32:50Z] DEBUG bot [inst=DOGE-USDT-SWAP] [sess=22d61ff280694966bf46bae0acde1f54] [mode=-] [err=-]: üîÑ [REINVEST] waiting for TP fill event‚Ä¶
[2025-07-30T16:32:51Z] INFO bot [inst=DOGE-USDT-SWAP] [sess=22d61ff280694966bf46bae0acde1f54] [mode=STARTUP] [err=-]: Startup detected TWO legs ‚Üí enter TPSL mode
[2025-07-30T16:32:51Z] INFO bot [inst=DOGE-USDT-SWAP] [sess=22d61ff280694966bf46bae0acde1f54] [mode=ORCHESTRATOR] [err=-]: ‚Üí All legs closed ‚Üí back to ORDER mode
[2025-07-30T16:32:52Z] INFO bot [inst=DOGE-USDT-SWAP] [sess=22d61ff280694966bf46bae0acde1f54] [mode=WS] [err=-]: ‚úÖ [WS-PUB] subscribed to tickers
[2025-07-30T16:32:52Z] INFO bot [inst=DOGE-USDT-SWAP] [sess=22d61ff280694966bf46bae0acde1f54] [mode=WS] [err=-]: ‚úÖ [WS-PRIV] login successful
[2025-07-30T16:32:52Z] INFO bot [inst=DOGE-USDT-SWAP] [sess=22d61ff280694966bf46bae0acde1f54] [mode=WS] [err=-]: ‚úÖ [WS-PRIV] subscribed to orders
[2025-07-30T16:32:52Z] INFO bot [inst=DOGE-USDT-SWAP] [sess=22d61ff280694966bf46bae0acde1f54] [mode=WS] [err=-]: ‚úÖ [WS-PRIV] subscribed to positions
[2025-07-30T16:32:54Z] INFO bot [inst=DOGE-USDT-SWAP] [sess=22d61ff280694966bf46bae0acde1f54] [mode=TPSL] [err=-]: ‚Üí TPSL mode
[2025-07-30T16:33:51Z] INFO bot [inst=DOGE-USDT-SWAP] [sess=22d61ff280694966bf46bae0acde1f54] [mode=SHUTDOWN] [err=-]: Shutdown initiated
[2025-07-30T16:52:03Z] WARNING bot [inst=DOGE-USDT-SWAP] [sess=9cae2c2198174818912620acb545f32f] [mode=REST] [err=-]: Time sync failed: 
[2025-07-30T16:52:03Z] WARNING bot [inst=DOGE-USDT-SWAP] [sess=9cae2c2198174818912620acb545f32f] [mode=START] [err=-]: ‚è∞ Initial time sync failed: 
[2025-07-30T16:52:14Z] ERROR bot [inst=DOGE-USDT-SWAP] [sess=9cae2c2198174818912620acb545f32f] [mode=REST] [err=-]: Timeout GET https://www.okx.com/api/v5/market/books
Traceback (most recent call last):
  File "C:\Users\Professional\AppData\Local\Programs\Python\Python312\Lib\site-packages\aiohttp\client.py", line 663, in _request
    conn = await self._connector.connect(
           ^^^^^^^^^^^^^^^^^^^^^^^^^^^^^^
  File "C:\Users\Professional\AppData\Local\Programs\Python\Python312\Lib\site-packages\aiohttp\connector.py", line 538, in connect
    proto = await self._create_connection(req, traces, timeout)
            ^^^^^^^^^^^^^^^^^^^^^^^^^^^^^^^^^^^^^^^^^^^^^^^^^^^
  File "C:\Users\Professional\AppData\Local\Programs\Python\Python312\Lib\site-packages\aiohttp\connector.py", line 1050, in _create_connection
    _, proto = await self._create_direct_connection(req, traces, timeout)
               ^^^^^^^^^^^^^^^^^^^^^^^^^^^^^^^^^^^^^^^^^^^^^^^^^^^^^^^^^^
  File "C:\Users\Professional\AppData\Local\Programs\Python\Python312\Lib\site-packages\aiohttp\connector.py", line 1335, in _create_direct_connection
    hosts = await self._resolve_host(host, port, traces=traces)
            ^^^^^^^^^^^^^^^^^^^^^^^^^^^^^^^^^^^^^^^^^^^^^^^^^^^
  File "C:\Users\Professional\AppData\Local\Programs\Python\Python312\Lib\site-packages\aiohttp\connector.py", line 964, in _resolve_host
    await future
asyncio.exceptions.CancelledError

The above exception was the direct cause of the following exception:

Traceback (most recent call last):
  File "d:\Develop\Python\trade_bot\11.8.3\rest_client.py", line 138, in request
    async with self.session.request(
  File "C:\Users\Professional\AppData\Local\Programs\Python\Python312\Lib\site-packages\aiohttp\client.py", line 1360, in __aenter__
    self._resp: _RetType = await self._coro
                           ^^^^^^^^^^^^^^^^
  File "C:\Users\Professional\AppData\Local\Programs\Python\Python312\Lib\site-packages\aiohttp\client.py", line 578, in _request
    with timer:
  File "C:\Users\Professional\AppData\Local\Programs\Python\Python312\Lib\site-packages\aiohttp\helpers.py", line 749, in __exit__
    raise asyncio.TimeoutError from exc_val
TimeoutError
[2025-07-30T16:52:14Z] WARNING bot [inst=DOGE-USDT-SWAP] [sess=9cae2c2198174818912620acb545f32f] [mode=START] [err=-]: ‚ö†Ô∏è Initial snapshot failed: 
[2025-07-30T16:52:14Z] INFO bot [inst=DOGE-USDT-SWAP] [sess=9cae2c2198174818912620acb545f32f] [mode=START] [err=-]: Orchestrator started
[2025-07-30T16:52:14Z] DEBUG bot [inst=DOGE-USDT-SWAP] [sess=9cae2c2198174818912620acb545f32f] [mode=-] [err=-]: üîÑ [REINVEST] waiting for TP fill event‚Ä¶
[2025-07-30T16:52:15Z] INFO bot [inst=DOGE-USDT-SWAP] [sess=9cae2c2198174818912620acb545f32f] [mode=WS] [err=-]: ‚úÖ [WS-PUB] subscribed to tickers
[2025-07-30T16:52:15Z] INFO bot [inst=DOGE-USDT-SWAP] [sess=9cae2c2198174818912620acb545f32f] [mode=WS] [err=-]: ‚úÖ [WS-PRIV] login successful
[2025-07-30T16:52:15Z] INFO bot [inst=DOGE-USDT-SWAP] [sess=9cae2c2198174818912620acb545f32f] [mode=WS] [err=-]: ‚úÖ [WS-PRIV] subscribed to orders
[2025-07-30T16:52:16Z] INFO bot [inst=DOGE-USDT-SWAP] [sess=9cae2c2198174818912620acb545f32f] [mode=WS] [err=-]: ‚úÖ [WS-PRIV] subscribed to positions
[2025-07-30T16:52:24Z] WARNING bot [inst=DOGE-USDT-SWAP] [sess=9cae2c2198174818912620acb545f32f] [mode=REST] [err=-]: Time sync failed: 
[2025-07-30T16:52:25Z] ERROR bot [inst=DOGE-USDT-SWAP] [sess=9cae2c2198174818912620acb545f32f] [mode=REST] [err=-]: Timeout GET https://www.okx.com/api/v5/account/positions
Traceback (most recent call last):
  File "C:\Users\Professional\AppData\Local\Programs\Python\Python312\Lib\site-packages\aiohttp\client.py", line 663, in _request
    conn = await self._connector.connect(
           ^^^^^^^^^^^^^^^^^^^^^^^^^^^^^^
  File "C:\Users\Professional\AppData\Local\Programs\Python\Python312\Lib\site-packages\aiohttp\connector.py", line 538, in connect
    proto = await self._create_connection(req, traces, timeout)
            ^^^^^^^^^^^^^^^^^^^^^^^^^^^^^^^^^^^^^^^^^^^^^^^^^^^
  File "C:\Users\Professional\AppData\Local\Programs\Python\Python312\Lib\site-packages\aiohttp\connector.py", line 1050, in _create_connection
    _, proto = await self._create_direct_connection(req, traces, timeout)
               ^^^^^^^^^^^^^^^^^^^^^^^^^^^^^^^^^^^^^^^^^^^^^^^^^^^^^^^^^^
  File "C:\Users\Professional\AppData\Local\Programs\Python\Python312\Lib\site-packages\aiohttp\connector.py", line 1335, in _create_direct_connection
    hosts = await self._resolve_host(host, port, traces=traces)
            ^^^^^^^^^^^^^^^^^^^^^^^^^^^^^^^^^^^^^^^^^^^^^^^^^^^
  File "C:\Users\Professional\AppData\Local\Programs\Python\Python312\Lib\site-packages\aiohttp\connector.py", line 964, in _resolve_host
    await future
asyncio.exceptions.CancelledError

The above exception was the direct cause of the following exception:

Traceback (most recent call last):
  File "d:\Develop\Python\trade_bot\11.8.3\rest_client.py", line 138, in request
    async with self.session.request(
  File "C:\Users\Professional\AppData\Local\Programs\Python\Python312\Lib\site-packages\aiohttp\client.py", line 1360, in __aenter__
    self._resp: _RetType = await self._coro
                           ^^^^^^^^^^^^^^^^
  File "C:\Users\Professional\AppData\Local\Programs\Python\Python312\Lib\site-packages\aiohttp\client.py", line 578, in _request
    with timer:
  File "C:\Users\Professional\AppData\Local\Programs\Python\Python312\Lib\site-packages\aiohttp\helpers.py", line 749, in __exit__
    raise asyncio.TimeoutError from exc_val
TimeoutError
[2025-07-30T16:52:25Z] ERROR bot [inst=DOGE-USDT-SWAP] [sess=9cae2c2198174818912620acb545f32f] [mode=MAIN] [err=-]: üí• Fatal error: 
Traceback (most recent call last):
  File "C:\Users\Professional\AppData\Local\Programs\Python\Python312\Lib\site-packages\aiohttp\client.py", line 663, in _request
    conn = await self._connector.connect(
           ^^^^^^^^^^^^^^^^^^^^^^^^^^^^^^
  File "C:\Users\Professional\AppData\Local\Programs\Python\Python312\Lib\site-packages\aiohttp\connector.py", line 538, in connect
    proto = await self._create_connection(req, traces, timeout)
            ^^^^^^^^^^^^^^^^^^^^^^^^^^^^^^^^^^^^^^^^^^^^^^^^^^^
  File "C:\Users\Professional\AppData\Local\Programs\Python\Python312\Lib\site-packages\aiohttp\connector.py", line 1050, in _create_connection
    _, proto = await self._create_direct_connection(req, traces, timeout)
               ^^^^^^^^^^^^^^^^^^^^^^^^^^^^^^^^^^^^^^^^^^^^^^^^^^^^^^^^^^
  File "C:\Users\Professional\AppData\Local\Programs\Python\Python312\Lib\site-packages\aiohttp\connector.py", line 1335, in _create_direct_connection
    hosts = await self._resolve_host(host, port, traces=traces)
            ^^^^^^^^^^^^^^^^^^^^^^^^^^^^^^^^^^^^^^^^^^^^^^^^^^^
  File "C:\Users\Professional\AppData\Local\Programs\Python\Python312\Lib\site-packages\aiohttp\connector.py", line 964, in _resolve_host
    await future
asyncio.exceptions.CancelledError

The above exception was the direct cause of the following exception:

Traceback (most recent call last):
  File "d:\Develop\Python\trade_bot\11.8.3\main.py", line 107, in <module>
    asyncio.run(main())
  File "C:\Users\Professional\AppData\Local\Programs\Python\Python312\Lib\asyncio\runners.py", line 194, in run
    return runner.run(main)
           ^^^^^^^^^^^^^^^^
  File "C:\Users\Professional\AppData\Local\Programs\Python\Python312\Lib\asyncio\runners.py", line 118, in run
    return self._loop.run_until_complete(task)
           ^^^^^^^^^^^^^^^^^^^^^^^^^^^^^^^^^^^
  File "C:\Users\Professional\AppData\Local\Programs\Python\Python312\Lib\asyncio\base_events.py", line 687, in run_until_complete
    return future.result()
           ^^^^^^^^^^^^^^^
  File "d:\Develop\Python\trade_bot\11.8.3\main.py", line 98, in main
    await orchestrator.run()
  File "d:\Develop\Python\trade_bot\11.8.3\orchestrator.py", line 92, in run
    long_q, short_q = await self.get_positions_rest()
                      ^^^^^^^^^^^^^^^^^^^^^^^^^^^^^^^
  File "d:\Develop\Python\trade_bot\11.8.3\orchestrator.py", line 182, in get_positions_rest
    resp   = await self.rest.request(
             ^^^^^^^^^^^^^^^^^^^^^^^^
  File "d:\Develop\Python\trade_bot\11.8.3\rest_client.py", line 138, in request
    async with self.session.request(
  File "C:\Users\Professional\AppData\Local\Programs\Python\Python312\Lib\site-packages\aiohttp\client.py", line 1360, in __aenter__
    self._resp: _RetType = await self._coro
                           ^^^^^^^^^^^^^^^^
  File "C:\Users\Professional\AppData\Local\Programs\Python\Python312\Lib\site-packages\aiohttp\client.py", line 578, in _request
    with timer:
  File "C:\Users\Professional\AppData\Local\Programs\Python\Python312\Lib\site-packages\aiohttp\helpers.py", line 749, in __exit__
    raise asyncio.TimeoutError from exc_val
TimeoutError
[2025-07-30T17:03:58Z] INFO bot [inst=DOGE-USDT-SWAP] [sess=fc3791553e014723951413b05030bdd9] [mode=START] [err=-]: ‚è≤Ô∏è Time offset set to -610 ms
[2025-07-30T17:03:58Z] INFO bot [inst=DOGE-USDT-SWAP] [sess=fc3791553e014723951413b05030bdd9] [mode=START] [err=-]: üìà Initial snapshot fetched
[2025-07-30T17:03:58Z] INFO bot [inst=DOGE-USDT-SWAP] [sess=fc3791553e014723951413b05030bdd9] [mode=REINVEST] [err=-]: [REINVEST] enabled=True, pct=90.00%, min_lot=0.01
[2025-07-30T17:03:58Z] INFO bot [inst=DOGE-USDT-SWAP] [sess=fc3791553e014723951413b05030bdd9] [mode=START] [err=-]: Orchestrator started
[2025-07-30T17:03:58Z] DEBUG bot [inst=DOGE-USDT-SWAP] [sess=fc3791553e014723951413b05030bdd9] [mode=-] [err=-]: üîÑ [REINVEST] waiting for TP fill event‚Ä¶
[2025-07-30T17:03:59Z] INFO bot [inst=DOGE-USDT-SWAP] [sess=fc3791553e014723951413b05030bdd9] [mode=STARTUP] [err=-]: Startup detected TWO legs ‚Üí enter TPSL mode
[2025-07-30T17:03:59Z] INFO bot [inst=DOGE-USDT-SWAP] [sess=fc3791553e014723951413b05030bdd9] [mode=ORCHESTRATOR] [err=-]: ‚Üí All legs closed ‚Üí back to ORDER mode
[2025-07-30T17:04:00Z] INFO bot [inst=DOGE-USDT-SWAP] [sess=fc3791553e014723951413b05030bdd9] [mode=WS] [err=-]: ‚úÖ [WS-PRIV] login successful
[2025-07-30T17:04:00Z] INFO bot [inst=DOGE-USDT-SWAP] [sess=fc3791553e014723951413b05030bdd9] [mode=WS] [err=-]: ‚úÖ [WS-PUB] subscribed to tickers
[2025-07-30T17:04:00Z] INFO bot [inst=DOGE-USDT-SWAP] [sess=fc3791553e014723951413b05030bdd9] [mode=WS] [err=-]: ‚úÖ [WS-PRIV] subscribed to orders
[2025-07-30T17:04:00Z] INFO bot [inst=DOGE-USDT-SWAP] [sess=fc3791553e014723951413b05030bdd9] [mode=WS] [err=-]: ‚úÖ [WS-PRIV] subscribed to positions
[2025-07-30T17:04:02Z] INFO bot [inst=DOGE-USDT-SWAP] [sess=fc3791553e014723951413b05030bdd9] [mode=TPSL] [err=-]: ‚Üí TPSL mode
[2025-07-30T18:32:02Z] INFO bot [inst=DOGE-USDT-SWAP] [sess=fc3791553e014723951413b05030bdd9] [mode=WS] [err=-]: ‚úÖ [WS-PUB] subscribed to tickers
[2025-07-30T18:32:02Z] INFO bot [inst=DOGE-USDT-SWAP] [sess=fc3791553e014723951413b05030bdd9] [mode=WS] [err=-]: ‚úÖ [WS-PRIV] login successful
[2025-07-30T18:32:02Z] INFO bot [inst=DOGE-USDT-SWAP] [sess=fc3791553e014723951413b05030bdd9] [mode=WS] [err=-]: ‚úÖ [WS-PRIV] subscribed to orders
[2025-07-30T18:32:02Z] INFO bot [inst=DOGE-USDT-SWAP] [sess=fc3791553e014723951413b05030bdd9] [mode=WS] [err=-]: ‚úÖ [WS-PRIV] subscribed to positions
[2025-07-30T18:32:03Z] ERROR bot [inst=DOGE-USDT-SWAP] [sess=fc3791553e014723951413b05030bdd9] [mode=WS] [err=-]: üîÑ [WS-PRIV] Disconnected: Cannot connect to host wspap.okx.com:8443 ssl:default [Multiple exceptions: [Errno 10065] Connect call failed ('2606:4700:4400::ac40:9052', 8443, 0, 0), [Errno 10065] Connect call failed ('104.18.43.174', 8443)], retry in 1s
[2025-07-30T18:32:03Z] ERROR bot [inst=DOGE-USDT-SWAP] [sess=fc3791553e014723951413b05030bdd9] [mode=WS] [err=-]: üîÑ [WS-PUB] Disconnected: Cannot connect to host ws.okx.com:8443 ssl:default [Multiple exceptions: [Errno 10065] Connect call failed ('2606:4700:4400::ac40:9052', 8443, 0, 0), [Errno 10065] Connect call failed ('104.18.43.174', 8443)], retry in 1s
[2025-07-30T18:32:04Z] ERROR bot [inst=DOGE-USDT-SWAP] [sess=fc3791553e014723951413b05030bdd9] [mode=WS] [err=-]: üîÑ [WS-PRIV] Disconnected: Cannot connect to host wspap.okx.com:8443 ssl:default [Multiple exceptions: [Errno 10065] Connect call failed ('2606:4700:4400::ac40:9052', 8443, 0, 0), [Errno 10065] Connect call failed ('172.64.144.82', 8443)], retry in 2s
[2025-07-30T18:32:07Z] INFO bot [inst=DOGE-USDT-SWAP] [sess=fc3791553e014723951413b05030bdd9] [mode=WS] [err=-]: ‚úÖ [WS-PRIV] login successful
[2025-07-30T18:32:08Z] INFO bot [inst=DOGE-USDT-SWAP] [sess=fc3791553e014723951413b05030bdd9] [mode=WS] [err=-]: ‚úÖ [WS-PRIV] subscribed to orders
[2025-07-30T18:32:08Z] INFO bot [inst=DOGE-USDT-SWAP] [sess=fc3791553e014723951413b05030bdd9] [mode=WS] [err=-]: ‚úÖ [WS-PRIV] subscribed to positions
[2025-07-30T18:32:27Z] INFO bot [inst=DOGE-USDT-SWAP] [sess=fc3791553e014723951413b05030bdd9] [mode=WS] [err=-]: ‚úÖ [WS-PUB] subscribed to tickers
