[2025-08-05T00:19:20] ERROR bot [mode=REST] : API error code=1 response={'code': '1', 'data': [{'algoClOrdId': '', 'algoId': '', 'clOrdId': '', 'sCode': '51023', 'sMsg': "Position doesn't exist. ", 'tag': ''}], 'msg': ''}
[2025-08-05T00:19:20] ERROR bot [mode=-] : ❌ [TPSL] OCO(init) failed for LDOGEUSDTSWAP: API error 1
[2025-08-05T00:21:16] ERROR bot [mode=REST] : API error code=1 response={'code': '1', 'data': [{'algoClOrdId': '', 'algoId': '', 'clOrdId': '', 'sCode': '51023', 'sMsg': "Position doesn't exist. ", 'tag': ''}], 'msg': ''}
[2025-08-05T00:21:16] ERROR bot [mode=-] : ❌ [PreHEDGE] TP placement failed: API error 1
Traceback (most recent call last):
  File "d:\Develop\Python\trade_bot\11.9.1\core\prehedge_watcher.py", line 137, in _place_tp
    response = await self.rest.request(
               ^^^^^^^^^^^^^^^^^^^^^^^^
  File "d:\Develop\Python\trade_bot\11.9.1\core\rest_client.py", line 294, in request
    raise RuntimeError(f"API error {code}")
RuntimeError: API error 1
[2025-08-05T00:22:12] ERROR bot [mode=REST] : API error code=1 response={'code': '1', 'data': [{'algoClOrdId': '', 'algoId': '', 'clOrdId': '', 'sCode': '51023', 'sMsg': "Position doesn't exist. ", 'tag': ''}], 'msg': ''}
[2025-08-05T00:22:12] ERROR bot [mode=-] : ❌ [PreHEDGE] TP placement failed: API error 1
Traceback (most recent call last):
  File "d:\Develop\Python\trade_bot\11.9.1\core\prehedge_watcher.py", line 137, in _place_tp
    response = await self.rest.request(
               ^^^^^^^^^^^^^^^^^^^^^^^^
  File "d:\Develop\Python\trade_bot\11.9.1\core\rest_client.py", line 294, in request
    raise RuntimeError(f"API error {code}")
RuntimeError: API error 1
[2025-08-05T00:24:01] ERROR bot [mode=REST] : API error code=1 response={'code': '1', 'data': [{'algoClOrdId': '', 'algoId': '', 'clOrdId': '', 'sCode': '51023', 'sMsg': "Position doesn't exist. ", 'tag': ''}], 'msg': ''}
[2025-08-05T00:24:01] ERROR bot [mode=-] : ❌ [PreHEDGE] TP placement failed: API error 1
Traceback (most recent call last):
  File "d:\Develop\Python\trade_bot\11.9.1\core\prehedge_watcher.py", line 137, in _place_tp
    response = await self.rest.request(
               ^^^^^^^^^^^^^^^^^^^^^^^^
  File "d:\Develop\Python\trade_bot\11.9.1\core\rest_client.py", line 294, in request
    raise RuntimeError(f"API error {code}")
RuntimeError: API error 1
[2025-08-05T00:35:12] ERROR bot [mode=LOOP] : Loop-level exception
Traceback (most recent call last):
  File "d:\Develop\Python\trade_bot\11.9.1\core\prehedge_watcher.py", line 56, in run
    await self._place_tp()
  File "d:\Develop\Python\trade_bot\11.9.1\core\prehedge_watcher.py", line 107, in _place_tp
    raise ValueError("entry_price is None in _place_tp()")
ValueError: entry_price is None in _place_tp()
[2025-08-05T00:35:31] ERROR bot [mode=REST] : API error code=1 response={'code': '1', 'data': [{'algoClOrdId': '', 'algoId': '', 'clOrdId': '', 'sCode': '51023', 'sMsg': "Position doesn't exist. ", 'tag': ''}], 'msg': ''}
[2025-08-05T00:35:31] ERROR bot [mode=-] : ❌ [PreHEDGE] TP placement failed: API error 1
Traceback (most recent call last):
  File "d:\Develop\Python\trade_bot\11.9.1\core\prehedge_watcher.py", line 137, in _place_tp
    response = await self.rest.request(
               ^^^^^^^^^^^^^^^^^^^^^^^^
  File "d:\Develop\Python\trade_bot\11.9.1\core\rest_client.py", line 294, in request
    raise RuntimeError(f"API error {code}")
RuntimeError: API error 1
[2025-08-05T00:51:03] ERROR bot [mode=-] : ❌ [PreHEDGE] TP placement failed: code=-1, msg=
[2025-08-05T00:53:48] ERROR bot [mode=REST] : API error code=1 response={'code': '1', 'data': [{'algoClOrdId': '', 'algoId': '', 'clOrdId': '', 'sCode': '51023', 'sMsg': "Position doesn't exist. ", 'tag': ''}], 'msg': ''}
[2025-08-05T00:53:48] ERROR bot [mode=-] : ❌ [PreHEDGE] TP placement failed: API error 1
Traceback (most recent call last):
  File "d:\Develop\Python\trade_bot\11.9.1\core\prehedge_watcher.py", line 137, in _place_tp
    response = await self.rest.request(
               ^^^^^^^^^^^^^^^^^^^^^^^^
  File "d:\Develop\Python\trade_bot\11.9.1\core\rest_client.py", line 294, in request
    raise RuntimeError(f"API error {code}")
RuntimeError: API error 1
[2025-08-05T01:01:06] ERROR bot [mode=LOOP] : Loop-level exception
Traceback (most recent call last):
  File "d:\Develop\Python\trade_bot\11.9.1\core\prehedge_watcher.py", line 56, in run
    await self._place_tp()
  File "d:\Develop\Python\trade_bot\11.9.1\core\prehedge_watcher.py", line 107, in _place_tp
    raise ValueError("entry_price is None in _place_tp()")
ValueError: entry_price is None in _place_tp()
[2025-08-05T01:04:02] ERROR bot [mode=LOOP] : Loop-level exception
Traceback (most recent call last):
  File "d:\Develop\Python\trade_bot\11.9.1\core\prehedge_watcher.py", line 56, in run
    await self._place_tp()
  File "d:\Develop\Python\trade_bot\11.9.1\core\prehedge_watcher.py", line 107, in _place_tp
    raise ValueError("entry_price is None in _place_tp()")
ValueError: entry_price is None in _place_tp()
[2025-08-05T01:04:02] ERROR bot [mode=-] : ❌ [PreHEDGE] TP placement failed: code=-1, msg=
[2025-08-05T01:19:11] ERROR bot [mode=-] : ❌ [PreHEDGE] TP placement failed: code=-1, msg=
[2025-08-05T01:20:13] ERROR bot [mode=-] : ❌ [PreHEDGE] TP placement failed: code=-1, msg=
[2025-08-05T01:34:57] ERROR bot [mode=LOOP] : Loop-level exception
Traceback (most recent call last):
  File "d:\Develop\Python\trade_bot\11.9.1\core\prehedge_watcher.py", line 56, in run
    await self._place_tp()
  File "d:\Develop\Python\trade_bot\11.9.1\core\prehedge_watcher.py", line 107, in _place_tp
    raise ValueError("entry_price is None in _place_tp()")
ValueError: entry_price is None in _place_tp()
[2025-08-05T01:34:58] ERROR bot [mode=-] : ❌ [PreHEDGE] TP placement failed: code=-1, msg=
[2025-08-05T01:34:59] ERROR bot [mode=-] : ❌ [PreHEDGE] TP placement failed: code=-1, msg=
[2025-08-05T01:35:00] ERROR bot [mode=-] : ❌ [PreHEDGE] TP placement failed: code=-1, msg=
[2025-08-05T01:35:01] ERROR bot [mode=-] : ❌ [PreHEDGE] TP placement failed: code=-1, msg=
[2025-08-05T01:35:02] ERROR bot [mode=-] : ❌ [PreHEDGE] TP placement failed: code=-1, msg=
[2025-08-05T01:35:03] ERROR bot [mode=-] : ❌ [PreHEDGE] TP placement failed: code=-1, msg=
[2025-08-05T01:35:05] ERROR bot [mode=LOOP] : Loop-level exception
Traceback (most recent call last):
  File "d:\Develop\Python\trade_bot\11.9.1\core\prehedge_watcher.py", line 66, in run
    await self.hedge_manager.run()
  File "d:\Develop\Python\trade_bot\11.9.1\core\hedge.py", line 114, in run
    rest_long, rest_short = await self._get_rest_positions()
                            ^^^^^^^^^^^^^^^^^^^^^^^^^^^^^^^^
  File "d:\Develop\Python\trade_bot\11.9.1\core\hedge.py", line 148, in _get_rest_positions
    resp = await self.rest.request(
           ^^^^^^^^^^^^^^^^^^^^^^^^
  File "d:\Develop\Python\trade_bot\11.9.1\core\rest_client.py", line 206, in request
    async with self.session.request(
  File "C:\Users\Professional\AppData\Local\Programs\Python\Python312\Lib\site-packages\aiohttp\client.py", line 1360, in __aenter__
    self._resp: _RetType = await self._coro
                           ^^^^^^^^^^^^^^^^
  File "C:\Users\Professional\AppData\Local\Programs\Python\Python312\Lib\site-packages\aiohttp\client.py", line 663, in _request
    conn = await self._connector.connect(
                 ^^^^^^^^^^^^^^^^^^^^^^^
AttributeError: 'NoneType' object has no attribute 'connect'
[2025-08-05T01:35:05] ERROR bot [mode=LOOP] : Loop-level exception
Traceback (most recent call last):
  File "d:\Develop\Python\trade_bot\11.9.1\core\prehedge_watcher.py", line 66, in run
    await self.hedge_manager.run()
  File "d:\Develop\Python\trade_bot\11.9.1\core\hedge.py", line 114, in run
    rest_long, rest_short = await self._get_rest_positions()
                            ^^^^^^^^^^^^^^^^^^^^^^^^^^^^^^^^
  File "d:\Develop\Python\trade_bot\11.9.1\core\hedge.py", line 148, in _get_rest_positions
    resp = await self.rest.request(
           ^^^^^^^^^^^^^^^^^^^^^^^^
  File "d:\Develop\Python\trade_bot\11.9.1\core\rest_client.py", line 206, in request
    async with self.session.request(
  File "C:\Users\Professional\AppData\Local\Programs\Python\Python312\Lib\site-packages\aiohttp\client.py", line 1360, in __aenter__
    self._resp: _RetType = await self._coro
                           ^^^^^^^^^^^^^^^^
  File "C:\Users\Professional\AppData\Local\Programs\Python\Python312\Lib\site-packages\aiohttp\client.py", line 663, in _request
    conn = await self._connector.connect(
                 ^^^^^^^^^^^^^^^^^^^^^^^
AttributeError: 'NoneType' object has no attribute 'connect'
[2025-08-05T01:35:05] ERROR bot [mode=LOOP] : Loop-level exception
Traceback (most recent call last):
  File "d:\Develop\Python\trade_bot\11.9.1\core\prehedge_watcher.py", line 66, in run
    await self.hedge_manager.run()
  File "d:\Develop\Python\trade_bot\11.9.1\core\hedge.py", line 114, in run
    rest_long, rest_short = await self._get_rest_positions()
                            ^^^^^^^^^^^^^^^^^^^^^^^^^^^^^^^^
  File "d:\Develop\Python\trade_bot\11.9.1\core\hedge.py", line 148, in _get_rest_positions
    resp = await self.rest.request(
           ^^^^^^^^^^^^^^^^^^^^^^^^
  File "d:\Develop\Python\trade_bot\11.9.1\core\rest_client.py", line 206, in request
    async with self.session.request(
  File "C:\Users\Professional\AppData\Local\Programs\Python\Python312\Lib\site-packages\aiohttp\client.py", line 1360, in __aenter__
    self._resp: _RetType = await self._coro
                           ^^^^^^^^^^^^^^^^
  File "C:\Users\Professional\AppData\Local\Programs\Python\Python312\Lib\site-packages\aiohttp\client.py", line 493, in _request
    raise RuntimeError("Session is closed")
RuntimeError: Session is closed
[2025-08-05T01:35:05] ERROR bot [mode=HEDGE] : ❌ [HEDGE] place hedge failed: Session is closed
Traceback (most recent call last):
  File "d:\Develop\Python\trade_bot\11.9.1\core\hedge.py", line 84, in run
    resp = await self.rest.request(
           ^^^^^^^^^^^^^^^^^^^^^^^^
  File "d:\Develop\Python\trade_bot\11.9.1\core\rest_client.py", line 206, in request
    async with self.session.request(
  File "C:\Users\Professional\AppData\Local\Programs\Python\Python312\Lib\site-packages\aiohttp\client.py", line 1360, in __aenter__
    self._resp: _RetType = await self._coro
                           ^^^^^^^^^^^^^^^^
  File "C:\Users\Professional\AppData\Local\Programs\Python\Python312\Lib\site-packages\aiohttp\client.py", line 493, in _request
    raise RuntimeError("Session is closed")
RuntimeError: Session is closed
[2025-08-05T01:35:05] ERROR bot [mode=LOOP] : Loop-level exception
Traceback (most recent call last):
  File "d:\Develop\Python\trade_bot\11.9.1\core\prehedge_watcher.py", line 66, in run
    await self.hedge_manager.run()
  File "d:\Develop\Python\trade_bot\11.9.1\core\hedge.py", line 114, in run
    rest_long, rest_short = await self._get_rest_positions()
                            ^^^^^^^^^^^^^^^^^^^^^^^^^^^^^^^^
  File "d:\Develop\Python\trade_bot\11.9.1\core\hedge.py", line 148, in _get_rest_positions
    resp = await self.rest.request(
           ^^^^^^^^^^^^^^^^^^^^^^^^
  File "d:\Develop\Python\trade_bot\11.9.1\core\rest_client.py", line 206, in request
    async with self.session.request(
  File "C:\Users\Professional\AppData\Local\Programs\Python\Python312\Lib\site-packages\aiohttp\client.py", line 1360, in __aenter__
    self._resp: _RetType = await self._coro
                           ^^^^^^^^^^^^^^^^
  File "C:\Users\Professional\AppData\Local\Programs\Python\Python312\Lib\site-packages\aiohttp\client.py", line 493, in _request
    raise RuntimeError("Session is closed")
RuntimeError: Session is closed
[2025-08-05T01:39:39] ERROR bot [mode=-] : ❌ [PreHEDGE] TP placement failed: code=-1, msg=
[2025-08-05T01:39:40] ERROR bot [mode=-] : ❌ [PreHEDGE] TP placement failed: code=-1, msg=
[2025-08-05T01:39:41] ERROR bot [mode=-] : ❌ [PreHEDGE] TP placement failed: code=-1, msg=
[2025-08-05T01:39:42] ERROR bot [mode=-] : ❌ [PreHEDGE] TP placement failed: code=-1, msg=
[2025-08-05T01:39:44] ERROR bot [mode=HEDGE] : ❌ [HEDGE] place hedge failed: [Errno 1] [SSL: APPLICATION_DATA_AFTER_CLOSE_NOTIFY] application data after close notify (_ssl.c:2685)
Traceback (most recent call last):
  File "C:\Users\Professional\AppData\Local\Programs\Python\Python312\Lib\asyncio\sslproto.py", line 648, in _do_shutdown
    self._sslobj.unwrap()
  File "C:\Users\Professional\AppData\Local\Programs\Python\Python312\Lib\ssl.py", line 921, in unwrap
    return self._sslobj.shutdown()
           ^^^^^^^^^^^^^^^^^^^^^^^
ssl.SSLError: [SSL: APPLICATION_DATA_AFTER_CLOSE_NOTIFY] application data after close notify (_ssl.c:2685)

The above exception was the direct cause of the following exception:

Traceback (most recent call last):
  File "d:\Develop\Python\trade_bot\11.9.1\core\hedge.py", line 84, in run
    resp = await self.rest.request(
           ^^^^^^^^^^^^^^^^^^^^^^^^
  File "d:\Develop\Python\trade_bot\11.9.1\core\rest_client.py", line 206, in request
    async with self.session.request(
  File "C:\Users\Professional\AppData\Local\Programs\Python\Python312\Lib\site-packages\aiohttp\client.py", line 1360, in __aenter__
    self._resp: _RetType = await self._coro
                           ^^^^^^^^^^^^^^^^
  File "C:\Users\Professional\AppData\Local\Programs\Python\Python312\Lib\site-packages\aiohttp\client.py", line 690, in _request
    await resp.start(conn)
  File "C:\Users\Professional\AppData\Local\Programs\Python\Python312\Lib\site-packages\aiohttp\client_reqrep.py", line 1059, in start
    message, payload = await protocol.read()  # type: ignore[union-attr]
                       ^^^^^^^^^^^^^^^^^^^^^
  File "C:\Users\Professional\AppData\Local\Programs\Python\Python312\Lib\site-packages\aiohttp\streams.py", line 644, in read
    await self._waiter
aiohttp.client_exceptions.ClientOSError: [Errno 1] [SSL: APPLICATION_DATA_AFTER_CLOSE_NOTIFY] application data after close notify (_ssl.c:2685)
[2025-08-05T01:46:36] ERROR bot [mode=-] : ❌ [PreHEDGE] TP placement failed: code=-1, msg=
[2025-08-05T01:48:49] ERROR bot [mode=-] : ❌ [PreHEDGE] TP placement failed: code=-1, msg=
[2025-08-05T01:50:34] ERROR bot [mode=-] : ❌ [PreHEDGE] TP placement failed: code=-1, msg=
[2025-08-05T01:51:12] ERROR bot [mode=-] : ❌ [PreHEDGE] TP placement failed: code=-1, msg=
[2025-08-05T01:51:58] ERROR bot [mode=-] : ❌ [PreHEDGE] TP placement failed: code=-1, msg=
[2025-08-05T01:55:35] ERROR bot [mode=-] : ❌ [PreHEDGE] TP placement failed: code=-1, msg=
[2025-08-05T03:48:57] ERROR bot [mode=-] : ❌ [PreHEDGE] TP placement failed: code=-1, msg=
[2025-08-05T03:49:40] ERROR bot [mode=-] : ❌ [PreHEDGE] TP placement failed: code=-1, msg=
[2025-08-05T05:02:37] ERROR bot [mode=-] : ❌ [PreHEDGE] TP placement failed: code=-1, msg=
[2025-08-05T12:13:16] ERROR bot [mode=-] : ❌ [PreHEDGE] TP placement failed: code=-1, msg=
[2025-08-05T12:13:27] ERROR bot [mode=-] : ❌ [PreHEDGE] TP placement failed: code=-1, msg=
[2025-08-05T12:13:37] ERROR bot [mode=-] : ❌ [PreHEDGE] TP placement failed: code=-1, msg=
[2025-08-05T12:13:47] ERROR bot [mode=-] : ❌ [PreHEDGE] TP placement failed: code=-1, msg=
[2025-08-05T13:01:50] ERROR bot [mode=-] : ❌ [PreHEDGE] TP placement failed: code=-1, msg=
[2025-08-05T15:39:57] ERROR bot [mode=LOOP] : Loop-level exception
Traceback (most recent call last):
  File "d:\Develop\Python\trade_bot\11.9.1\core\orchestrator.py", line 228, in _reinvest_loop
    await self.reinvestor.handle_tp_fill((ep, eq, Decimal(str(tp_price))))
  File "d:\Develop\Python\trade_bot\11.9.1\core\reinvest.py", line 43, in handle_tp_fill
    await self._do_reinvest(snapshot)
  File "d:\Develop\Python\trade_bot\11.9.1\core\reinvest.py", line 77, in _do_reinvest
    if mark <= 0:
       ^^^^^^^^^
TypeError: '<=' not supported between instances of 'coroutine' and 'int'
[2025-08-05T15:39:58] ERROR bot [mode=-] : ❌ [PreHEDGE] TP placement failed: code=-1, msg=
[2025-08-05T17:34:43] ERROR bot [mode=REST] : API error code=1 response={'code': '1', 'data': [{'algoClOrdId': '', 'algoId': '', 'clOrdId': '', 'sCode': '51023', 'sMsg': "Position doesn't exist. ", 'tag': ''}], 'msg': ''}
[2025-08-05T17:34:43] ERROR bot [mode=-] : ❌ [TPSL] OCO(init) failed for SDOGEUSDTSWAP: API error 1
[2025-08-05T17:34:49] ERROR bot [mode=REST] : API error code=1 response={'code': '1', 'data': [{'clOrdId': '', 'ordId': '', 'sCode': '51008', 'sMsg': 'Order failed. Insufficient USDT margin in account ', 'tag': '', 'ts': '1754404489420'}], 'inTime': '1754404489419459', 'msg': 'All operations failed', 'outTime': '1754404489422080'}
[2025-08-05T17:34:49] ERROR bot [mode=HEDGE] : ❌ [HEDGE] place hedge failed: API error 1
Traceback (most recent call last):
  File "d:\Develop\Python\trade_bot\11.9.1\core\hedge.py", line 84, in run
    resp = await self.rest.request(
           ^^^^^^^^^^^^^^^^^^^^^^^^
  File "d:\Develop\Python\trade_bot\11.9.1\core\rest_client.py", line 294, in request
    raise RuntimeError(f"API error {code}")
RuntimeError: API error 1
[2025-08-05T17:34:50] ERROR bot [mode=-] : ❌ [PreHEDGE] TP placement failed: code=-1, msg=
[2025-08-05T17:34:53] ERROR bot [mode=REST] : API error code=1 response={'code': '1', 'data': [{'clOrdId': '', 'ordId': '', 'sCode': '51008', 'sMsg': 'Order failed. Insufficient USDT margin in account ', 'tag': '', 'ts': '1754404493975'}], 'inTime': '1754404493974283', 'msg': 'All operations failed', 'outTime': '1754404493977087'}
[2025-08-05T17:34:53] ERROR bot [mode=HEDGE] : ❌ [HEDGE] place hedge failed: API error 1
Traceback (most recent call last):
  File "d:\Develop\Python\trade_bot\11.9.1\core\hedge.py", line 84, in run
    resp = await self.rest.request(
           ^^^^^^^^^^^^^^^^^^^^^^^^
  File "d:\Develop\Python\trade_bot\11.9.1\core\rest_client.py", line 294, in request
    raise RuntimeError(f"API error {code}")
RuntimeError: API error 1
[2025-08-05T17:34:54] ERROR bot [mode=-] : ❌ [PreHEDGE] TP placement failed: code=-1, msg=
[2025-08-05T19:45:47] ERROR bot [mode=REST] : [TimeoutError] GET https://www.okx.com/api/v5/account/positions, attempt 1/4, sleeping 1.1s before retry
Traceback (most recent call last):
  File "C:\Users\Professional\AppData\Local\Programs\Python\Python312\Lib\site-packages\aiohttp\client.py", line 663, in _request
    conn = await self._connector.connect(
           ^^^^^^^^^^^^^^^^^^^^^^^^^^^^^^
  File "C:\Users\Professional\AppData\Local\Programs\Python\Python312\Lib\site-packages\aiohttp\connector.py", line 538, in connect
    proto = await self._create_connection(req, traces, timeout)
            ^^^^^^^^^^^^^^^^^^^^^^^^^^^^^^^^^^^^^^^^^^^^^^^^^^^
  File "C:\Users\Professional\AppData\Local\Programs\Python\Python312\Lib\site-packages\aiohttp\connector.py", line 1050, in _create_connection
    _, proto = await self._create_direct_connection(req, traces, timeout)
               ^^^^^^^^^^^^^^^^^^^^^^^^^^^^^^^^^^^^^^^^^^^^^^^^^^^^^^^^^^
  File "C:\Users\Professional\AppData\Local\Programs\Python\Python312\Lib\site-packages\aiohttp\connector.py", line 1353, in _create_direct_connection
    transp, proto = await self._wrap_create_connection(
                    ^^^^^^^^^^^^^^^^^^^^^^^^^^^^^^^^^^^
  File "C:\Users\Professional\AppData\Local\Programs\Python\Python312\Lib\site-packages\aiohttp\connector.py", line 1109, in _wrap_create_connection
    sock = await aiohappyeyeballs.start_connection(
           ^^^^^^^^^^^^^^^^^^^^^^^^^^^^^^^^^^^^^^^^
  File "C:\Users\Professional\AppData\Local\Programs\Python\Python312\Lib\site-packages\aiohappyeyeballs\impl.py", line 87, in start_connection
    sock, _, _ = await _staggered.staggered_race(
                 ^^^^^^^^^^^^^^^^^^^^^^^^^^^^^^^^
  File "C:\Users\Professional\AppData\Local\Programs\Python\Python312\Lib\site-packages\aiohappyeyeballs\_staggered.py", line 165, in staggered_race
    done = await _wait_one(
           ^^^^^^^^^^^^^^^^
  File "C:\Users\Professional\AppData\Local\Programs\Python\Python312\Lib\site-packages\aiohappyeyeballs\_staggered.py", line 46, in _wait_one
    return await wait_next
           ^^^^^^^^^^^^^^^
asyncio.exceptions.CancelledError

The above exception was the direct cause of the following exception:

Traceback (most recent call last):
  File "d:\Develop\Python\trade_bot\11.9.1\core\rest_client.py", line 206, in request
    async with self.session.request(
  File "C:\Users\Professional\AppData\Local\Programs\Python\Python312\Lib\site-packages\aiohttp\client.py", line 1360, in __aenter__
    self._resp: _RetType = await self._coro
                           ^^^^^^^^^^^^^^^^
  File "C:\Users\Professional\AppData\Local\Programs\Python\Python312\Lib\site-packages\aiohttp\client.py", line 578, in _request
    with timer:
  File "C:\Users\Professional\AppData\Local\Programs\Python\Python312\Lib\site-packages\aiohttp\helpers.py", line 749, in __exit__
    raise asyncio.TimeoutError from exc_val
TimeoutError
[2025-08-05T21:09:34] ERROR bot [mode=MAIN] : 💥 Fatal error: 'NoneType' object has no attribute 'connect'
Traceback (most recent call last):
  File "d:\Develop\Python\trade_bot\11.9.1\main.py", line 139, in <module>
    asyncio.run(main())
  File "C:\Users\Professional\AppData\Local\Programs\Python\Python312\Lib\asyncio\runners.py", line 194, in run
    return runner.run(main)
           ^^^^^^^^^^^^^^^^
  File "C:\Users\Professional\AppData\Local\Programs\Python\Python312\Lib\asyncio\runners.py", line 118, in run
    return self._loop.run_until_complete(task)
           ^^^^^^^^^^^^^^^^^^^^^^^^^^^^^^^^^^^
  File "C:\Users\Professional\AppData\Local\Programs\Python\Python312\Lib\asyncio\base_events.py", line 687, in run_until_complete
    return future.result()
           ^^^^^^^^^^^^^^^
  File "d:\Develop\Python\trade_bot\11.9.1\main.py", line 107, in main
    await orchestrator.run()
  File "d:\Develop\Python\trade_bot\11.9.1\core\orchestrator.py", line 110, in run
    snap = await self.snapshot.sync_from_rest()
    ^^^^^^^^^^^^^^^^^^^^^^^^^^^^^^^^^^^^
  File "d:\Develop\Python\trade_bot\11.9.1\core\position_snapshot.py", line 35, in sync_from_rest
    await self._fetch_and_store()
  File "d:\Develop\Python\trade_bot\11.9.1\core\position_snapshot.py", line 53, in _fetch_and_store
    long_q, long_px = await self._rest_position("long")
                      ^^^^^^^^^^^^^^^^^^^^^^^^^^^^^^^^^
  File "d:\Develop\Python\trade_bot\11.9.1\core\position_snapshot.py", line 76, in _rest_position
    resp = await self.rest.request(
           ^^^^^^^^^^^^^^^^^^^^^^^^
  File "d:\Develop\Python\trade_bot\11.9.1\core\rest_client.py", line 206, in request
    async with self.session.request(
  File "C:\Users\Professional\AppData\Local\Programs\Python\Python312\Lib\site-packages\aiohttp\client.py", line 1360, in __aenter__
    self._resp: _RetType = await self._coro
                           ^^^^^^^^^^^^^^^^
  File "C:\Users\Professional\AppData\Local\Programs\Python\Python312\Lib\site-packages\aiohttp\client.py", line 663, in _request
    conn = await self._connector.connect(
                 ^^^^^^^^^^^^^^^^^^^^^^^
AttributeError: 'NoneType' object has no attribute 'connect'
[2025-08-05T21:28:49] ERROR bot [mode=MAIN] : 💥 Fatal error: 'NoneType' object has no attribute 'connect'
Traceback (most recent call last):
  File "d:\Develop\Python\trade_bot\11.9.1\main.py", line 139, in <module>
    asyncio.run(main())
  File "C:\Users\Professional\AppData\Local\Programs\Python\Python312\Lib\asyncio\runners.py", line 194, in run
    return runner.run(main)
           ^^^^^^^^^^^^^^^^
  File "C:\Users\Professional\AppData\Local\Programs\Python\Python312\Lib\asyncio\runners.py", line 118, in run
    return self._loop.run_until_complete(task)
           ^^^^^^^^^^^^^^^^^^^^^^^^^^^^^^^^^^^
  File "C:\Users\Professional\AppData\Local\Programs\Python\Python312\Lib\asyncio\base_events.py", line 687, in run_until_complete
    return future.result()
           ^^^^^^^^^^^^^^^
  File "d:\Develop\Python\trade_bot\11.9.1\main.py", line 107, in main
    await orchestrator.run()
  File "d:\Develop\Python\trade_bot\11.9.1\core\orchestrator.py", line 110, in run
    snap = await self.snapshot.sync_from_rest()
    ^^^^^^^^^^^^^^^^^^^^^^^^^^^^^^^^^^^^
  File "d:\Develop\Python\trade_bot\11.9.1\core\position_snapshot.py", line 35, in sync_from_rest
    await self._fetch_and_store()
  File "d:\Develop\Python\trade_bot\11.9.1\core\position_snapshot.py", line 53, in _fetch_and_store
    long_q, long_px = await self._rest_position("long")
                      ^^^^^^^^^^^^^^^^^^^^^^^^^^^^^^^^^
  File "d:\Develop\Python\trade_bot\11.9.1\core\position_snapshot.py", line 79, in _rest_position
    resp = await self.rest.request(
           ^^^^^^^^^^^^^^^^^^^^^^^^
  File "d:\Develop\Python\trade_bot\11.9.1\core\rest_client.py", line 206, in request
    async with self.session.request(
  File "C:\Users\Professional\AppData\Local\Programs\Python\Python312\Lib\site-packages\aiohttp\client.py", line 1360, in __aenter__
    self._resp: _RetType = await self._coro
                           ^^^^^^^^^^^^^^^^
  File "C:\Users\Professional\AppData\Local\Programs\Python\Python312\Lib\site-packages\aiohttp\client.py", line 663, in _request
    conn = await self._connector.connect(
                 ^^^^^^^^^^^^^^^^^^^^^^^
AttributeError: 'NoneType' object has no attribute 'connect'
[2025-08-05T21:31:44] ERROR bot [mode=-] : ❌ [TPSL] OCO(init) failed for LDOGEUSDTSWAP: [Errno 1] [SSL: APPLICATION_DATA_AFTER_CLOSE_NOTIFY] application data after close notify (_ssl.c:2685)
[2025-08-05T21:31:44] ERROR bot [mode=-] : ❌ [TPSL] conditional failed for SDOGEUSDTSWAP: Session is closed
[2025-08-05T21:38:58] ERROR bot [mode=MAIN] : 💥 Fatal error: 'NoneType' object has no attribute 'connect'
Traceback (most recent call last):
  File "d:\Develop\Python\trade_bot\11.9.1\main.py", line 139, in <module>
    asyncio.run(main())
  File "C:\Users\Professional\AppData\Local\Programs\Python\Python312\Lib\asyncio\runners.py", line 194, in run
    return runner.run(main)
           ^^^^^^^^^^^^^^^^
  File "C:\Users\Professional\AppData\Local\Programs\Python\Python312\Lib\asyncio\runners.py", line 118, in run
    return self._loop.run_until_complete(task)
           ^^^^^^^^^^^^^^^^^^^^^^^^^^^^^^^^^^^
  File "C:\Users\Professional\AppData\Local\Programs\Python\Python312\Lib\asyncio\base_events.py", line 687, in run_until_complete
    return future.result()
           ^^^^^^^^^^^^^^^
  File "d:\Develop\Python\trade_bot\11.9.1\main.py", line 107, in main
    await orchestrator.run()
  File "d:\Develop\Python\trade_bot\11.9.1\core\orchestrator.py", line 110, in run
    snap = await self.snapshot.sync_from_rest()
    ^^^^^^^^^^^^^^^^^^^^^^^^^^^^^^^^^^^^
  File "d:\Develop\Python\trade_bot\11.9.1\core\position_snapshot.py", line 35, in sync_from_rest
    await self._fetch_and_store()
  File "d:\Develop\Python\trade_bot\11.9.1\core\position_snapshot.py", line 53, in _fetch_and_store
    long_q, long_px = await self._rest_position("long")
                      ^^^^^^^^^^^^^^^^^^^^^^^^^^^^^^^^^
  File "d:\Develop\Python\trade_bot\11.9.1\core\position_snapshot.py", line 85, in _rest_position
    resp = await self.rest.request(
           ^^^^^^^^^^^^^^^^^^^^^^^^
  File "d:\Develop\Python\trade_bot\11.9.1\core\rest_client.py", line 206, in request
    async with self.session.request(
  File "C:\Users\Professional\AppData\Local\Programs\Python\Python312\Lib\site-packages\aiohttp\client.py", line 1360, in __aenter__
    self._resp: _RetType = await self._coro
                           ^^^^^^^^^^^^^^^^
  File "C:\Users\Professional\AppData\Local\Programs\Python\Python312\Lib\site-packages\aiohttp\client.py", line 663, in _request
    conn = await self._connector.connect(
                 ^^^^^^^^^^^^^^^^^^^^^^^
AttributeError: 'NoneType' object has no attribute 'connect'
