[2025-07-18T19:53:44Z] ERROR bot [inst=DOGE-USDT-SWAP] [sess=ab961dc9f03e4c9087458029e5cca812] [mode=REST] [err=50113]: API error code=50113 response={'msg': 'Invalid Sign', 'code': '50113'}
[2025-07-18T19:53:44Z] ERROR bot [inst=DOGE-USDT-SWAP] [sess=ab961dc9f03e4c9087458029e5cca812] [mode=ORDER] [err=-]: ❌ [OrderMode] place error: API error 50113
[2025-07-18T19:53:44Z] ERROR bot [inst=DOGE-USDT-SWAP] [sess=ab961dc9f03e4c9087458029e5cca812] [mode=REST] [err=50113]: API error code=50113 response={'msg': 'Invalid Sign', 'code': '50113'}
[2025-07-18T19:58:59Z] ERROR bot [inst=DOGE-USDT-SWAP] [sess=ba23a8e0d9d34289bc865eade68bc4da] [mode=-] [err=-]: ❌ [TPSL] loop error: float division by zero
Traceback (most recent call last):
  File "d:\Develop\Python\trade_bot\11.8.3\tpsl_monitor.py", line 112, in _loop
    abs(current.get(cid_init, 0)  - tp_init)  / tp_init  > self.threshold
    ~~~~~~~~~~~~~~~~~~~~~~~~~~~~~~~~~~~~~~~~~~^~~~~~~~~
ZeroDivisionError: float division by zero
[2025-07-18T20:01:08Z] ERROR bot [inst=DOGE-USDT-SWAP] [sess=ba23a8e0d9d34289bc865eade68bc4da] [mode=REST] [err=1]: API error code=1 response={'code': '1', 'data': [{'algoClOrdId': '', 'algoId': '', 'clOrdId': '', 'sCode': '51279', 'sMsg': 'TP trigger price cannot be lower than the last price ', 'tag': ''}], 'msg': ''}
[2025-07-18T20:01:08Z] ERROR bot [inst=DOGE-USDT-SWAP] [sess=ba23a8e0d9d34289bc865eade68bc4da] [mode=-] [err=-]: ❌ [TPSL] OCO(init) failed for LDOGEUSDTSWAP: API error 1
[2025-07-18T20:22:15Z] ERROR bot [inst=DOGE-USDT-SWAP] [sess=ba23a8e0d9d34289bc865eade68bc4da] [mode=REST] [err=-]: Timeout GET https://www.okx.com/api/v5/account/positions
Traceback (most recent call last):
  File "C:\Users\Professional\AppData\Local\Programs\Python\Python312\Lib\site-packages\aiohttp\client_reqrep.py", line 1059, in start
    message, payload = await protocol.read()  # type: ignore[union-attr]
                       ^^^^^^^^^^^^^^^^^^^^^
  File "C:\Users\Professional\AppData\Local\Programs\Python\Python312\Lib\site-packages\aiohttp\streams.py", line 644, in read
    await self._waiter
asyncio.exceptions.CancelledError

The above exception was the direct cause of the following exception:

Traceback (most recent call last):
  File "d:\Develop\Python\trade_bot\11.8.3\rest_client.py", line 138, in request
    async with self.session.request(
  File "C:\Users\Professional\AppData\Local\Programs\Python\Python312\Lib\site-packages\aiohttp\client.py", line 1360, in __aenter__
    self._resp: _RetType = await self._coro
                           ^^^^^^^^^^^^^^^^
  File "C:\Users\Professional\AppData\Local\Programs\Python\Python312\Lib\site-packages\aiohttp\client.py", line 690, in _request
    await resp.start(conn)
  File "C:\Users\Professional\AppData\Local\Programs\Python\Python312\Lib\site-packages\aiohttp\client_reqrep.py", line 1054, in start
    with self._timer:
  File "C:\Users\Professional\AppData\Local\Programs\Python\Python312\Lib\site-packages\aiohttp\helpers.py", line 749, in __exit__
    raise asyncio.TimeoutError from exc_val
TimeoutError
[2025-07-18T20:22:15Z] ERROR bot [inst=DOGE-USDT-SWAP] [sess=ba23a8e0d9d34289bc865eade68bc4da] [mode=-] [err=-]: ❌ [TPSL] loop error: 
Traceback (most recent call last):
  File "C:\Users\Professional\AppData\Local\Programs\Python\Python312\Lib\site-packages\aiohttp\client_reqrep.py", line 1059, in start
    message, payload = await protocol.read()  # type: ignore[union-attr]
                       ^^^^^^^^^^^^^^^^^^^^^
  File "C:\Users\Professional\AppData\Local\Programs\Python\Python312\Lib\site-packages\aiohttp\streams.py", line 644, in read
    await self._waiter
asyncio.exceptions.CancelledError

The above exception was the direct cause of the following exception:

Traceback (most recent call last):
  File "d:\Develop\Python\trade_bot\11.8.3\tpsl_monitor.py", line 80, in _loop
    lq, lp, sq, sp = await self._get_state()
                     ^^^^^^^^^^^^^^^^^^^^^^^
  File "d:\Develop\Python\trade_bot\11.8.3\tpsl_monitor.py", line 134, in _get_state
    resp = await self.rest.request(
           ^^^^^^^^^^^^^^^^^^^^^^^^
  File "d:\Develop\Python\trade_bot\11.8.3\rest_client.py", line 138, in request
    async with self.session.request(
  File "C:\Users\Professional\AppData\Local\Programs\Python\Python312\Lib\site-packages\aiohttp\client.py", line 1360, in __aenter__
    self._resp: _RetType = await self._coro
                           ^^^^^^^^^^^^^^^^
  File "C:\Users\Professional\AppData\Local\Programs\Python\Python312\Lib\site-packages\aiohttp\client.py", line 690, in _request
    await resp.start(conn)
  File "C:\Users\Professional\AppData\Local\Programs\Python\Python312\Lib\site-packages\aiohttp\client_reqrep.py", line 1054, in start
    with self._timer:
  File "C:\Users\Professional\AppData\Local\Programs\Python\Python312\Lib\site-packages\aiohttp\helpers.py", line 749, in __exit__
    raise asyncio.TimeoutError from exc_val
TimeoutError
[2025-07-18T20:27:58Z] ERROR bot [inst=DOGE-USDT-SWAP] [sess=5a5199baf4ac460896f8b772af67c899] [mode=REST] [err=1]: API error code=1 response={'code': '1', 'data': [{'algoClOrdId': '', 'algoId': '', 'clOrdId': '', 'sCode': '51023', 'sMsg': "Position doesn't exist. ", 'tag': ''}], 'msg': ''}
[2025-07-18T20:27:58Z] ERROR bot [inst=DOGE-USDT-SWAP] [sess=5a5199baf4ac460896f8b772af67c899] [mode=-] [err=-]: ❌ [TPSL] OCO(init) failed for SDOGEUSDTSWAP: API error 1
[2025-07-18T20:29:10Z] ERROR bot [inst=DOGE-USDT-SWAP] [sess=5a5199baf4ac460896f8b772af67c899] [mode=-] [err=-]: ❌ [TPSL] loop error: float division by zero
Traceback (most recent call last):
  File "d:\Develop\Python\trade_bot\11.8.3\tpsl_monitor.py", line 112, in _loop
    abs(current.get(cid_init, 0)  - tp_init)  / tp_init  > self.threshold
    ~~~~~~~~~~~~~~~~~~~~~~~~~~~~~~~~~~~~~~~~~~^~~~~~~~~
ZeroDivisionError: float division by zero
[2025-07-18T20:59:28Z] ERROR bot [inst=DOGE-USDT-SWAP] [sess=18fe8442ea6942d8a9f67bffad390f59] [mode=WS] [err=-]: 🔄 [WS] Disconnected: WS subscribe tickers failed: {'event': 'error', 'msg': 'The current WebSocket endpoint does not support subscribing to public channels. Please check the WebSocket URL.', 'code': '60008', 'connId': '70404ef5'}, retry in 1s
[2025-07-18T20:59:32Z] ERROR bot [inst=DOGE-USDT-SWAP] [sess=18fe8442ea6942d8a9f67bffad390f59] [mode=WS] [err=-]: 🔄 [WS] Disconnected: WS subscribe tickers failed: {'event': 'error', 'msg': 'The current WebSocket endpoint does not support subscribing to public channels. Please check the WebSocket URL.', 'code': '60008', 'connId': 'c329a169'}, retry in 2s
[2025-07-18T20:59:37Z] ERROR bot [inst=DOGE-USDT-SWAP] [sess=18fe8442ea6942d8a9f67bffad390f59] [mode=WS] [err=-]: 🔄 [WS] Disconnected: WS subscribe tickers failed: {'event': 'error', 'msg': 'The current WebSocket endpoint does not support subscribing to public channels. Please check the WebSocket URL.', 'code': '60008', 'connId': 'ab4b4dde'}, retry in 4s
