[18-08  00:02:27] ERROR bot [mode=MAIN] : ðŸ’¥ Fatal error: maximum recursion depth exceeded
Traceback (most recent call last):
  File "C:\Users\Professional\AppData\Local\Programs\Python\Python312\Lib\asyncio\runners.py", line 194, in run
    return runner.run(main)
           ^^^^^^^^^^^^^^^^
  File "C:\Users\Professional\AppData\Local\Programs\Python\Python312\Lib\asyncio\runners.py", line 118, in run
    return self._loop.run_until_complete(task)
           ^^^^^^^^^^^^^^^^^^^^^^^^^^^^^^^^^^^
  File "C:\Users\Professional\AppData\Local\Programs\Python\Python312\Lib\asyncio\base_events.py", line 687, in run_until_complete
    return future.result()
           ^^^^^^^^^^^^^^^
  File "d:\Develop\Python\trade_bot\11.9.1\main.py", line 122, in main
    await task_manager.wait("orchestrator")
  File "d:\Develop\Python\trade_bot\11.9.1\core\task_manager.py", line 114, in wait
    await task
  File "d:\Develop\Python\trade_bot\11.9.1\core\orchestrator.py", line 174, in run
    await asyncio.sleep(self.poll_interval)
  File "C:\Users\Professional\AppData\Local\Programs\Python\Python312\Lib\asyncio\tasks.py", line 665, in sleep
    return await future
           ^^^^^^^^^^^^
asyncio.exceptions.CancelledError

During handling of the above exception, another exception occurred:

Traceback (most recent call last):
  File "d:\Develop\Python\trade_bot\11.9.1\main.py", line 180, in <module>
    asyncio.run(main())
  File "C:\Users\Professional\AppData\Local\Programs\Python\Python312\Lib\asyncio\runners.py", line 193, in run
    with Runner(debug=debug, loop_factory=loop_factory) as runner:
  File "C:\Users\Professional\AppData\Local\Programs\Python\Python312\Lib\asyncio\runners.py", line 62, in __exit__
    self.close()
  File "C:\Users\Professional\AppData\Local\Programs\Python\Python312\Lib\asyncio\runners.py", line 70, in close
    _cancel_all_tasks(loop)
  File "C:\Users\Professional\AppData\Local\Programs\Python\Python312\Lib\asyncio\runners.py", line 203, in _cancel_all_tasks
    task.cancel()
  File "C:\Users\Professional\AppData\Local\Programs\Python\Python312\Lib\asyncio\tasks.py", line 721, in cancel
    if child.cancel(msg=msg):
       ^^^^^^^^^^^^^^^^^^^^^
  File "C:\Users\Professional\AppData\Local\Programs\Python\Python312\Lib\asyncio\tasks.py", line 721, in cancel
    if child.cancel(msg=msg):
       ^^^^^^^^^^^^^^^^^^^^^
  File "C:\Users\Professional\AppData\Local\Programs\Python\Python312\Lib\asyncio\tasks.py", line 721, in cancel
    if child.cancel(msg=msg):
       ^^^^^^^^^^^^^^^^^^^^^
  [Previous line repeated 992 more times]
RecursionError: maximum recursion depth exceeded
[18-08  00:18:06] ERROR bot [mode=MAIN] : ðŸ’¥ Fatal error: maximum recursion depth exceeded
Traceback (most recent call last):
  File "C:\Users\Professional\AppData\Local\Programs\Python\Python312\Lib\asyncio\runners.py", line 194, in run
    return runner.run(main)
           ^^^^^^^^^^^^^^^^
  File "C:\Users\Professional\AppData\Local\Programs\Python\Python312\Lib\asyncio\runners.py", line 118, in run
    return self._loop.run_until_complete(task)
           ^^^^^^^^^^^^^^^^^^^^^^^^^^^^^^^^^^^
  File "C:\Users\Professional\AppData\Local\Programs\Python\Python312\Lib\asyncio\base_events.py", line 687, in run_until_complete
    return future.result()
           ^^^^^^^^^^^^^^^
  File "d:\Develop\Python\trade_bot\11.9.1\main.py", line 122, in main
    await task_manager.wait("orchestrator")
  File "d:\Develop\Python\trade_bot\11.9.1\core\task_manager.py", line 114, in wait
    await task
  File "d:\Develop\Python\trade_bot\11.9.1\core\orchestrator.py", line 174, in run
    await asyncio.sleep(self.poll_interval)
  File "C:\Users\Professional\AppData\Local\Programs\Python\Python312\Lib\asyncio\tasks.py", line 665, in sleep
    return await future
           ^^^^^^^^^^^^
asyncio.exceptions.CancelledError

During handling of the above exception, another exception occurred:

Traceback (most recent call last):
  File "d:\Develop\Python\trade_bot\11.9.1\main.py", line 180, in <module>
    asyncio.run(main())
  File "C:\Users\Professional\AppData\Local\Programs\Python\Python312\Lib\asyncio\runners.py", line 193, in run
    with Runner(debug=debug, loop_factory=loop_factory) as runner:
  File "C:\Users\Professional\AppData\Local\Programs\Python\Python312\Lib\asyncio\runners.py", line 62, in __exit__
    self.close()
  File "C:\Users\Professional\AppData\Local\Programs\Python\Python312\Lib\asyncio\runners.py", line 70, in close
    _cancel_all_tasks(loop)
  File "C:\Users\Professional\AppData\Local\Programs\Python\Python312\Lib\asyncio\runners.py", line 203, in _cancel_all_tasks
    task.cancel()
  File "C:\Users\Professional\AppData\Local\Programs\Python\Python312\Lib\asyncio\tasks.py", line 721, in cancel
    if child.cancel(msg=msg):
       ^^^^^^^^^^^^^^^^^^^^^
  File "C:\Users\Professional\AppData\Local\Programs\Python\Python312\Lib\asyncio\tasks.py", line 721, in cancel
    if child.cancel(msg=msg):
       ^^^^^^^^^^^^^^^^^^^^^
  File "C:\Users\Professional\AppData\Local\Programs\Python\Python312\Lib\asyncio\tasks.py", line 721, in cancel
    if child.cancel(msg=msg):
       ^^^^^^^^^^^^^^^^^^^^^
  [Previous line repeated 992 more times]
RecursionError: maximum recursion depth exceeded
[18-08  00:20:53] ERROR bot [mode=MAIN] : ðŸ’¥ Fatal error: maximum recursion depth exceeded
Traceback (most recent call last):
  File "C:\Users\Professional\AppData\Local\Programs\Python\Python312\Lib\asyncio\runners.py", line 194, in run
    return runner.run(main)
           ^^^^^^^^^^^^^^^^
  File "C:\Users\Professional\AppData\Local\Programs\Python\Python312\Lib\asyncio\runners.py", line 118, in run
    return self._loop.run_until_complete(task)
           ^^^^^^^^^^^^^^^^^^^^^^^^^^^^^^^^^^^
  File "C:\Users\Professional\AppData\Local\Programs\Python\Python312\Lib\asyncio\base_events.py", line 687, in run_until_complete
    return future.result()
           ^^^^^^^^^^^^^^^
  File "d:\Develop\Python\trade_bot\11.9.1\main.py", line 122, in main
    await task_manager.wait("orchestrator")
  File "d:\Develop\Python\trade_bot\11.9.1\core\task_manager.py", line 114, in wait
    await task
  File "d:\Develop\Python\trade_bot\11.9.1\core\orchestrator.py", line 174, in run
    await asyncio.sleep(self.poll_interval)
  File "C:\Users\Professional\AppData\Local\Programs\Python\Python312\Lib\asyncio\tasks.py", line 665, in sleep
    return await future
           ^^^^^^^^^^^^
asyncio.exceptions.CancelledError

During handling of the above exception, another exception occurred:

Traceback (most recent call last):
  File "d:\Develop\Python\trade_bot\11.9.1\main.py", line 180, in <module>
    asyncio.run(main())
  File "C:\Users\Professional\AppData\Local\Programs\Python\Python312\Lib\asyncio\runners.py", line 193, in run
    with Runner(debug=debug, loop_factory=loop_factory) as runner:
  File "C:\Users\Professional\AppData\Local\Programs\Python\Python312\Lib\asyncio\runners.py", line 62, in __exit__
    self.close()
  File "C:\Users\Professional\AppData\Local\Programs\Python\Python312\Lib\asyncio\runners.py", line 70, in close
    _cancel_all_tasks(loop)
  File "C:\Users\Professional\AppData\Local\Programs\Python\Python312\Lib\asyncio\runners.py", line 203, in _cancel_all_tasks
    task.cancel()
  File "C:\Users\Professional\AppData\Local\Programs\Python\Python312\Lib\asyncio\tasks.py", line 721, in cancel
    if child.cancel(msg=msg):
       ^^^^^^^^^^^^^^^^^^^^^
  File "C:\Users\Professional\AppData\Local\Programs\Python\Python312\Lib\asyncio\tasks.py", line 721, in cancel
    if child.cancel(msg=msg):
       ^^^^^^^^^^^^^^^^^^^^^
  File "C:\Users\Professional\AppData\Local\Programs\Python\Python312\Lib\asyncio\tasks.py", line 721, in cancel
    if child.cancel(msg=msg):
       ^^^^^^^^^^^^^^^^^^^^^
  [Previous line repeated 992 more times]
RecursionError: maximum recursion depth exceeded
[18-08  00:21:04] ERROR bot [mode=MAIN] : ðŸ’¥ Fatal error: maximum recursion depth exceeded
Traceback (most recent call last):
  File "C:\Users\Professional\AppData\Local\Programs\Python\Python312\Lib\asyncio\runners.py", line 194, in run
    return runner.run(main)
           ^^^^^^^^^^^^^^^^
  File "C:\Users\Professional\AppData\Local\Programs\Python\Python312\Lib\asyncio\runners.py", line 118, in run
    return self._loop.run_until_complete(task)
           ^^^^^^^^^^^^^^^^^^^^^^^^^^^^^^^^^^^
  File "C:\Users\Professional\AppData\Local\Programs\Python\Python312\Lib\asyncio\base_events.py", line 687, in run_until_complete
    return future.result()
           ^^^^^^^^^^^^^^^
  File "d:\Develop\Python\trade_bot\11.9.1\main.py", line 122, in main
    await task_manager.wait("orchestrator")
  File "d:\Develop\Python\trade_bot\11.9.1\core\task_manager.py", line 114, in wait
    await task
  File "d:\Develop\Python\trade_bot\11.9.1\core\orchestrator.py", line 108, in run
    await asyncio.sleep(self.poll_interval * 5)
  File "C:\Users\Professional\AppData\Local\Programs\Python\Python312\Lib\asyncio\tasks.py", line 665, in sleep
    return await future
           ^^^^^^^^^^^^
asyncio.exceptions.CancelledError

During handling of the above exception, another exception occurred:

Traceback (most recent call last):
  File "d:\Develop\Python\trade_bot\11.9.1\main.py", line 180, in <module>
    asyncio.run(main())
  File "C:\Users\Professional\AppData\Local\Programs\Python\Python312\Lib\asyncio\runners.py", line 193, in run
    with Runner(debug=debug, loop_factory=loop_factory) as runner:
  File "C:\Users\Professional\AppData\Local\Programs\Python\Python312\Lib\asyncio\runners.py", line 62, in __exit__
    self.close()
  File "C:\Users\Professional\AppData\Local\Programs\Python\Python312\Lib\asyncio\runners.py", line 70, in close
    _cancel_all_tasks(loop)
  File "C:\Users\Professional\AppData\Local\Programs\Python\Python312\Lib\asyncio\runners.py", line 203, in _cancel_all_tasks
    task.cancel()
  File "C:\Users\Professional\AppData\Local\Programs\Python\Python312\Lib\asyncio\tasks.py", line 721, in cancel
    if child.cancel(msg=msg):
       ^^^^^^^^^^^^^^^^^^^^^
  File "C:\Users\Professional\AppData\Local\Programs\Python\Python312\Lib\asyncio\tasks.py", line 721, in cancel
    if child.cancel(msg=msg):
       ^^^^^^^^^^^^^^^^^^^^^
  File "C:\Users\Professional\AppData\Local\Programs\Python\Python312\Lib\asyncio\tasks.py", line 721, in cancel
    if child.cancel(msg=msg):
       ^^^^^^^^^^^^^^^^^^^^^
  [Previous line repeated 992 more times]
RecursionError: maximum recursion depth exceeded
[18-08  00:27:20] ERROR bot [mode=MAIN] : ðŸ’¥ Fatal error: maximum recursion depth exceeded
Traceback (most recent call last):
  File "C:\Users\Professional\AppData\Local\Programs\Python\Python312\Lib\asyncio\runners.py", line 194, in run
    return runner.run(main)
           ^^^^^^^^^^^^^^^^
  File "C:\Users\Professional\AppData\Local\Programs\Python\Python312\Lib\asyncio\runners.py", line 118, in run
    return self._loop.run_until_complete(task)
           ^^^^^^^^^^^^^^^^^^^^^^^^^^^^^^^^^^^
  File "C:\Users\Professional\AppData\Local\Programs\Python\Python312\Lib\asyncio\base_events.py", line 687, in run_until_complete
    return future.result()
           ^^^^^^^^^^^^^^^
  File "d:\Develop\Python\trade_bot\11.9.1\main.py", line 122, in main
    await task_manager.wait("orchestrator")
  File "d:\Develop\Python\trade_bot\11.9.1\core\task_manager.py", line 114, in wait
    await task
  File "d:\Develop\Python\trade_bot\11.9.1\core\orchestrator.py", line 108, in run
    await asyncio.sleep(self.poll_interval * 5)
  File "C:\Users\Professional\AppData\Local\Programs\Python\Python312\Lib\asyncio\tasks.py", line 665, in sleep
    return await future
           ^^^^^^^^^^^^
asyncio.exceptions.CancelledError

During handling of the above exception, another exception occurred:

Traceback (most recent call last):
  File "d:\Develop\Python\trade_bot\11.9.1\main.py", line 180, in <module>
    asyncio.run(main())
  File "C:\Users\Professional\AppData\Local\Programs\Python\Python312\Lib\asyncio\runners.py", line 193, in run
    with Runner(debug=debug, loop_factory=loop_factory) as runner:
  File "C:\Users\Professional\AppData\Local\Programs\Python\Python312\Lib\asyncio\runners.py", line 62, in __exit__
    self.close()
  File "C:\Users\Professional\AppData\Local\Programs\Python\Python312\Lib\asyncio\runners.py", line 70, in close
    _cancel_all_tasks(loop)
  File "C:\Users\Professional\AppData\Local\Programs\Python\Python312\Lib\asyncio\runners.py", line 203, in _cancel_all_tasks
    task.cancel()
  File "C:\Users\Professional\AppData\Local\Programs\Python\Python312\Lib\asyncio\tasks.py", line 721, in cancel
    if child.cancel(msg=msg):
       ^^^^^^^^^^^^^^^^^^^^^
  File "C:\Users\Professional\AppData\Local\Programs\Python\Python312\Lib\asyncio\tasks.py", line 721, in cancel
    if child.cancel(msg=msg):
       ^^^^^^^^^^^^^^^^^^^^^
  File "C:\Users\Professional\AppData\Local\Programs\Python\Python312\Lib\asyncio\tasks.py", line 721, in cancel
    if child.cancel(msg=msg):
       ^^^^^^^^^^^^^^^^^^^^^
  [Previous line repeated 992 more times]
RecursionError: maximum recursion depth exceeded
[18-08  00:30:13] ERROR bot [mode=MAIN] : ðŸ’¥ Fatal error: maximum recursion depth exceeded
Traceback (most recent call last):
  File "C:\Users\Professional\AppData\Local\Programs\Python\Python312\Lib\asyncio\runners.py", line 194, in run
    return runner.run(main)
           ^^^^^^^^^^^^^^^^
  File "C:\Users\Professional\AppData\Local\Programs\Python\Python312\Lib\asyncio\runners.py", line 118, in run
    return self._loop.run_until_complete(task)
           ^^^^^^^^^^^^^^^^^^^^^^^^^^^^^^^^^^^
  File "C:\Users\Professional\AppData\Local\Programs\Python\Python312\Lib\asyncio\base_events.py", line 687, in run_until_complete
    return future.result()
           ^^^^^^^^^^^^^^^
  File "d:\Develop\Python\trade_bot\11.9.1\main.py", line 122, in main
    await task_manager.wait("orchestrator")
  File "d:\Develop\Python\trade_bot\11.9.1\core\task_manager.py", line 114, in wait
    await task
  File "d:\Develop\Python\trade_bot\11.9.1\core\orchestrator.py", line 135, in run
    await asyncio.sleep(self.poll_interval * 3)
  File "C:\Users\Professional\AppData\Local\Programs\Python\Python312\Lib\asyncio\tasks.py", line 665, in sleep
    return await future
           ^^^^^^^^^^^^
asyncio.exceptions.CancelledError

During handling of the above exception, another exception occurred:

Traceback (most recent call last):
  File "d:\Develop\Python\trade_bot\11.9.1\main.py", line 180, in <module>
    asyncio.run(main())
  File "C:\Users\Professional\AppData\Local\Programs\Python\Python312\Lib\asyncio\runners.py", line 193, in run
    with Runner(debug=debug, loop_factory=loop_factory) as runner:
  File "C:\Users\Professional\AppData\Local\Programs\Python\Python312\Lib\asyncio\runners.py", line 62, in __exit__
    self.close()
  File "C:\Users\Professional\AppData\Local\Programs\Python\Python312\Lib\asyncio\runners.py", line 70, in close
    _cancel_all_tasks(loop)
  File "C:\Users\Professional\AppData\Local\Programs\Python\Python312\Lib\asyncio\runners.py", line 203, in _cancel_all_tasks
    task.cancel()
  File "C:\Users\Professional\AppData\Local\Programs\Python\Python312\Lib\asyncio\tasks.py", line 721, in cancel
    if child.cancel(msg=msg):
       ^^^^^^^^^^^^^^^^^^^^^
  File "C:\Users\Professional\AppData\Local\Programs\Python\Python312\Lib\asyncio\tasks.py", line 721, in cancel
    if child.cancel(msg=msg):
       ^^^^^^^^^^^^^^^^^^^^^
  File "C:\Users\Professional\AppData\Local\Programs\Python\Python312\Lib\asyncio\tasks.py", line 721, in cancel
    if child.cancel(msg=msg):
       ^^^^^^^^^^^^^^^^^^^^^
  [Previous line repeated 992 more times]
RecursionError: maximum recursion depth exceeded
[18-08  00:30:35] ERROR bot [mode=MAIN] : ðŸ’¥ Fatal error: maximum recursion depth exceeded
Traceback (most recent call last):
  File "C:\Users\Professional\AppData\Local\Programs\Python\Python312\Lib\asyncio\runners.py", line 194, in run
    return runner.run(main)
           ^^^^^^^^^^^^^^^^
  File "C:\Users\Professional\AppData\Local\Programs\Python\Python312\Lib\asyncio\runners.py", line 118, in run
    return self._loop.run_until_complete(task)
           ^^^^^^^^^^^^^^^^^^^^^^^^^^^^^^^^^^^
  File "C:\Users\Professional\AppData\Local\Programs\Python\Python312\Lib\asyncio\base_events.py", line 687, in run_until_complete
    return future.result()
           ^^^^^^^^^^^^^^^
  File "d:\Develop\Python\trade_bot\11.9.1\main.py", line 122, in main
    await task_manager.wait("orchestrator")
  File "d:\Develop\Python\trade_bot\11.9.1\core\task_manager.py", line 114, in wait
    await task
  File "d:\Develop\Python\trade_bot\11.9.1\core\orchestrator.py", line 174, in run
    await asyncio.sleep(self.poll_interval)
  File "C:\Users\Professional\AppData\Local\Programs\Python\Python312\Lib\asyncio\tasks.py", line 665, in sleep
    return await future
           ^^^^^^^^^^^^
asyncio.exceptions.CancelledError

During handling of the above exception, another exception occurred:

Traceback (most recent call last):
  File "d:\Develop\Python\trade_bot\11.9.1\main.py", line 180, in <module>
    asyncio.run(main())
  File "C:\Users\Professional\AppData\Local\Programs\Python\Python312\Lib\asyncio\runners.py", line 193, in run
    with Runner(debug=debug, loop_factory=loop_factory) as runner:
  File "C:\Users\Professional\AppData\Local\Programs\Python\Python312\Lib\asyncio\runners.py", line 62, in __exit__
    self.close()
  File "C:\Users\Professional\AppData\Local\Programs\Python\Python312\Lib\asyncio\runners.py", line 70, in close
    _cancel_all_tasks(loop)
  File "C:\Users\Professional\AppData\Local\Programs\Python\Python312\Lib\asyncio\runners.py", line 203, in _cancel_all_tasks
    task.cancel()
  File "C:\Users\Professional\AppData\Local\Programs\Python\Python312\Lib\asyncio\tasks.py", line 721, in cancel
    if child.cancel(msg=msg):
       ^^^^^^^^^^^^^^^^^^^^^
  File "C:\Users\Professional\AppData\Local\Programs\Python\Python312\Lib\asyncio\tasks.py", line 721, in cancel
    if child.cancel(msg=msg):
       ^^^^^^^^^^^^^^^^^^^^^
  File "C:\Users\Professional\AppData\Local\Programs\Python\Python312\Lib\asyncio\tasks.py", line 721, in cancel
    if child.cancel(msg=msg):
       ^^^^^^^^^^^^^^^^^^^^^
  [Previous line repeated 992 more times]
RecursionError: maximum recursion depth exceeded
[18-08  00:31:38] ERROR bot [mode=MAIN] : ðŸ’¥ Fatal error: maximum recursion depth exceeded
Traceback (most recent call last):
  File "C:\Users\Professional\AppData\Local\Programs\Python\Python312\Lib\asyncio\runners.py", line 194, in run
    return runner.run(main)
           ^^^^^^^^^^^^^^^^
  File "C:\Users\Professional\AppData\Local\Programs\Python\Python312\Lib\asyncio\runners.py", line 118, in run
    return self._loop.run_until_complete(task)
           ^^^^^^^^^^^^^^^^^^^^^^^^^^^^^^^^^^^
  File "C:\Users\Professional\AppData\Local\Programs\Python\Python312\Lib\asyncio\base_events.py", line 687, in run_until_complete
    return future.result()
           ^^^^^^^^^^^^^^^
  File "d:\Develop\Python\trade_bot\11.9.1\main.py", line 122, in main
    await task_manager.wait("orchestrator")
  File "d:\Develop\Python\trade_bot\11.9.1\core\task_manager.py", line 114, in wait
    await task
  File "d:\Develop\Python\trade_bot\11.9.1\core\orchestrator.py", line 174, in run
    await asyncio.sleep(self.poll_interval)
  File "C:\Users\Professional\AppData\Local\Programs\Python\Python312\Lib\asyncio\tasks.py", line 665, in sleep
    return await future
           ^^^^^^^^^^^^
asyncio.exceptions.CancelledError

During handling of the above exception, another exception occurred:

Traceback (most recent call last):
  File "d:\Develop\Python\trade_bot\11.9.1\main.py", line 180, in <module>
    asyncio.run(main())
  File "C:\Users\Professional\AppData\Local\Programs\Python\Python312\Lib\asyncio\runners.py", line 193, in run
    with Runner(debug=debug, loop_factory=loop_factory) as runner:
  File "C:\Users\Professional\AppData\Local\Programs\Python\Python312\Lib\asyncio\runners.py", line 62, in __exit__
    self.close()
  File "C:\Users\Professional\AppData\Local\Programs\Python\Python312\Lib\asyncio\runners.py", line 70, in close
    _cancel_all_tasks(loop)
  File "C:\Users\Professional\AppData\Local\Programs\Python\Python312\Lib\asyncio\runners.py", line 203, in _cancel_all_tasks
    task.cancel()
  File "C:\Users\Professional\AppData\Local\Programs\Python\Python312\Lib\asyncio\tasks.py", line 721, in cancel
    if child.cancel(msg=msg):
       ^^^^^^^^^^^^^^^^^^^^^
  File "C:\Users\Professional\AppData\Local\Programs\Python\Python312\Lib\asyncio\tasks.py", line 721, in cancel
    if child.cancel(msg=msg):
       ^^^^^^^^^^^^^^^^^^^^^
  File "C:\Users\Professional\AppData\Local\Programs\Python\Python312\Lib\asyncio\tasks.py", line 721, in cancel
    if child.cancel(msg=msg):
       ^^^^^^^^^^^^^^^^^^^^^
  [Previous line repeated 992 more times]
RecursionError: maximum recursion depth exceeded
[18-08  00:38:50] ERROR bot [mode=MAIN] : ðŸ’¥ Fatal error: maximum recursion depth exceeded
Traceback (most recent call last):
  File "C:\Users\Professional\AppData\Local\Programs\Python\Python312\Lib\asyncio\runners.py", line 194, in run
    return runner.run(main)
           ^^^^^^^^^^^^^^^^
  File "C:\Users\Professional\AppData\Local\Programs\Python\Python312\Lib\asyncio\runners.py", line 118, in run
    return self._loop.run_until_complete(task)
           ^^^^^^^^^^^^^^^^^^^^^^^^^^^^^^^^^^^
  File "C:\Users\Professional\AppData\Local\Programs\Python\Python312\Lib\asyncio\base_events.py", line 687, in run_until_complete
    return future.result()
           ^^^^^^^^^^^^^^^
  File "d:\Develop\Python\trade_bot\11.9.1\main.py", line 122, in main
    await task_manager.wait("orchestrator")
  File "d:\Develop\Python\trade_bot\11.9.1\core\task_manager.py", line 114, in wait
    await task
  File "d:\Develop\Python\trade_bot\11.9.1\core\orchestrator.py", line 174, in run
    await asyncio.sleep(self.poll_interval)
  File "C:\Users\Professional\AppData\Local\Programs\Python\Python312\Lib\asyncio\tasks.py", line 665, in sleep
    return await future
           ^^^^^^^^^^^^
asyncio.exceptions.CancelledError

During handling of the above exception, another exception occurred:

Traceback (most recent call last):
  File "d:\Develop\Python\trade_bot\11.9.1\main.py", line 180, in <module>
    asyncio.run(main())
  File "C:\Users\Professional\AppData\Local\Programs\Python\Python312\Lib\asyncio\runners.py", line 193, in run
    with Runner(debug=debug, loop_factory=loop_factory) as runner:
  File "C:\Users\Professional\AppData\Local\Programs\Python\Python312\Lib\asyncio\runners.py", line 62, in __exit__
    self.close()
  File "C:\Users\Professional\AppData\Local\Programs\Python\Python312\Lib\asyncio\runners.py", line 70, in close
    _cancel_all_tasks(loop)
  File "C:\Users\Professional\AppData\Local\Programs\Python\Python312\Lib\asyncio\runners.py", line 203, in _cancel_all_tasks
    task.cancel()
  File "C:\Users\Professional\AppData\Local\Programs\Python\Python312\Lib\asyncio\tasks.py", line 721, in cancel
    if child.cancel(msg=msg):
       ^^^^^^^^^^^^^^^^^^^^^
  File "C:\Users\Professional\AppData\Local\Programs\Python\Python312\Lib\asyncio\tasks.py", line 721, in cancel
    if child.cancel(msg=msg):
       ^^^^^^^^^^^^^^^^^^^^^
  File "C:\Users\Professional\AppData\Local\Programs\Python\Python312\Lib\asyncio\tasks.py", line 721, in cancel
    if child.cancel(msg=msg):
       ^^^^^^^^^^^^^^^^^^^^^
  [Previous line repeated 992 more times]
RecursionError: maximum recursion depth exceeded
[18-08  00:43:44] ERROR bot [mode=MAIN] : ðŸ’¥ Fatal error: maximum recursion depth exceeded
Traceback (most recent call last):
  File "C:\Users\Professional\AppData\Local\Programs\Python\Python312\Lib\asyncio\runners.py", line 194, in run
    return runner.run(main)
           ^^^^^^^^^^^^^^^^
  File "C:\Users\Professional\AppData\Local\Programs\Python\Python312\Lib\asyncio\runners.py", line 118, in run
    return self._loop.run_until_complete(task)
           ^^^^^^^^^^^^^^^^^^^^^^^^^^^^^^^^^^^
  File "C:\Users\Professional\AppData\Local\Programs\Python\Python312\Lib\asyncio\base_events.py", line 687, in run_until_complete
    return future.result()
           ^^^^^^^^^^^^^^^
  File "d:\Develop\Python\trade_bot\11.9.1\main.py", line 122, in main
    await task_manager.wait("orchestrator")
  File "d:\Develop\Python\trade_bot\11.9.1\core\task_manager.py", line 114, in wait
    await task
  File "d:\Develop\Python\trade_bot\11.9.1\core\orchestrator.py", line 135, in run
    await asyncio.sleep(self.poll_interval * 3)
  File "C:\Users\Professional\AppData\Local\Programs\Python\Python312\Lib\asyncio\tasks.py", line 665, in sleep
    return await future
           ^^^^^^^^^^^^
asyncio.exceptions.CancelledError

During handling of the above exception, another exception occurred:

Traceback (most recent call last):
  File "d:\Develop\Python\trade_bot\11.9.1\main.py", line 180, in <module>
    asyncio.run(main())
  File "C:\Users\Professional\AppData\Local\Programs\Python\Python312\Lib\asyncio\runners.py", line 193, in run
    with Runner(debug=debug, loop_factory=loop_factory) as runner:
  File "C:\Users\Professional\AppData\Local\Programs\Python\Python312\Lib\asyncio\runners.py", line 62, in __exit__
    self.close()
  File "C:\Users\Professional\AppData\Local\Programs\Python\Python312\Lib\asyncio\runners.py", line 70, in close
    _cancel_all_tasks(loop)
  File "C:\Users\Professional\AppData\Local\Programs\Python\Python312\Lib\asyncio\runners.py", line 203, in _cancel_all_tasks
    task.cancel()
  File "C:\Users\Professional\AppData\Local\Programs\Python\Python312\Lib\asyncio\tasks.py", line 721, in cancel
    if child.cancel(msg=msg):
       ^^^^^^^^^^^^^^^^^^^^^
  File "C:\Users\Professional\AppData\Local\Programs\Python\Python312\Lib\asyncio\tasks.py", line 721, in cancel
    if child.cancel(msg=msg):
       ^^^^^^^^^^^^^^^^^^^^^
  File "C:\Users\Professional\AppData\Local\Programs\Python\Python312\Lib\asyncio\tasks.py", line 721, in cancel
    if child.cancel(msg=msg):
       ^^^^^^^^^^^^^^^^^^^^^
  [Previous line repeated 992 more times]
RecursionError: maximum recursion depth exceeded
