[07-08  00:08:23] ERROR bot [mode=-] : ❌ [PreHEDGE] TP placement failed: code=-1, msg=
[07-08  01:14:46] ERROR bot [mode=REST] : API error code=50002 response={'code': '50002', 'data': [], 'msg': 'Incorrect json data format'}
[07-08  01:14:46] ERROR bot [mode=-] : ❌ [PreHEDGE] TP placement failed: code=-1, msg=
[07-08  14:40:37] ERROR bot [mode=REST] : [TimeoutError] POST https://www.okx.com/api/v5/trade/cancel-order, attempt 1/4, sleeping 1.0s before retry
Traceback (most recent call last):
  File "C:\Users\Professional\AppData\Local\Programs\Python\Python312\Lib\site-packages\aiohttp\client_reqrep.py", line 1059, in start
    message, payload = await protocol.read()  # type: ignore[union-attr]
                       ^^^^^^^^^^^^^^^^^^^^^
  File "C:\Users\Professional\AppData\Local\Programs\Python\Python312\Lib\site-packages\aiohttp\streams.py", line 644, in read
    await self._waiter
asyncio.exceptions.CancelledError

The above exception was the direct cause of the following exception:

Traceback (most recent call last):
  File "d:\Develop\Python\trade_bot\11.9.1\core\rest_client.py", line 206, in request
    async with self.session.request(
  File "C:\Users\Professional\AppData\Local\Programs\Python\Python312\Lib\site-packages\aiohttp\client.py", line 1360, in __aenter__
    self._resp: _RetType = await self._coro
                           ^^^^^^^^^^^^^^^^
  File "C:\Users\Professional\AppData\Local\Programs\Python\Python312\Lib\site-packages\aiohttp\client.py", line 690, in _request
    await resp.start(conn)
  File "C:\Users\Professional\AppData\Local\Programs\Python\Python312\Lib\site-packages\aiohttp\client_reqrep.py", line 1054, in start
    with self._timer:
  File "C:\Users\Professional\AppData\Local\Programs\Python\Python312\Lib\site-packages\aiohttp\helpers.py", line 749, in __exit__
    raise asyncio.TimeoutError from exc_val
TimeoutError
[07-08  14:40:52] ERROR bot [mode=REST] : [TimeoutError] GET https://www.okx.com/api/v5/account/positions, attempt 1/4, sleeping 1.0s before retry
Traceback (most recent call last):
  File "C:\Users\Professional\AppData\Local\Programs\Python\Python312\Lib\site-packages\aiohttp\client.py", line 663, in _request
    conn = await self._connector.connect(
           ^^^^^^^^^^^^^^^^^^^^^^^^^^^^^^
  File "C:\Users\Professional\AppData\Local\Programs\Python\Python312\Lib\site-packages\aiohttp\connector.py", line 538, in connect
    proto = await self._create_connection(req, traces, timeout)
            ^^^^^^^^^^^^^^^^^^^^^^^^^^^^^^^^^^^^^^^^^^^^^^^^^^^
  File "C:\Users\Professional\AppData\Local\Programs\Python\Python312\Lib\site-packages\aiohttp\connector.py", line 1050, in _create_connection
    _, proto = await self._create_direct_connection(req, traces, timeout)
               ^^^^^^^^^^^^^^^^^^^^^^^^^^^^^^^^^^^^^^^^^^^^^^^^^^^^^^^^^^
  File "C:\Users\Professional\AppData\Local\Programs\Python\Python312\Lib\site-packages\aiohttp\connector.py", line 1335, in _create_direct_connection
    hosts = await self._resolve_host(host, port, traces=traces)
            ^^^^^^^^^^^^^^^^^^^^^^^^^^^^^^^^^^^^^^^^^^^^^^^^^^^
  File "C:\Users\Professional\AppData\Local\Programs\Python\Python312\Lib\site-packages\aiohttp\connector.py", line 989, in _resolve_host
    return await asyncio.shield(resolved_host_task)
           ^^^^^^^^^^^^^^^^^^^^^^^^^^^^^^^^^^^^^^^^
asyncio.exceptions.CancelledError

The above exception was the direct cause of the following exception:

Traceback (most recent call last):
  File "d:\Develop\Python\trade_bot\11.9.1\core\rest_client.py", line 206, in request
    async with self.session.request(
  File "C:\Users\Professional\AppData\Local\Programs\Python\Python312\Lib\site-packages\aiohttp\client.py", line 1360, in __aenter__
    self._resp: _RetType = await self._coro
                           ^^^^^^^^^^^^^^^^
  File "C:\Users\Professional\AppData\Local\Programs\Python\Python312\Lib\site-packages\aiohttp\client.py", line 578, in _request
    with timer:
  File "C:\Users\Professional\AppData\Local\Programs\Python\Python312\Lib\site-packages\aiohttp\helpers.py", line 749, in __exit__
    raise asyncio.TimeoutError from exc_val
TimeoutError
[07-08  14:40:52] ERROR bot [mode=REST] : [TimeoutError] GET https://www.okx.com/api/v5/account/positions, attempt 1/4, sleeping 1.1s before retry
Traceback (most recent call last):
  File "C:\Users\Professional\AppData\Local\Programs\Python\Python312\Lib\site-packages\aiohttp\client.py", line 663, in _request
    conn = await self._connector.connect(
           ^^^^^^^^^^^^^^^^^^^^^^^^^^^^^^
  File "C:\Users\Professional\AppData\Local\Programs\Python\Python312\Lib\site-packages\aiohttp\connector.py", line 538, in connect
    proto = await self._create_connection(req, traces, timeout)
            ^^^^^^^^^^^^^^^^^^^^^^^^^^^^^^^^^^^^^^^^^^^^^^^^^^^
  File "C:\Users\Professional\AppData\Local\Programs\Python\Python312\Lib\site-packages\aiohttp\connector.py", line 1050, in _create_connection
    _, proto = await self._create_direct_connection(req, traces, timeout)
               ^^^^^^^^^^^^^^^^^^^^^^^^^^^^^^^^^^^^^^^^^^^^^^^^^^^^^^^^^^
  File "C:\Users\Professional\AppData\Local\Programs\Python\Python312\Lib\site-packages\aiohttp\connector.py", line 1335, in _create_direct_connection
    hosts = await self._resolve_host(host, port, traces=traces)
            ^^^^^^^^^^^^^^^^^^^^^^^^^^^^^^^^^^^^^^^^^^^^^^^^^^^
  File "C:\Users\Professional\AppData\Local\Programs\Python\Python312\Lib\site-packages\aiohttp\connector.py", line 964, in _resolve_host
    await future
asyncio.exceptions.CancelledError

The above exception was the direct cause of the following exception:

Traceback (most recent call last):
  File "d:\Develop\Python\trade_bot\11.9.1\core\rest_client.py", line 206, in request
    async with self.session.request(
  File "C:\Users\Professional\AppData\Local\Programs\Python\Python312\Lib\site-packages\aiohttp\client.py", line 1360, in __aenter__
    self._resp: _RetType = await self._coro
                           ^^^^^^^^^^^^^^^^
  File "C:\Users\Professional\AppData\Local\Programs\Python\Python312\Lib\site-packages\aiohttp\client.py", line 578, in _request
    with timer:
  File "C:\Users\Professional\AppData\Local\Programs\Python\Python312\Lib\site-packages\aiohttp\helpers.py", line 749, in __exit__
    raise asyncio.TimeoutError from exc_val
TimeoutError
[07-08  14:40:57] ERROR bot [mode=REST] : [TimeoutError] POST https://www.okx.com/api/v5/trade/cancel-order, attempt 2/4, sleeping 2.0s before retry
Traceback (most recent call last):
  File "C:\Users\Professional\AppData\Local\Programs\Python\Python312\Lib\site-packages\aiohttp\client.py", line 663, in _request
    conn = await self._connector.connect(
           ^^^^^^^^^^^^^^^^^^^^^^^^^^^^^^
  File "C:\Users\Professional\AppData\Local\Programs\Python\Python312\Lib\site-packages\aiohttp\connector.py", line 538, in connect
    proto = await self._create_connection(req, traces, timeout)
            ^^^^^^^^^^^^^^^^^^^^^^^^^^^^^^^^^^^^^^^^^^^^^^^^^^^
  File "C:\Users\Professional\AppData\Local\Programs\Python\Python312\Lib\site-packages\aiohttp\connector.py", line 1050, in _create_connection
    _, proto = await self._create_direct_connection(req, traces, timeout)
               ^^^^^^^^^^^^^^^^^^^^^^^^^^^^^^^^^^^^^^^^^^^^^^^^^^^^^^^^^^
  File "C:\Users\Professional\AppData\Local\Programs\Python\Python312\Lib\site-packages\aiohttp\connector.py", line 1335, in _create_direct_connection
    hosts = await self._resolve_host(host, port, traces=traces)
            ^^^^^^^^^^^^^^^^^^^^^^^^^^^^^^^^^^^^^^^^^^^^^^^^^^^
  File "C:\Users\Professional\AppData\Local\Programs\Python\Python312\Lib\site-packages\aiohttp\connector.py", line 964, in _resolve_host
    await future
asyncio.exceptions.CancelledError

The above exception was the direct cause of the following exception:

Traceback (most recent call last):
  File "d:\Develop\Python\trade_bot\11.9.1\core\rest_client.py", line 206, in request
    async with self.session.request(
  File "C:\Users\Professional\AppData\Local\Programs\Python\Python312\Lib\site-packages\aiohttp\client.py", line 1360, in __aenter__
    self._resp: _RetType = await self._coro
                           ^^^^^^^^^^^^^^^^
  File "C:\Users\Professional\AppData\Local\Programs\Python\Python312\Lib\site-packages\aiohttp\client.py", line 578, in _request
    with timer:
  File "C:\Users\Professional\AppData\Local\Programs\Python\Python312\Lib\site-packages\aiohttp\helpers.py", line 749, in __exit__
    raise asyncio.TimeoutError from exc_val
TimeoutError
[07-08  14:41:07] ERROR bot [mode=REST] : ❌ Time sync permanently failed after 3 attempts
[07-08  14:41:09] ERROR bot [mode=REST] : [TimeoutError] GET https://www.okx.com/api/v5/account/positions, attempt 2/4, sleeping 2.1s before retry
Traceback (most recent call last):
  File "C:\Users\Professional\AppData\Local\Programs\Python\Python312\Lib\site-packages\aiohttp\client.py", line 663, in _request
    conn = await self._connector.connect(
           ^^^^^^^^^^^^^^^^^^^^^^^^^^^^^^
  File "C:\Users\Professional\AppData\Local\Programs\Python\Python312\Lib\site-packages\aiohttp\connector.py", line 538, in connect
    proto = await self._create_connection(req, traces, timeout)
            ^^^^^^^^^^^^^^^^^^^^^^^^^^^^^^^^^^^^^^^^^^^^^^^^^^^
  File "C:\Users\Professional\AppData\Local\Programs\Python\Python312\Lib\site-packages\aiohttp\connector.py", line 1050, in _create_connection
    _, proto = await self._create_direct_connection(req, traces, timeout)
               ^^^^^^^^^^^^^^^^^^^^^^^^^^^^^^^^^^^^^^^^^^^^^^^^^^^^^^^^^^
  File "C:\Users\Professional\AppData\Local\Programs\Python\Python312\Lib\site-packages\aiohttp\connector.py", line 1335, in _create_direct_connection
    hosts = await self._resolve_host(host, port, traces=traces)
            ^^^^^^^^^^^^^^^^^^^^^^^^^^^^^^^^^^^^^^^^^^^^^^^^^^^
  File "C:\Users\Professional\AppData\Local\Programs\Python\Python312\Lib\site-packages\aiohttp\connector.py", line 964, in _resolve_host
    await future
asyncio.exceptions.CancelledError

The above exception was the direct cause of the following exception:

Traceback (most recent call last):
  File "d:\Develop\Python\trade_bot\11.9.1\core\rest_client.py", line 206, in request
    async with self.session.request(
  File "C:\Users\Professional\AppData\Local\Programs\Python\Python312\Lib\site-packages\aiohttp\client.py", line 1360, in __aenter__
    self._resp: _RetType = await self._coro
                           ^^^^^^^^^^^^^^^^
  File "C:\Users\Professional\AppData\Local\Programs\Python\Python312\Lib\site-packages\aiohttp\client.py", line 578, in _request
    with timer:
  File "C:\Users\Professional\AppData\Local\Programs\Python\Python312\Lib\site-packages\aiohttp\helpers.py", line 749, in __exit__
    raise asyncio.TimeoutError from exc_val
TimeoutError
[07-08  14:41:09] ERROR bot [mode=REST] : [TimeoutError] GET https://www.okx.com/api/v5/account/positions, attempt 2/4, sleeping 2.1s before retry
Traceback (most recent call last):
  File "C:\Users\Professional\AppData\Local\Programs\Python\Python312\Lib\site-packages\aiohttp\client.py", line 663, in _request
    conn = await self._connector.connect(
           ^^^^^^^^^^^^^^^^^^^^^^^^^^^^^^
  File "C:\Users\Professional\AppData\Local\Programs\Python\Python312\Lib\site-packages\aiohttp\connector.py", line 538, in connect
    proto = await self._create_connection(req, traces, timeout)
            ^^^^^^^^^^^^^^^^^^^^^^^^^^^^^^^^^^^^^^^^^^^^^^^^^^^
  File "C:\Users\Professional\AppData\Local\Programs\Python\Python312\Lib\site-packages\aiohttp\connector.py", line 1050, in _create_connection
    _, proto = await self._create_direct_connection(req, traces, timeout)
               ^^^^^^^^^^^^^^^^^^^^^^^^^^^^^^^^^^^^^^^^^^^^^^^^^^^^^^^^^^
  File "C:\Users\Professional\AppData\Local\Programs\Python\Python312\Lib\site-packages\aiohttp\connector.py", line 1335, in _create_direct_connection
    hosts = await self._resolve_host(host, port, traces=traces)
            ^^^^^^^^^^^^^^^^^^^^^^^^^^^^^^^^^^^^^^^^^^^^^^^^^^^
  File "C:\Users\Professional\AppData\Local\Programs\Python\Python312\Lib\site-packages\aiohttp\connector.py", line 964, in _resolve_host
    await future
asyncio.exceptions.CancelledError

The above exception was the direct cause of the following exception:

Traceback (most recent call last):
  File "d:\Develop\Python\trade_bot\11.9.1\core\rest_client.py", line 206, in request
    async with self.session.request(
  File "C:\Users\Professional\AppData\Local\Programs\Python\Python312\Lib\site-packages\aiohttp\client.py", line 1360, in __aenter__
    self._resp: _RetType = await self._coro
                           ^^^^^^^^^^^^^^^^
  File "C:\Users\Professional\AppData\Local\Programs\Python\Python312\Lib\site-packages\aiohttp\client.py", line 578, in _request
    with timer:
  File "C:\Users\Professional\AppData\Local\Programs\Python\Python312\Lib\site-packages\aiohttp\helpers.py", line 749, in __exit__
    raise asyncio.TimeoutError from exc_val
TimeoutError
[07-08  14:41:15] ERROR bot [mode=REST] : [TimeoutError] POST https://www.okx.com/api/v5/trade/cancel-order, attempt 3/4, sleeping 4.1s before retry
Traceback (most recent call last):
  File "C:\Users\Professional\AppData\Local\Programs\Python\Python312\Lib\site-packages\aiohttp\client.py", line 663, in _request
    conn = await self._connector.connect(
           ^^^^^^^^^^^^^^^^^^^^^^^^^^^^^^
  File "C:\Users\Professional\AppData\Local\Programs\Python\Python312\Lib\site-packages\aiohttp\connector.py", line 538, in connect
    proto = await self._create_connection(req, traces, timeout)
            ^^^^^^^^^^^^^^^^^^^^^^^^^^^^^^^^^^^^^^^^^^^^^^^^^^^
  File "C:\Users\Professional\AppData\Local\Programs\Python\Python312\Lib\site-packages\aiohttp\connector.py", line 1050, in _create_connection
    _, proto = await self._create_direct_connection(req, traces, timeout)
               ^^^^^^^^^^^^^^^^^^^^^^^^^^^^^^^^^^^^^^^^^^^^^^^^^^^^^^^^^^
  File "C:\Users\Professional\AppData\Local\Programs\Python\Python312\Lib\site-packages\aiohttp\connector.py", line 1335, in _create_direct_connection
    hosts = await self._resolve_host(host, port, traces=traces)
            ^^^^^^^^^^^^^^^^^^^^^^^^^^^^^^^^^^^^^^^^^^^^^^^^^^^
  File "C:\Users\Professional\AppData\Local\Programs\Python\Python312\Lib\site-packages\aiohttp\connector.py", line 964, in _resolve_host
    await future
asyncio.exceptions.CancelledError

The above exception was the direct cause of the following exception:

Traceback (most recent call last):
  File "d:\Develop\Python\trade_bot\11.9.1\core\rest_client.py", line 206, in request
    async with self.session.request(
  File "C:\Users\Professional\AppData\Local\Programs\Python\Python312\Lib\site-packages\aiohttp\client.py", line 1360, in __aenter__
    self._resp: _RetType = await self._coro
                           ^^^^^^^^^^^^^^^^
  File "C:\Users\Professional\AppData\Local\Programs\Python\Python312\Lib\site-packages\aiohttp\client.py", line 578, in _request
    with timer:
  File "C:\Users\Professional\AppData\Local\Programs\Python\Python312\Lib\site-packages\aiohttp\helpers.py", line 749, in __exit__
    raise asyncio.TimeoutError from exc_val
TimeoutError
[07-08  14:41:20] ERROR bot [mode=REST] : API error code=53000 response={'msg': 'Invalid token', 'code': '53000'}
[07-08  14:41:20] ERROR bot [mode=ORDER] : ❌ [OrderMode] cancel-order failed for 2752004720165179392: API error 53000
Traceback (most recent call last):
  File "d:\Develop\Python\trade_bot\11.9.1\core\order_mode.py", line 26, in cancel_order
    await self.rest.request(
  File "d:\Develop\Python\trade_bot\11.9.1\core\rest_client.py", line 294, in request
    raise RuntimeError(f"API error {code}")
RuntimeError: API error 53000
[07-08  14:41:20] ERROR bot [mode=REST] : API error code=53000 response={'msg': 'Invalid token', 'code': '53000'}
[07-08  14:41:20] ERROR bot [mode=ORDER] : ❌ [OrderMode] cancel-order failed for 2752004737210830848: API error 53000
Traceback (most recent call last):
  File "d:\Develop\Python\trade_bot\11.9.1\core\order_mode.py", line 26, in cancel_order
    await self.rest.request(
  File "d:\Develop\Python\trade_bot\11.9.1\core\rest_client.py", line 294, in request
    raise RuntimeError(f"API error {code}")
RuntimeError: API error 53000
[07-08  14:41:20] ERROR bot [mode=REST] : API error code=53000 response={'msg': 'Invalid token', 'code': '53000'}
[07-08  14:41:21] ERROR bot [mode=REST] : API error code=53000 response={'msg': 'Invalid token', 'code': '53000'}
[07-08  14:41:21] ERROR bot [mode=REST] : API error code=53000 response={'msg': 'Invalid token', 'code': '53000'}
[07-08  14:41:21] ERROR bot [mode=ORDER] : ❌ [OrderMode] place error: API error 53000
[07-08  14:41:22] ERROR bot [mode=REST] : API error code=53000 response={'msg': 'Invalid token', 'code': '53000'}
[07-08  14:41:31] ERROR bot [mode=REST] : API error code=53000 response={'msg': 'Invalid token', 'code': '53000'}
[07-08  14:41:32] ERROR bot [mode=REST] : API error code=53000 response={'msg': 'Invalid token', 'code': '53000'}
[07-08  14:41:32] ERROR bot [mode=ORDER] : ❌ [OrderMode] place error: API error 53000
[07-08  14:41:32] ERROR bot [mode=REST] : API error code=53000 response={'msg': 'Invalid token', 'code': '53000'}
[07-08  14:41:42] ERROR bot [mode=REST] : API error code=53000 response={'msg': 'Invalid token', 'code': '53000'}
[07-08  14:41:43] ERROR bot [mode=REST] : API error code=53000 response={'msg': 'Invalid token', 'code': '53000'}
[07-08  14:41:43] ERROR bot [mode=ORDER] : ❌ [OrderMode] place error: API error 53000
[07-08  14:41:43] ERROR bot [mode=REST] : API error code=53000 response={'msg': 'Invalid token', 'code': '53000'}
[07-08  14:41:54] ERROR bot [mode=REST] : API error code=53000 response={'msg': 'Invalid token', 'code': '53000'}
[07-08  14:41:54] ERROR bot [mode=REST] : API error code=53000 response={'msg': 'Invalid token', 'code': '53000'}
[07-08  14:41:54] ERROR bot [mode=ORDER] : ❌ [OrderMode] place error: API error 53000
[07-08  14:41:54] ERROR bot [mode=REST] : API error code=53000 response={'msg': 'Invalid token', 'code': '53000'}
[07-08  14:42:05] ERROR bot [mode=REST] : API error code=53000 response={'msg': 'Invalid token', 'code': '53000'}
[07-08  14:42:05] ERROR bot [mode=REST] : API error code=53000 response={'msg': 'Invalid token', 'code': '53000'}
[07-08  14:42:05] ERROR bot [mode=ORDER] : ❌ [OrderMode] place error: API error 53000
[07-08  14:42:05] ERROR bot [mode=REST] : API error code=53000 response={'msg': 'Invalid token', 'code': '53000'}
[07-08  14:42:16] ERROR bot [mode=REST] : API error code=53000 response={'msg': 'Invalid token', 'code': '53000'}
[07-08  14:42:16] ERROR bot [mode=REST] : API error code=53000 response={'msg': 'Invalid token', 'code': '53000'}
[07-08  14:42:16] ERROR bot [mode=ORDER] : ❌ [OrderMode] place error: API error 53000
[07-08  14:42:16] ERROR bot [mode=REST] : API error code=53000 response={'msg': 'Invalid token', 'code': '53000'}
[07-08  14:42:27] ERROR bot [mode=REST] : API error code=53000 response={'msg': 'Invalid token', 'code': '53000'}
[07-08  14:42:27] ERROR bot [mode=REST] : API error code=53000 response={'msg': 'Invalid token', 'code': '53000'}
[07-08  14:42:27] ERROR bot [mode=ORDER] : ❌ [OrderMode] place error: API error 53000
[07-08  14:42:28] ERROR bot [mode=REST] : API error code=53000 response={'msg': 'Invalid token', 'code': '53000'}
[07-08  14:42:38] ERROR bot [mode=REST] : API error code=53000 response={'msg': 'Invalid token', 'code': '53000'}
[07-08  14:42:39] ERROR bot [mode=REST] : API error code=53000 response={'msg': 'Invalid token', 'code': '53000'}
[07-08  14:42:39] ERROR bot [mode=REST] : API error code=53000 response={'msg': 'Invalid token', 'code': '53000'}
[07-08  14:42:39] ERROR bot [mode=ORDER] : ❌ [OrderMode] place error: API error 53000
[07-08  14:42:49] ERROR bot [mode=REST] : API error code=53000 response={'msg': 'Invalid token', 'code': '53000'}
[07-08  14:42:50] ERROR bot [mode=REST] : API error code=53000 response={'msg': 'Invalid token', 'code': '53000'}
[07-08  14:42:50] ERROR bot [mode=ORDER] : ❌ [OrderMode] place error: API error 53000
[07-08  14:42:50] ERROR bot [mode=REST] : API error code=53000 response={'msg': 'Invalid token', 'code': '53000'}
[07-08  14:43:00] ERROR bot [mode=REST] : API error code=53000 response={'msg': 'Invalid token', 'code': '53000'}
[07-08  14:43:01] ERROR bot [mode=REST] : API error code=53000 response={'msg': 'Invalid token', 'code': '53000'}
[07-08  14:43:01] ERROR bot [mode=ORDER] : ❌ [OrderMode] place error: API error 53000
[07-08  14:43:01] ERROR bot [mode=REST] : API error code=53000 response={'msg': 'Invalid token', 'code': '53000'}
[07-08  14:43:11] ERROR bot [mode=REST] : API error code=53000 response={'msg': 'Invalid token', 'code': '53000'}
[07-08  14:43:12] ERROR bot [mode=REST] : API error code=53000 response={'msg': 'Invalid token', 'code': '53000'}
[07-08  14:43:12] ERROR bot [mode=ORDER] : ❌ [OrderMode] place error: API error 53000
[07-08  14:43:12] ERROR bot [mode=REST] : API error code=53000 response={'msg': 'Invalid token', 'code': '53000'}
[07-08  14:43:22] ERROR bot [mode=REST] : API error code=53000 response={'msg': 'Invalid token', 'code': '53000'}
[07-08  14:43:23] ERROR bot [mode=REST] : API error code=53000 response={'msg': 'Invalid token', 'code': '53000'}
[07-08  14:43:23] ERROR bot [mode=ORDER] : ❌ [OrderMode] place error: API error 53000
[07-08  14:43:23] ERROR bot [mode=REST] : API error code=53000 response={'msg': 'Invalid token', 'code': '53000'}
[07-08  14:43:33] ERROR bot [mode=REST] : API error code=53000 response={'msg': 'Invalid token', 'code': '53000'}
[07-08  14:43:34] ERROR bot [mode=REST] : API error code=53000 response={'msg': 'Invalid token', 'code': '53000'}
[07-08  14:43:34] ERROR bot [mode=ORDER] : ❌ [OrderMode] place error: API error 53000
[07-08  14:43:34] ERROR bot [mode=REST] : API error code=53000 response={'msg': 'Invalid token', 'code': '53000'}
[07-08  14:43:44] ERROR bot [mode=REST] : API error code=53000 response={'msg': 'Invalid token', 'code': '53000'}
[07-08  14:43:45] ERROR bot [mode=REST] : API error code=53000 response={'msg': 'Invalid token', 'code': '53000'}
[07-08  14:43:45] ERROR bot [mode=ORDER] : ❌ [OrderMode] place error: API error 53000
[07-08  14:43:45] ERROR bot [mode=REST] : API error code=53000 response={'msg': 'Invalid token', 'code': '53000'}
[07-08  14:43:55] ERROR bot [mode=REST] : API error code=53000 response={'msg': 'Invalid token', 'code': '53000'}
[07-08  14:43:56] ERROR bot [mode=REST] : API error code=53000 response={'msg': 'Invalid token', 'code': '53000'}
[07-08  14:43:56] ERROR bot [mode=ORDER] : ❌ [OrderMode] place error: API error 53000
[07-08  14:43:56] ERROR bot [mode=REST] : API error code=53000 response={'msg': 'Invalid token', 'code': '53000'}
[07-08  14:44:06] ERROR bot [mode=REST] : API error code=53000 response={'msg': 'Invalid token', 'code': '53000'}
[07-08  14:44:07] ERROR bot [mode=REST] : API error code=53000 response={'msg': 'Invalid token', 'code': '53000'}
[07-08  14:44:07] ERROR bot [mode=ORDER] : ❌ [OrderMode] place error: API error 53000
[07-08  14:44:07] ERROR bot [mode=REST] : API error code=53000 response={'msg': 'Invalid token', 'code': '53000'}
[07-08  14:44:17] ERROR bot [mode=REST] : API error code=53000 response={'msg': 'Invalid token', 'code': '53000'}
[07-08  14:44:18] ERROR bot [mode=REST] : API error code=53000 response={'msg': 'Invalid token', 'code': '53000'}
[07-08  14:44:18] ERROR bot [mode=ORDER] : ❌ [OrderMode] place error: API error 53000
[07-08  14:44:18] ERROR bot [mode=REST] : API error code=53000 response={'msg': 'Invalid token', 'code': '53000'}
[07-08  14:44:28] ERROR bot [mode=REST] : API error code=53000 response={'msg': 'Invalid token', 'code': '53000'}
[07-08  14:44:29] ERROR bot [mode=REST] : API error code=53000 response={'msg': 'Invalid token', 'code': '53000'}
[07-08  14:44:29] ERROR bot [mode=ORDER] : ❌ [OrderMode] place error: API error 53000
[07-08  14:44:29] ERROR bot [mode=REST] : API error code=53000 response={'msg': 'Invalid token', 'code': '53000'}
[07-08  14:44:40] ERROR bot [mode=REST] : API error code=53000 response={'msg': 'Invalid token', 'code': '53000'}
[07-08  14:44:40] ERROR bot [mode=REST] : API error code=53000 response={'msg': 'Invalid token', 'code': '53000'}
[07-08  14:44:40] ERROR bot [mode=ORDER] : ❌ [OrderMode] place error: API error 53000
[07-08  14:44:40] ERROR bot [mode=REST] : API error code=53000 response={'msg': 'Invalid token', 'code': '53000'}
[07-08  14:44:51] ERROR bot [mode=REST] : API error code=53000 response={'msg': 'Invalid token', 'code': '53000'}
[07-08  14:44:52] ERROR bot [mode=REST] : API error code=53000 response={'msg': 'Invalid token', 'code': '53000'}
[07-08  14:44:52] ERROR bot [mode=ORDER] : ❌ [OrderMode] place error: API error 53000
[07-08  14:44:52] ERROR bot [mode=REST] : API error code=53000 response={'msg': 'Invalid token', 'code': '53000'}
[07-08  14:45:02] ERROR bot [mode=REST] : API error code=53000 response={'msg': 'Invalid token', 'code': '53000'}
[07-08  14:45:03] ERROR bot [mode=REST] : API error code=53000 response={'msg': 'Invalid token', 'code': '53000'}
[07-08  14:45:03] ERROR bot [mode=ORDER] : ❌ [OrderMode] place error: API error 53000
[07-08  14:45:03] ERROR bot [mode=REST] : API error code=53000 response={'msg': 'Invalid token', 'code': '53000'}
[07-08  14:45:13] ERROR bot [mode=REST] : API error code=53000 response={'msg': 'Invalid token', 'code': '53000'}
[07-08  14:45:14] ERROR bot [mode=REST] : API error code=53000 response={'msg': 'Invalid token', 'code': '53000'}
[07-08  14:45:14] ERROR bot [mode=ORDER] : ❌ [OrderMode] place error: API error 53000
[07-08  14:45:14] ERROR bot [mode=REST] : API error code=53000 response={'msg': 'Invalid token', 'code': '53000'}
[07-08  14:45:25] ERROR bot [mode=REST] : API error code=53000 response={'msg': 'Invalid token', 'code': '53000'}
[07-08  14:45:25] ERROR bot [mode=REST] : API error code=53000 response={'msg': 'Invalid token', 'code': '53000'}
[07-08  14:45:25] ERROR bot [mode=ORDER] : ❌ [OrderMode] place error: API error 53000
[07-08  14:45:25] ERROR bot [mode=REST] : API error code=53000 response={'msg': 'Invalid token', 'code': '53000'}
[07-08  14:45:36] ERROR bot [mode=REST] : API error code=53000 response={'msg': 'Invalid token', 'code': '53000'}
[07-08  14:45:36] ERROR bot [mode=REST] : API error code=53000 response={'msg': 'Invalid token', 'code': '53000'}
[07-08  14:45:36] ERROR bot [mode=ORDER] : ❌ [OrderMode] place error: API error 53000
[07-08  14:45:36] ERROR bot [mode=REST] : API error code=53000 response={'msg': 'Invalid token', 'code': '53000'}
[07-08  14:45:47] ERROR bot [mode=REST] : API error code=53000 response={'msg': 'Invalid token', 'code': '53000'}
[07-08  14:45:48] ERROR bot [mode=REST] : API error code=53000 response={'msg': 'Invalid token', 'code': '53000'}
[07-08  14:45:48] ERROR bot [mode=ORDER] : ❌ [OrderMode] place error: API error 53000
[07-08  14:45:48] ERROR bot [mode=REST] : API error code=53000 response={'msg': 'Invalid token', 'code': '53000'}
[07-08  14:45:58] ERROR bot [mode=REST] : API error code=53000 response={'msg': 'Invalid token', 'code': '53000'}
[07-08  14:45:59] ERROR bot [mode=REST] : API error code=53000 response={'msg': 'Invalid token', 'code': '53000'}
[07-08  14:45:59] ERROR bot [mode=ORDER] : ❌ [OrderMode] place error: API error 53000
[07-08  14:45:59] ERROR bot [mode=REST] : API error code=53000 response={'msg': 'Invalid token', 'code': '53000'}
[07-08  14:46:09] ERROR bot [mode=REST] : API error code=53000 response={'msg': 'Invalid token', 'code': '53000'}
[07-08  14:46:10] ERROR bot [mode=REST] : API error code=53000 response={'msg': 'Invalid token', 'code': '53000'}
[07-08  14:46:10] ERROR bot [mode=ORDER] : ❌ [OrderMode] place error: API error 53000
[07-08  14:46:10] ERROR bot [mode=REST] : API error code=53000 response={'msg': 'Invalid token', 'code': '53000'}
[07-08  14:46:20] ERROR bot [mode=REST] : API error code=53000 response={'msg': 'Invalid token', 'code': '53000'}
[07-08  14:46:21] ERROR bot [mode=REST] : API error code=53000 response={'msg': 'Invalid token', 'code': '53000'}
[07-08  14:46:21] ERROR bot [mode=ORDER] : ❌ [OrderMode] place error: API error 53000
[07-08  14:46:21] ERROR bot [mode=REST] : API error code=53000 response={'msg': 'Invalid token', 'code': '53000'}
[07-08  14:46:31] ERROR bot [mode=REST] : API error code=53000 response={'msg': 'Invalid token', 'code': '53000'}
[07-08  14:46:32] ERROR bot [mode=REST] : API error code=53000 response={'msg': 'Invalid token', 'code': '53000'}
[07-08  14:46:32] ERROR bot [mode=ORDER] : ❌ [OrderMode] place error: API error 53000
[07-08  14:46:32] ERROR bot [mode=REST] : API error code=53000 response={'msg': 'Invalid token', 'code': '53000'}
[07-08  14:46:42] ERROR bot [mode=REST] : API error code=53000 response={'msg': 'Invalid token', 'code': '53000'}
[07-08  14:46:43] ERROR bot [mode=REST] : API error code=53000 response={'msg': 'Invalid token', 'code': '53000'}
[07-08  14:46:43] ERROR bot [mode=ORDER] : ❌ [OrderMode] place error: API error 53000
[07-08  14:46:43] ERROR bot [mode=REST] : API error code=53000 response={'msg': 'Invalid token', 'code': '53000'}
[07-08  14:46:54] ERROR bot [mode=REST] : API error code=53000 response={'msg': 'Invalid token', 'code': '53000'}
[07-08  14:46:54] ERROR bot [mode=REST] : API error code=53000 response={'msg': 'Invalid token', 'code': '53000'}
[07-08  14:46:54] ERROR bot [mode=ORDER] : ❌ [OrderMode] place error: API error 53000
[07-08  14:46:54] ERROR bot [mode=REST] : API error code=53000 response={'msg': 'Invalid token', 'code': '53000'}
[07-08  14:47:05] ERROR bot [mode=REST] : API error code=53000 response={'msg': 'Invalid token', 'code': '53000'}
[07-08  14:47:05] ERROR bot [mode=REST] : API error code=53000 response={'msg': 'Invalid token', 'code': '53000'}
[07-08  14:47:05] ERROR bot [mode=ORDER] : ❌ [OrderMode] place error: API error 53000
[07-08  14:47:06] ERROR bot [mode=REST] : API error code=53000 response={'msg': 'Invalid token', 'code': '53000'}
[07-08  14:47:16] ERROR bot [mode=REST] : API error code=53000 response={'msg': 'Invalid token', 'code': '53000'}
[07-08  14:47:16] ERROR bot [mode=REST] : API error code=53000 response={'msg': 'Invalid token', 'code': '53000'}
[07-08  14:47:16] ERROR bot [mode=ORDER] : ❌ [OrderMode] place error: API error 53000
[07-08  14:47:16] ERROR bot [mode=REST] : API error code=53000 response={'msg': 'Invalid token', 'code': '53000'}
[07-08  14:47:27] ERROR bot [mode=REST] : API error code=53000 response={'msg': 'Invalid token', 'code': '53000'}
[07-08  14:47:28] ERROR bot [mode=REST] : API error code=53000 response={'msg': 'Invalid token', 'code': '53000'}
[07-08  14:47:28] ERROR bot [mode=ORDER] : ❌ [OrderMode] place error: API error 53000
[07-08  14:47:28] ERROR bot [mode=REST] : API error code=53000 response={'msg': 'Invalid token', 'code': '53000'}
[07-08  14:47:32] ERROR bot [mode=LOOP] : Loop-level exception
Traceback (most recent call last):
  File "d:\Develop\Python\trade_bot\11.9.1\core\orchestrator.py", line 268, in _shutdown
    await self.tpsl.stop()
  File "d:\Develop\Python\trade_bot\11.9.1\core\tpsl_monitor.py", line 85, in stop
    await self._task
  File "d:\Develop\Python\trade_bot\11.9.1\core\tpsl_monitor.py", line 161, in _loop
    lq, lp, sq, sp =  await self._get_state()
                     ^^^^^^^^^^^^^^^^^^^^^^^
  File "d:\Develop\Python\trade_bot\11.9.1\core\tpsl_monitor.py", line 253, in _get_state
    resp = await self.rest.request("GET", "/api/v5/account/positions",params={"instId": self.inst}        )
           ^^^^^^^^^^^^^^^^^^^^^^^^^^^^^^^^^^^^^^^^^^^^^^^^^^^^^^^^^^^^^^^^^^^^^^^^^^^^^^^^^^^^^^^^^^^^^^^^
  File "d:\Develop\Python\trade_bot\11.9.1\core\rest_client.py", line 294, in request
    raise RuntimeError(f"API error {code}")
RuntimeError: API error 53000
[07-08  14:56:49] ERROR bot [mode=REST] : API error code=1 response={'code': '1', 'data': [{'clOrdId': '', 'ordId': '2753657947768016896', 'sCode': '51400', 'sMsg': 'Order cancellation failed as the order has been filled, canceled or does not exist.', 'ts': '1754567809572'}], 'inTime': '1754567809571191', 'msg': 'All operations failed', 'outTime': '1754567809573193'}
[07-08  14:56:49] ERROR bot [mode=ORDER] : ❌ [OrderMode] cancel-order failed for 2753657947768016896: API error 1
Traceback (most recent call last):
  File "d:\Develop\Python\trade_bot\11.9.1\core\order_mode.py", line 26, in cancel_order
    await self.rest.request(
  File "d:\Develop\Python\trade_bot\11.9.1\core\rest_client.py", line 294, in request
    raise RuntimeError(f"API error {code}")
RuntimeError: API error 1
[07-08  14:57:55] ERROR bot [mode=REST] : API error code=50002 response={'code': '50002', 'data': [], 'msg': 'Incorrect json data format'}
[07-08  14:57:55] ERROR bot [mode=-] : ❌ [PreHEDGE] TP placement failed: code=-1, msg=
[07-08  14:58:03] ERROR bot [mode=REST] : API error code=1 response={'code': '1', 'data': [{'algoClOrdId': '', 'algoId': '', 'clOrdId': '', 'sCode': '51277', 'sMsg': 'TP trigger price cannot be higher than the last price ', 'tag': ''}], 'msg': ''}
[07-08  14:58:03] ERROR bot [mode=-] : ❌ [TPSL] conditional failed for SDOGEUSDTSWAP: API error 1
[07-08  14:58:10] ERROR bot [mode=REST] : API error code=1 response={'code': '1', 'data': [{'algoClOrdId': '', 'algoId': '', 'clOrdId': '', 'sCode': '51277', 'sMsg': 'TP trigger price cannot be higher than the last price ', 'tag': ''}], 'msg': ''}
[07-08  14:58:10] ERROR bot [mode=-] : ❌ [TPSL] conditional failed for SDOGEUSDTSWAP: API error 1
[07-08  14:58:17] ERROR bot [mode=REST] : API error code=1 response={'code': '1', 'data': [{'algoClOrdId': '', 'algoId': '', 'clOrdId': '', 'sCode': '51277', 'sMsg': 'TP trigger price cannot be higher than the last price ', 'tag': ''}], 'msg': ''}
[07-08  14:58:17] ERROR bot [mode=-] : ❌ [TPSL] conditional failed for SDOGEUSDTSWAP: API error 1
[07-08  14:58:23] ERROR bot [mode=REST] : API error code=1 response={'code': '1', 'data': [{'algoClOrdId': '', 'algoId': '', 'clOrdId': '', 'sCode': '51277', 'sMsg': 'TP trigger price cannot be higher than the last price ', 'tag': ''}], 'msg': ''}
[07-08  14:58:23] ERROR bot [mode=-] : ❌ [TPSL] conditional failed for SDOGEUSDTSWAP: API error 1
[07-08  14:58:30] ERROR bot [mode=REST] : API error code=1 response={'code': '1', 'data': [{'algoClOrdId': '', 'algoId': '', 'clOrdId': '', 'sCode': '51277', 'sMsg': 'TP trigger price cannot be higher than the last price ', 'tag': ''}], 'msg': ''}
[07-08  14:58:30] ERROR bot [mode=-] : ❌ [TPSL] conditional failed for SDOGEUSDTSWAP: API error 1
[07-08  14:58:37] ERROR bot [mode=REST] : API error code=1 response={'code': '1', 'data': [{'algoClOrdId': '', 'algoId': '', 'clOrdId': '', 'sCode': '51277', 'sMsg': 'TP trigger price cannot be higher than the last price ', 'tag': ''}], 'msg': ''}
[07-08  14:58:37] ERROR bot [mode=-] : ❌ [TPSL] conditional failed for SDOGEUSDTSWAP: API error 1
[07-08  14:58:43] ERROR bot [mode=REST] : API error code=1 response={'code': '1', 'data': [{'algoClOrdId': '', 'algoId': '', 'clOrdId': '', 'sCode': '51277', 'sMsg': 'TP trigger price cannot be higher than the last price ', 'tag': ''}], 'msg': ''}
[07-08  14:58:43] ERROR bot [mode=-] : ❌ [TPSL] conditional failed for SDOGEUSDTSWAP: API error 1
[07-08  14:58:50] ERROR bot [mode=REST] : API error code=1 response={'code': '1', 'data': [{'algoClOrdId': '', 'algoId': '', 'clOrdId': '', 'sCode': '51277', 'sMsg': 'TP trigger price cannot be higher than the last price ', 'tag': ''}], 'msg': ''}
[07-08  14:58:50] ERROR bot [mode=-] : ❌ [TPSL] conditional failed for SDOGEUSDTSWAP: API error 1
[07-08  14:58:57] ERROR bot [mode=REST] : API error code=1 response={'code': '1', 'data': [{'algoClOrdId': '', 'algoId': '', 'clOrdId': '', 'sCode': '51277', 'sMsg': 'TP trigger price cannot be higher than the last price ', 'tag': ''}], 'msg': ''}
[07-08  14:58:57] ERROR bot [mode=-] : ❌ [TPSL] conditional failed for SDOGEUSDTSWAP: API error 1
[07-08  14:59:04] ERROR bot [mode=REST] : API error code=1 response={'code': '1', 'data': [{'algoClOrdId': '', 'algoId': '', 'clOrdId': '', 'sCode': '51277', 'sMsg': 'TP trigger price cannot be higher than the last price ', 'tag': ''}], 'msg': ''}
[07-08  14:59:04] ERROR bot [mode=-] : ❌ [TPSL] conditional failed for SDOGEUSDTSWAP: API error 1
[07-08  14:59:11] ERROR bot [mode=REST] : API error code=1 response={'code': '1', 'data': [{'algoClOrdId': '', 'algoId': '', 'clOrdId': '', 'sCode': '51277', 'sMsg': 'TP trigger price cannot be higher than the last price ', 'tag': ''}], 'msg': ''}
[07-08  14:59:11] ERROR bot [mode=-] : ❌ [TPSL] conditional failed for SDOGEUSDTSWAP: API error 1
[07-08  14:59:18] ERROR bot [mode=REST] : API error code=1 response={'code': '1', 'data': [{'algoClOrdId': '', 'algoId': '', 'clOrdId': '', 'sCode': '51277', 'sMsg': 'TP trigger price cannot be higher than the last price ', 'tag': ''}], 'msg': ''}
[07-08  14:59:18] ERROR bot [mode=-] : ❌ [TPSL] conditional failed for SDOGEUSDTSWAP: API error 1
[07-08  14:59:24] ERROR bot [mode=REST] : API error code=1 response={'code': '1', 'data': [{'algoClOrdId': '', 'algoId': '', 'clOrdId': '', 'sCode': '51277', 'sMsg': 'TP trigger price cannot be higher than the last price ', 'tag': ''}], 'msg': ''}
[07-08  14:59:24] ERROR bot [mode=-] : ❌ [TPSL] conditional failed for SDOGEUSDTSWAP: API error 1
[07-08  14:59:31] ERROR bot [mode=REST] : API error code=1 response={'code': '1', 'data': [{'algoClOrdId': '', 'algoId': '', 'clOrdId': '', 'sCode': '51277', 'sMsg': 'TP trigger price cannot be higher than the last price ', 'tag': ''}], 'msg': ''}
[07-08  14:59:31] ERROR bot [mode=-] : ❌ [TPSL] conditional failed for SDOGEUSDTSWAP: API error 1
[07-08  14:59:38] ERROR bot [mode=REST] : API error code=1 response={'code': '1', 'data': [{'algoClOrdId': '', 'algoId': '', 'clOrdId': '', 'sCode': '51277', 'sMsg': 'TP trigger price cannot be higher than the last price ', 'tag': ''}], 'msg': ''}
[07-08  14:59:38] ERROR bot [mode=-] : ❌ [TPSL] conditional failed for SDOGEUSDTSWAP: API error 1
[07-08  14:59:45] ERROR bot [mode=REST] : API error code=1 response={'code': '1', 'data': [{'algoClOrdId': '', 'algoId': '', 'clOrdId': '', 'sCode': '51277', 'sMsg': 'TP trigger price cannot be higher than the last price ', 'tag': ''}], 'msg': ''}
[07-08  14:59:45] ERROR bot [mode=-] : ❌ [TPSL] conditional failed for SDOGEUSDTSWAP: API error 1
[07-08  14:59:52] ERROR bot [mode=REST] : API error code=1 response={'code': '1', 'data': [{'algoClOrdId': '', 'algoId': '', 'clOrdId': '', 'sCode': '51277', 'sMsg': 'TP trigger price cannot be higher than the last price ', 'tag': ''}], 'msg': ''}
[07-08  14:59:52] ERROR bot [mode=-] : ❌ [TPSL] conditional failed for SDOGEUSDTSWAP: API error 1
[07-08  14:59:59] ERROR bot [mode=REST] : API error code=1 response={'code': '1', 'data': [{'algoClOrdId': '', 'algoId': '', 'clOrdId': '', 'sCode': '51277', 'sMsg': 'TP trigger price cannot be higher than the last price ', 'tag': ''}], 'msg': ''}
[07-08  14:59:59] ERROR bot [mode=-] : ❌ [TPSL] conditional failed for SDOGEUSDTSWAP: API error 1
[07-08  15:00:06] ERROR bot [mode=REST] : API error code=1 response={'code': '1', 'data': [{'algoClOrdId': '', 'algoId': '', 'clOrdId': '', 'sCode': '51277', 'sMsg': 'TP trigger price cannot be higher than the last price ', 'tag': ''}], 'msg': ''}
[07-08  15:00:06] ERROR bot [mode=-] : ❌ [TPSL] conditional failed for SDOGEUSDTSWAP: API error 1
[07-08  15:00:18] ERROR bot [mode=REST] : API error code=50002 response={'code': '50002', 'data': [], 'msg': 'Incorrect json data format'}
[07-08  15:00:33] ERROR bot [mode=-] : ❌ [TPSL] loop error: float division by zero
Traceback (most recent call last):
  File "d:\Develop\Python\trade_bot\11.9.1\core\tpsl_monitor.py", line 221, in _loop
    abs(current.get(cid_init, 0)  - tp_init)  / tp_init  > self.threshold
    ~~~~~~~~~~~~~~~~~~~~~~~~~~~~~~~~~~~~~~~~~~^~~~~~~~~
ZeroDivisionError: float division by zero
[07-08  15:00:34] ERROR bot [mode=REST] : API error code=50002 response={'code': '50002', 'data': [], 'msg': 'Incorrect json data format'}
[07-08  15:00:34] ERROR bot [mode=REST] : API error code=1 response={'code': '1', 'data': [{'algoClOrdId': '', 'algoId': '', 'clOrdId': '', 'sCode': '51023', 'sMsg': "Position doesn't exist. ", 'tag': ''}], 'msg': ''}
[07-08  15:00:34] ERROR bot [mode=-] : ❌ [PreHEDGE] TP placement failed: API error 1
Traceback (most recent call last):
  File "d:\Develop\Python\trade_bot\11.9.1\core\prehedge_watcher.py", line 158, in _place_tp
    response = await self.rest.request(
               ^^^^^^^^^^^^^^^^^^^^^^^^
  File "d:\Develop\Python\trade_bot\11.9.1\core\rest_client.py", line 294, in request
    raise RuntimeError(f"API error {code}")
RuntimeError: API error 1
[07-08  15:07:31] ERROR bot [mode=REST] : API error code=50002 response={'code': '50002', 'data': [], 'msg': 'Incorrect json data format'}
[07-08  15:07:31] ERROR bot [mode=-] : ❌ [PreHEDGE] TP placement failed: code=-1, msg=
[07-08  15:20:17] ERROR bot [mode=LOOP] : Loop-level exception
Traceback (most recent call last):
  File "d:\Develop\Python\trade_bot\11.9.1\core\prehedge_watcher.py", line 56, in run
    await self._place_tp()
  File "d:\Develop\Python\trade_bot\11.9.1\core\prehedge_watcher.py", line 132, in _place_tp
    raise ValueError("entry_price is None in _place_tp()")
ValueError: entry_price is None in _place_tp()
[07-08  15:23:06] ERROR bot [mode=REST] : API error code=50002 response={'code': '50002', 'data': [], 'msg': 'Incorrect json data format'}
[07-08  15:23:06] ERROR bot [mode=-] : ❌ [PreHEDGE] TP placement failed: code=-1, msg=
[07-08  15:35:59] ERROR bot [mode=REST] : API error code=1 response={'code': '1', 'data': [{'algoClOrdId': '', 'algoId': '', 'clOrdId': '', 'sCode': '51279', 'sMsg': 'TP trigger price cannot be lower than the last price ', 'tag': ''}], 'msg': ''}
[07-08  15:35:59] ERROR bot [mode=-] : ❌ [TPSL] conditional failed for LDOGEUSDTSWAP: API error 1
[07-08  15:36:05] ERROR bot [mode=REST] : API error code=1 response={'code': '1', 'data': [{'algoClOrdId': '', 'algoId': '', 'clOrdId': '', 'sCode': '51279', 'sMsg': 'TP trigger price cannot be lower than the last price ', 'tag': ''}], 'msg': ''}
[07-08  15:36:05] ERROR bot [mode=-] : ❌ [TPSL] conditional failed for LDOGEUSDTSWAP: API error 1
[07-08  15:36:12] ERROR bot [mode=REST] : API error code=1 response={'code': '1', 'data': [{'algoClOrdId': '', 'algoId': '', 'clOrdId': '', 'sCode': '51279', 'sMsg': 'TP trigger price cannot be lower than the last price ', 'tag': ''}], 'msg': ''}
[07-08  15:36:12] ERROR bot [mode=-] : ❌ [TPSL] conditional failed for LDOGEUSDTSWAP: API error 1
[07-08  15:36:19] ERROR bot [mode=REST] : API error code=1 response={'code': '1', 'data': [{'algoClOrdId': '', 'algoId': '', 'clOrdId': '', 'sCode': '51279', 'sMsg': 'TP trigger price cannot be lower than the last price ', 'tag': ''}], 'msg': ''}
[07-08  15:36:19] ERROR bot [mode=-] : ❌ [TPSL] conditional failed for LDOGEUSDTSWAP: API error 1
[07-08  15:36:26] ERROR bot [mode=REST] : API error code=1 response={'code': '1', 'data': [{'algoClOrdId': '', 'algoId': '', 'clOrdId': '', 'sCode': '51279', 'sMsg': 'TP trigger price cannot be lower than the last price ', 'tag': ''}], 'msg': ''}
[07-08  15:36:26] ERROR bot [mode=-] : ❌ [TPSL] conditional failed for LDOGEUSDTSWAP: API error 1
[07-08  15:49:46] ERROR bot [mode=REST] : API error code=1 response={'code': '1', 'data': [{'algoClOrdId': '', 'algoId': '', 'clOrdId': '', 'sCode': '51023', 'sMsg': "Position doesn't exist. ", 'tag': ''}], 'msg': ''}
[07-08  15:49:46] ERROR bot [mode=-] : ❌ [PreHEDGE] TP placement failed: API error 1
Traceback (most recent call last):
  File "d:\Develop\Python\trade_bot\11.9.1\core\prehedge_watcher.py", line 162, in _place_tp
    response = await self.rest.request(
               ^^^^^^^^^^^^^^^^^^^^^^^^
  File "d:\Develop\Python\trade_bot\11.9.1\core\rest_client.py", line 294, in request
    raise RuntimeError(f"API error {code}")
RuntimeError: API error 1
[07-08  15:54:42] ERROR bot [mode=REST] : API error code=1 response={'code': '1', 'data': [{'algoClOrdId': '', 'algoId': '', 'clOrdId': '', 'sCode': '51023', 'sMsg': "Position doesn't exist. ", 'tag': ''}], 'msg': ''}
[07-08  15:54:42] ERROR bot [mode=-] : ❌ [PreHEDGE] TP placement failed: API error 1
Traceback (most recent call last):
  File "d:\Develop\Python\trade_bot\11.9.1\core\prehedge_watcher.py", line 162, in _place_tp
    response = await self.rest.request(
               ^^^^^^^^^^^^^^^^^^^^^^^^
  File "d:\Develop\Python\trade_bot\11.9.1\core\rest_client.py", line 294, in request
    raise RuntimeError(f"API error {code}")
RuntimeError: API error 1
[07-08  20:00:57] ERROR bot [mode=REST] : [TimeoutError] GET https://www.okx.com/api/v5/account/positions, attempt 1/4, sleeping 1.0s before retry
Traceback (most recent call last):
  File "C:\Users\Professional\AppData\Local\Programs\Python\Python312\Lib\site-packages\aiohttp\client.py", line 663, in _request
    conn = await self._connector.connect(
           ^^^^^^^^^^^^^^^^^^^^^^^^^^^^^^
  File "C:\Users\Professional\AppData\Local\Programs\Python\Python312\Lib\site-packages\aiohttp\connector.py", line 538, in connect
    proto = await self._create_connection(req, traces, timeout)
            ^^^^^^^^^^^^^^^^^^^^^^^^^^^^^^^^^^^^^^^^^^^^^^^^^^^
  File "C:\Users\Professional\AppData\Local\Programs\Python\Python312\Lib\site-packages\aiohttp\connector.py", line 1050, in _create_connection
    _, proto = await self._create_direct_connection(req, traces, timeout)
               ^^^^^^^^^^^^^^^^^^^^^^^^^^^^^^^^^^^^^^^^^^^^^^^^^^^^^^^^^^
  File "C:\Users\Professional\AppData\Local\Programs\Python\Python312\Lib\site-packages\aiohttp\connector.py", line 1353, in _create_direct_connection
    transp, proto = await self._wrap_create_connection(
                    ^^^^^^^^^^^^^^^^^^^^^^^^^^^^^^^^^^^
  File "C:\Users\Professional\AppData\Local\Programs\Python\Python312\Lib\site-packages\aiohttp\connector.py", line 1109, in _wrap_create_connection
    sock = await aiohappyeyeballs.start_connection(
           ^^^^^^^^^^^^^^^^^^^^^^^^^^^^^^^^^^^^^^^^
  File "C:\Users\Professional\AppData\Local\Programs\Python\Python312\Lib\site-packages\aiohappyeyeballs\impl.py", line 87, in start_connection
    sock, _, _ = await _staggered.staggered_race(
                 ^^^^^^^^^^^^^^^^^^^^^^^^^^^^^^^^
  File "C:\Users\Professional\AppData\Local\Programs\Python\Python312\Lib\site-packages\aiohappyeyeballs\_staggered.py", line 165, in staggered_race
    done = await _wait_one(
           ^^^^^^^^^^^^^^^^
  File "C:\Users\Professional\AppData\Local\Programs\Python\Python312\Lib\site-packages\aiohappyeyeballs\_staggered.py", line 46, in _wait_one
    return await wait_next
           ^^^^^^^^^^^^^^^
asyncio.exceptions.CancelledError

The above exception was the direct cause of the following exception:

Traceback (most recent call last):
  File "d:\Develop\Python\trade_bot\11.9.1\core\rest_client.py", line 206, in request
    async with self.session.request(
  File "C:\Users\Professional\AppData\Local\Programs\Python\Python312\Lib\site-packages\aiohttp\client.py", line 1360, in __aenter__
    self._resp: _RetType = await self._coro
                           ^^^^^^^^^^^^^^^^
  File "C:\Users\Professional\AppData\Local\Programs\Python\Python312\Lib\site-packages\aiohttp\client.py", line 578, in _request
    with timer:
  File "C:\Users\Professional\AppData\Local\Programs\Python\Python312\Lib\site-packages\aiohttp\helpers.py", line 749, in __exit__
    raise asyncio.TimeoutError from exc_val
TimeoutError
[07-08  22:14:39] ERROR bot [mode=LOOP] : Loop-level exception
Traceback (most recent call last):
  File "d:\Develop\Python\trade_bot\11.9.1\core\orchestrator.py", line 214, in _reinvest_loop
    logger.info("[REINVEST-LOOP] вход в цикл, жду tp_filled_evt")
  File "C:\Users\Professional\AppData\Local\Programs\Python\Python312\Lib\logging\__init__.py", line 1539, in info
    self._log(INFO, msg, args, **kwargs)
  File "C:\Users\Professional\AppData\Local\Programs\Python\Python312\Lib\logging\__init__.py", line 1684, in _log
    self.handle(record)
  File "C:\Users\Professional\AppData\Local\Programs\Python\Python312\Lib\logging\__init__.py", line 1700, in handle
    self.callHandlers(record)
  File "C:\Users\Professional\AppData\Local\Programs\Python\Python312\Lib\logging\__init__.py", line 1762, in callHandlers
    hdlr.handle(record)
  File "C:\Users\Professional\AppData\Local\Programs\Python\Python312\Lib\logging\__init__.py", line 1028, in handle
    self.emit(record)
  File "d:\Develop\Python\trade_bot\11.9.1\core\ui.py", line 30, in emit
    msg = self.format(record)
          ^^^^^^^^^^^^^^^^^^^
  File "C:\Users\Professional\AppData\Local\Programs\Python\Python312\Lib\logging\__init__.py", line 999, in format
    return fmt.format(record)
           ^^^^^^^^^^^^^^^^^^
  File "C:\Users\Professional\AppData\Local\Programs\Python\Python312\Lib\logging\__init__.py", line 706, in format
    s = self.formatMessage(record)
        ^^^^^^^^^^^^^^^^^^^^^^^^^^
  File "C:\Users\Professional\AppData\Local\Programs\Python\Python312\Lib\logging\__init__.py", line 675, in formatMessage
    return self._style.format(record)
           ^^^^^^^^^^^^^^^^^^^^^^^^^^
  File "C:\Users\Professional\AppData\Local\Programs\Python\Python312\Lib\logging\__init__.py", line 464, in format
    return self._format(record)
           ^^^^^^^^^^^^^^^^^^^^
  File "C:\Users\Professional\AppData\Local\Programs\Python\Python312\Lib\logging\__init__.py", line 460, in _format
    return self._fmt % values
           ~~~~~~~~~~^~~~~~~~
ValueError: unsupported format character 'H' (0x48) at index 1
[07-08  22:14:40] ERROR bot [mode=LOOP] : Loop-level exception
Traceback (most recent call last):
  File "d:\Develop\Python\trade_bot\11.9.1\core\orchestrator.py", line 91, in run
    logger.info("Orchestrator started", extra={"mode": "START"})
  File "C:\Users\Professional\AppData\Local\Programs\Python\Python312\Lib\logging\__init__.py", line 1539, in info
    self._log(INFO, msg, args, **kwargs)
  File "C:\Users\Professional\AppData\Local\Programs\Python\Python312\Lib\logging\__init__.py", line 1684, in _log
    self.handle(record)
  File "C:\Users\Professional\AppData\Local\Programs\Python\Python312\Lib\logging\__init__.py", line 1700, in handle
    self.callHandlers(record)
  File "C:\Users\Professional\AppData\Local\Programs\Python\Python312\Lib\logging\__init__.py", line 1762, in callHandlers
    hdlr.handle(record)
  File "C:\Users\Professional\AppData\Local\Programs\Python\Python312\Lib\logging\__init__.py", line 1028, in handle
    self.emit(record)
  File "d:\Develop\Python\trade_bot\11.9.1\core\ui.py", line 30, in emit
    msg = self.format(record)
          ^^^^^^^^^^^^^^^^^^^
  File "C:\Users\Professional\AppData\Local\Programs\Python\Python312\Lib\logging\__init__.py", line 999, in format
    return fmt.format(record)
           ^^^^^^^^^^^^^^^^^^
  File "C:\Users\Professional\AppData\Local\Programs\Python\Python312\Lib\logging\__init__.py", line 706, in format
    s = self.formatMessage(record)
        ^^^^^^^^^^^^^^^^^^^^^^^^^^
  File "C:\Users\Professional\AppData\Local\Programs\Python\Python312\Lib\logging\__init__.py", line 675, in formatMessage
    return self._style.format(record)
           ^^^^^^^^^^^^^^^^^^^^^^^^^^
  File "C:\Users\Professional\AppData\Local\Programs\Python\Python312\Lib\logging\__init__.py", line 464, in format
    return self._format(record)
           ^^^^^^^^^^^^^^^^^^^^
  File "C:\Users\Professional\AppData\Local\Programs\Python\Python312\Lib\logging\__init__.py", line 460, in _format
    return self._fmt % values
           ~~~~~~~~~~^~~~~~~~
ValueError: unsupported format character 'H' (0x48) at index 1
[07-08  22:14:45] ERROR bot [mode=-] : ❌ [TPSL] loop error: unsupported format character 'H' (0x48) at index 1
Traceback (most recent call last):
  File "d:\Develop\Python\trade_bot\11.9.1\core\tpsl_monitor.py", line 154, in _loop
    logger.debug("🔄 [TPSL] initial sync pass")
  File "C:\Users\Professional\AppData\Local\Programs\Python\Python312\Lib\logging\__init__.py", line 1527, in debug
    self._log(DEBUG, msg, args, **kwargs)
  File "C:\Users\Professional\AppData\Local\Programs\Python\Python312\Lib\logging\__init__.py", line 1684, in _log
    self.handle(record)
  File "C:\Users\Professional\AppData\Local\Programs\Python\Python312\Lib\logging\__init__.py", line 1700, in handle
    self.callHandlers(record)
  File "C:\Users\Professional\AppData\Local\Programs\Python\Python312\Lib\logging\__init__.py", line 1762, in callHandlers
    hdlr.handle(record)
  File "C:\Users\Professional\AppData\Local\Programs\Python\Python312\Lib\logging\__init__.py", line 1028, in handle
    self.emit(record)
  File "d:\Develop\Python\trade_bot\11.9.1\core\ui.py", line 30, in emit
    msg = self.format(record)
          ^^^^^^^^^^^^^^^^^^^
  File "C:\Users\Professional\AppData\Local\Programs\Python\Python312\Lib\logging\__init__.py", line 999, in format
    return fmt.format(record)
           ^^^^^^^^^^^^^^^^^^
  File "C:\Users\Professional\AppData\Local\Programs\Python\Python312\Lib\logging\__init__.py", line 706, in format
    s = self.formatMessage(record)
        ^^^^^^^^^^^^^^^^^^^^^^^^^^
  File "C:\Users\Professional\AppData\Local\Programs\Python\Python312\Lib\logging\__init__.py", line 675, in formatMessage
    return self._style.format(record)
           ^^^^^^^^^^^^^^^^^^^^^^^^^^
  File "C:\Users\Professional\AppData\Local\Programs\Python\Python312\Lib\logging\__init__.py", line 464, in format
    return self._format(record)
           ^^^^^^^^^^^^^^^^^^^^
  File "C:\Users\Professional\AppData\Local\Programs\Python\Python312\Lib\logging\__init__.py", line 460, in _format
    return self._fmt % values
           ~~~~~~~~~~^~~~~~~~
ValueError: unsupported format character 'H' (0x48) at index 1
[07-08  22:14:45] ERROR bot [mode=LOOP] : Loop-level exception
Traceback (most recent call last):
  File "d:\Develop\Python\trade_bot\11.9.1\core\tpsl_monitor.py", line 154, in _loop
    logger.debug("🔄 [TPSL] initial sync pass")
  File "C:\Users\Professional\AppData\Local\Programs\Python\Python312\Lib\logging\__init__.py", line 1527, in debug
    self._log(DEBUG, msg, args, **kwargs)
  File "C:\Users\Professional\AppData\Local\Programs\Python\Python312\Lib\logging\__init__.py", line 1684, in _log
    self.handle(record)
  File "C:\Users\Professional\AppData\Local\Programs\Python\Python312\Lib\logging\__init__.py", line 1700, in handle
    self.callHandlers(record)
  File "C:\Users\Professional\AppData\Local\Programs\Python\Python312\Lib\logging\__init__.py", line 1762, in callHandlers
    hdlr.handle(record)
  File "C:\Users\Professional\AppData\Local\Programs\Python\Python312\Lib\logging\__init__.py", line 1028, in handle
    self.emit(record)
  File "d:\Develop\Python\trade_bot\11.9.1\core\ui.py", line 30, in emit
    msg = self.format(record)
          ^^^^^^^^^^^^^^^^^^^
  File "C:\Users\Professional\AppData\Local\Programs\Python\Python312\Lib\logging\__init__.py", line 999, in format
    return fmt.format(record)
           ^^^^^^^^^^^^^^^^^^
  File "C:\Users\Professional\AppData\Local\Programs\Python\Python312\Lib\logging\__init__.py", line 706, in format
    s = self.formatMessage(record)
        ^^^^^^^^^^^^^^^^^^^^^^^^^^
  File "C:\Users\Professional\AppData\Local\Programs\Python\Python312\Lib\logging\__init__.py", line 675, in formatMessage
    return self._style.format(record)
           ^^^^^^^^^^^^^^^^^^^^^^^^^^
  File "C:\Users\Professional\AppData\Local\Programs\Python\Python312\Lib\logging\__init__.py", line 464, in format
    return self._format(record)
           ^^^^^^^^^^^^^^^^^^^^
  File "C:\Users\Professional\AppData\Local\Programs\Python\Python312\Lib\logging\__init__.py", line 460, in _format
    return self._fmt % values
           ~~~~~~~~~~^~~~~~~~
ValueError: unsupported format character 'H' (0x48) at index 1

During handling of the above exception, another exception occurred:

Traceback (most recent call last):
  File "d:\Develop\Python\trade_bot\11.9.1\core\tpsl_monitor.py", line 249, in _loop
    logger.error(f"❌ [TPSL] loop error: {e}", exc_info=e)
  File "C:\Users\Professional\AppData\Local\Programs\Python\Python312\Lib\logging\__init__.py", line 1568, in error
    self._log(ERROR, msg, args, **kwargs)
  File "C:\Users\Professional\AppData\Local\Programs\Python\Python312\Lib\logging\__init__.py", line 1684, in _log
    self.handle(record)
  File "C:\Users\Professional\AppData\Local\Programs\Python\Python312\Lib\logging\__init__.py", line 1700, in handle
    self.callHandlers(record)
  File "C:\Users\Professional\AppData\Local\Programs\Python\Python312\Lib\logging\__init__.py", line 1762, in callHandlers
    hdlr.handle(record)
  File "C:\Users\Professional\AppData\Local\Programs\Python\Python312\Lib\logging\__init__.py", line 1028, in handle
    self.emit(record)
  File "d:\Develop\Python\trade_bot\11.9.1\core\ui.py", line 30, in emit
    msg = self.format(record)
          ^^^^^^^^^^^^^^^^^^^
  File "C:\Users\Professional\AppData\Local\Programs\Python\Python312\Lib\logging\__init__.py", line 999, in format
    return fmt.format(record)
           ^^^^^^^^^^^^^^^^^^
  File "C:\Users\Professional\AppData\Local\Programs\Python\Python312\Lib\logging\__init__.py", line 706, in format
    s = self.formatMessage(record)
        ^^^^^^^^^^^^^^^^^^^^^^^^^^
  File "C:\Users\Professional\AppData\Local\Programs\Python\Python312\Lib\logging\__init__.py", line 675, in formatMessage
    return self._style.format(record)
           ^^^^^^^^^^^^^^^^^^^^^^^^^^
  File "C:\Users\Professional\AppData\Local\Programs\Python\Python312\Lib\logging\__init__.py", line 464, in format
    return self._format(record)
           ^^^^^^^^^^^^^^^^^^^^
  File "C:\Users\Professional\AppData\Local\Programs\Python\Python312\Lib\logging\__init__.py", line 460, in _format
    return self._fmt % values
           ~~~~~~~~~~^~~~~~~~
ValueError: unsupported format character 'H' (0x48) at index 1
[07-08  22:14:45] ERROR bot [mode=MAIN] : 💥 Fatal error: unsupported format character 'H' (0x48) at index 1
Traceback (most recent call last):
  File "C:\Users\Professional\AppData\Local\Programs\Python\Python312\Lib\asyncio\base_events.py", line 1871, in call_exception_handler
    ctx.run(self._exception_handler, self, context)
  File "d:\Develop\Python\trade_bot\11.9.1\core\orchestrator.py", line 281, in _handle_loop_exception
    logger.error("Loop-level exception",
  File "C:\Users\Professional\AppData\Local\Programs\Python\Python312\Lib\logging\__init__.py", line 1568, in error
    self._log(ERROR, msg, args, **kwargs)
  File "C:\Users\Professional\AppData\Local\Programs\Python\Python312\Lib\logging\__init__.py", line 1684, in _log
    self.handle(record)
  File "C:\Users\Professional\AppData\Local\Programs\Python\Python312\Lib\logging\__init__.py", line 1700, in handle
    self.callHandlers(record)
  File "C:\Users\Professional\AppData\Local\Programs\Python\Python312\Lib\logging\__init__.py", line 1762, in callHandlers
    hdlr.handle(record)
  File "C:\Users\Professional\AppData\Local\Programs\Python\Python312\Lib\logging\__init__.py", line 1028, in handle
    self.emit(record)
  File "d:\Develop\Python\trade_bot\11.9.1\core\ui.py", line 30, in emit
    msg = self.format(record)
          ^^^^^^^^^^^^^^^^^^^
  File "C:\Users\Professional\AppData\Local\Programs\Python\Python312\Lib\logging\__init__.py", line 999, in format
    return fmt.format(record)
           ^^^^^^^^^^^^^^^^^^
  File "C:\Users\Professional\AppData\Local\Programs\Python\Python312\Lib\logging\__init__.py", line 706, in format
    s = self.formatMessage(record)
        ^^^^^^^^^^^^^^^^^^^^^^^^^^
  File "C:\Users\Professional\AppData\Local\Programs\Python\Python312\Lib\logging\__init__.py", line 675, in formatMessage
    return self._style.format(record)
           ^^^^^^^^^^^^^^^^^^^^^^^^^^
  File "C:\Users\Professional\AppData\Local\Programs\Python\Python312\Lib\logging\__init__.py", line 464, in format
    return self._format(record)
           ^^^^^^^^^^^^^^^^^^^^
  File "C:\Users\Professional\AppData\Local\Programs\Python\Python312\Lib\logging\__init__.py", line 460, in _format
    return self._fmt % values
           ~~~~~~~~~~^~~~~~~~
ValueError: unsupported format character 'H' (0x48) at index 1

During handling of the above exception, another exception occurred:

Traceback (most recent call last):
  File "C:\Users\Professional\AppData\Local\Programs\Python\Python312\Lib\asyncio\base_events.py", line 1880, in call_exception_handler
    self.default_exception_handler({
  File "C:\Users\Professional\AppData\Local\Programs\Python\Python312\Lib\asyncio\base_events.py", line 1821, in default_exception_handler
    logger.error('\n'.join(log_lines), exc_info=exc_info)
  File "C:\Users\Professional\AppData\Local\Programs\Python\Python312\Lib\logging\__init__.py", line 1568, in error
    self._log(ERROR, msg, args, **kwargs)
  File "C:\Users\Professional\AppData\Local\Programs\Python\Python312\Lib\logging\__init__.py", line 1684, in _log
    self.handle(record)
  File "C:\Users\Professional\AppData\Local\Programs\Python\Python312\Lib\logging\__init__.py", line 1700, in handle
    self.callHandlers(record)
  File "C:\Users\Professional\AppData\Local\Programs\Python\Python312\Lib\logging\__init__.py", line 1762, in callHandlers
    hdlr.handle(record)
  File "C:\Users\Professional\AppData\Local\Programs\Python\Python312\Lib\logging\__init__.py", line 1028, in handle
    self.emit(record)
  File "d:\Develop\Python\trade_bot\11.9.1\core\ui.py", line 30, in emit
    msg = self.format(record)
          ^^^^^^^^^^^^^^^^^^^
  File "C:\Users\Professional\AppData\Local\Programs\Python\Python312\Lib\logging\__init__.py", line 999, in format
    return fmt.format(record)
           ^^^^^^^^^^^^^^^^^^
  File "C:\Users\Professional\AppData\Local\Programs\Python\Python312\Lib\logging\__init__.py", line 706, in format
    s = self.formatMessage(record)
        ^^^^^^^^^^^^^^^^^^^^^^^^^^
  File "C:\Users\Professional\AppData\Local\Programs\Python\Python312\Lib\logging\__init__.py", line 675, in formatMessage
    return self._style.format(record)
           ^^^^^^^^^^^^^^^^^^^^^^^^^^
  File "C:\Users\Professional\AppData\Local\Programs\Python\Python312\Lib\logging\__init__.py", line 464, in format
    return self._format(record)
           ^^^^^^^^^^^^^^^^^^^^
  File "C:\Users\Professional\AppData\Local\Programs\Python\Python312\Lib\logging\__init__.py", line 460, in _format
    return self._fmt % values
           ~~~~~~~~~~^~~~~~~~
ValueError: unsupported format character 'H' (0x48) at index 1

During handling of the above exception, another exception occurred:

Traceback (most recent call last):
  File "d:\Develop\Python\trade_bot\11.9.1\main.py", line 172, in <module>
    asyncio.run(main())
  File "C:\Users\Professional\AppData\Local\Programs\Python\Python312\Lib\asyncio\runners.py", line 193, in run
    with Runner(debug=debug, loop_factory=loop_factory) as runner:
  File "C:\Users\Professional\AppData\Local\Programs\Python\Python312\Lib\asyncio\runners.py", line 62, in __exit__
    self.close()
  File "C:\Users\Professional\AppData\Local\Programs\Python\Python312\Lib\asyncio\runners.py", line 70, in close
    _cancel_all_tasks(loop)
  File "C:\Users\Professional\AppData\Local\Programs\Python\Python312\Lib\asyncio\runners.py", line 211, in _cancel_all_tasks
    loop.call_exception_handler({
  File "C:\Users\Professional\AppData\Local\Programs\Python\Python312\Lib\asyncio\base_events.py", line 1890, in call_exception_handler
    logger.error('Exception in default exception handler '
  File "C:\Users\Professional\AppData\Local\Programs\Python\Python312\Lib\logging\__init__.py", line 1568, in error
    self._log(ERROR, msg, args, **kwargs)
  File "C:\Users\Professional\AppData\Local\Programs\Python\Python312\Lib\logging\__init__.py", line 1684, in _log
    self.handle(record)
  File "C:\Users\Professional\AppData\Local\Programs\Python\Python312\Lib\logging\__init__.py", line 1700, in handle
    self.callHandlers(record)
  File "C:\Users\Professional\AppData\Local\Programs\Python\Python312\Lib\logging\__init__.py", line 1762, in callHandlers
    hdlr.handle(record)
  File "C:\Users\Professional\AppData\Local\Programs\Python\Python312\Lib\logging\__init__.py", line 1028, in handle
    self.emit(record)
  File "d:\Develop\Python\trade_bot\11.9.1\core\ui.py", line 30, in emit
    msg = self.format(record)
          ^^^^^^^^^^^^^^^^^^^
  File "C:\Users\Professional\AppData\Local\Programs\Python\Python312\Lib\logging\__init__.py", line 999, in format
    return fmt.format(record)
           ^^^^^^^^^^^^^^^^^^
  File "C:\Users\Professional\AppData\Local\Programs\Python\Python312\Lib\logging\__init__.py", line 706, in format
    s = self.formatMessage(record)
        ^^^^^^^^^^^^^^^^^^^^^^^^^^
  File "C:\Users\Professional\AppData\Local\Programs\Python\Python312\Lib\logging\__init__.py", line 675, in formatMessage
    return self._style.format(record)
           ^^^^^^^^^^^^^^^^^^^^^^^^^^
  File "C:\Users\Professional\AppData\Local\Programs\Python\Python312\Lib\logging\__init__.py", line 464, in format
    return self._format(record)
           ^^^^^^^^^^^^^^^^^^^^
  File "C:\Users\Professional\AppData\Local\Programs\Python\Python312\Lib\logging\__init__.py", line 460, in _format
    return self._fmt % values
           ~~~~~~~~~~^~~~~~~~
ValueError: unsupported format character 'H' (0x48) at index 1
[07-08  22:32:10] ERROR bot [mode=LOOP] : Loop-level exception
Traceback (most recent call last):
  File "d:\Develop\Python\trade_bot\11.9.1\core\tpsl_monitor.py", line 163, in _loop
    lq, lp, sq, sp =  await self._get_state()
                     ^^^^^^^^^^^^^^^^^^^^^^^
  File "d:\Develop\Python\trade_bot\11.9.1\core\tpsl_monitor.py", line 257, in _get_state
    resp = await self.rest.request("GET", "/api/v5/account/positions",params={"instId": self.inst}        )
           ^^^^^^^^^^^^^^^^^^^^^^^^^^^^^^^^^^^^^^^^^^^^^^^^^^^^^^^^^^^^^^^^^^^^^^^^^^^^^^^^^^^^^^^^^^^^^^^^
  File "d:\Develop\Python\trade_bot\11.9.1\core\rest_client.py", line 206, in request
    async with self.session.request(
  File "C:\Users\Professional\AppData\Local\Programs\Python\Python312\Lib\site-packages\aiohttp\client.py", line 1360, in __aenter__
    self._resp: _RetType = await self._coro
                           ^^^^^^^^^^^^^^^^
  File "C:\Users\Professional\AppData\Local\Programs\Python\Python312\Lib\site-packages\aiohttp\client.py", line 493, in _request
    raise RuntimeError("Session is closed")
RuntimeError: Session is closed

During handling of the above exception, another exception occurred:

Traceback (most recent call last):
  File "C:\Users\Professional\AppData\Local\Programs\Python\Python312\Lib\site-packages\textual\message_pump.py", line 241, in app
    return active_app.get()
           ^^^^^^^^^^^^^^^^
LookupError: <ContextVar name='active_app' at 0x00000264481AE5C0>

During handling of the above exception, another exception occurred:

Traceback (most recent call last):
  File "d:\Develop\Python\trade_bot\11.9.1\core\tpsl_monitor.py", line 245, in _loop
    logger.warning("⚠️ TPSL loop terminated: HTTP session closed")
  File "C:\Users\Professional\AppData\Local\Programs\Python\Python312\Lib\logging\__init__.py", line 1551, in warning
    self._log(WARNING, msg, args, **kwargs)
  File "C:\Users\Professional\AppData\Local\Programs\Python\Python312\Lib\logging\__init__.py", line 1684, in _log
    self.handle(record)
  File "C:\Users\Professional\AppData\Local\Programs\Python\Python312\Lib\logging\__init__.py", line 1700, in handle
    self.callHandlers(record)
  File "C:\Users\Professional\AppData\Local\Programs\Python\Python312\Lib\logging\__init__.py", line 1762, in callHandlers
    hdlr.handle(record)
  File "C:\Users\Professional\AppData\Local\Programs\Python\Python312\Lib\logging\__init__.py", line 1028, in handle
    self.emit(record)
  File "d:\Develop\Python\trade_bot\11.9.1\core\ui.py", line 32, in emit
    self.text_log.write(msg)
  File "C:\Users\Professional\AppData\Local\Programs\Python\Python312\Lib\site-packages\textual\widgets\_log.py", line 195, in write
    self.scroll_end(animate=False, immediate=True, x_axis=False)
  File "C:\Users\Professional\AppData\Local\Programs\Python\Python312\Lib\site-packages\textual\widget.py", line 2900, in scroll_end
    _lazily_scroll_end()
  File "C:\Users\Professional\AppData\Local\Programs\Python\Python312\Lib\site-packages\textual\widget.py", line 2883, in _lazily_scroll_end
    self._scroll_to(
  File "C:\Users\Professional\AppData\Local\Programs\Python\Python312\Lib\site-packages\textual\widget.py", line 2583, in _scroll_to
    animator = self.app.animator
               ^^^^^^^^
  File "C:\Users\Professional\AppData\Local\Programs\Python\Python312\Lib\site-packages\textual\message_pump.py", line 248, in app
    raise NoActiveAppError()
textual._context.NoActiveAppError
[07-08  22:32:11] ERROR bot [mode=MAIN] : 💥 Fatal error: 
Traceback (most recent call last):
  File "C:\Users\Professional\AppData\Local\Programs\Python\Python312\Lib\site-packages\textual\message_pump.py", line 241, in app
    return active_app.get()
           ^^^^^^^^^^^^^^^^
LookupError: <ContextVar name='active_app' at 0x00000264481AE5C0>

During handling of the above exception, another exception occurred:

Traceback (most recent call last):
  File "C:\Users\Professional\AppData\Local\Programs\Python\Python312\Lib\asyncio\base_events.py", line 1871, in call_exception_handler
    ctx.run(self._exception_handler, self, context)
  File "d:\Develop\Python\trade_bot\11.9.1\core\orchestrator.py", line 281, in _handle_loop_exception
    logger.error("Loop-level exception",
  File "C:\Users\Professional\AppData\Local\Programs\Python\Python312\Lib\logging\__init__.py", line 1568, in error
    self._log(ERROR, msg, args, **kwargs)
  File "C:\Users\Professional\AppData\Local\Programs\Python\Python312\Lib\logging\__init__.py", line 1684, in _log
    self.handle(record)
  File "C:\Users\Professional\AppData\Local\Programs\Python\Python312\Lib\logging\__init__.py", line 1700, in handle
    self.callHandlers(record)
  File "C:\Users\Professional\AppData\Local\Programs\Python\Python312\Lib\logging\__init__.py", line 1762, in callHandlers
    hdlr.handle(record)
  File "C:\Users\Professional\AppData\Local\Programs\Python\Python312\Lib\logging\__init__.py", line 1028, in handle
    self.emit(record)
  File "d:\Develop\Python\trade_bot\11.9.1\core\ui.py", line 32, in emit
    self.text_log.write(msg)
  File "C:\Users\Professional\AppData\Local\Programs\Python\Python312\Lib\site-packages\textual\widgets\_log.py", line 195, in write
    self.scroll_end(animate=False, immediate=True, x_axis=False)
  File "C:\Users\Professional\AppData\Local\Programs\Python\Python312\Lib\site-packages\textual\widget.py", line 2900, in scroll_end
    _lazily_scroll_end()
  File "C:\Users\Professional\AppData\Local\Programs\Python\Python312\Lib\site-packages\textual\widget.py", line 2883, in _lazily_scroll_end
    self._scroll_to(
  File "C:\Users\Professional\AppData\Local\Programs\Python\Python312\Lib\site-packages\textual\widget.py", line 2583, in _scroll_to
    animator = self.app.animator
               ^^^^^^^^
  File "C:\Users\Professional\AppData\Local\Programs\Python\Python312\Lib\site-packages\textual\message_pump.py", line 248, in app
    raise NoActiveAppError()
textual._context.NoActiveAppError

During handling of the above exception, another exception occurred:

Traceback (most recent call last):
  File "C:\Users\Professional\AppData\Local\Programs\Python\Python312\Lib\site-packages\textual\message_pump.py", line 241, in app
    return active_app.get()
           ^^^^^^^^^^^^^^^^
LookupError: <ContextVar name='active_app' at 0x00000264481AE5C0>

During handling of the above exception, another exception occurred:

Traceback (most recent call last):
  File "C:\Users\Professional\AppData\Local\Programs\Python\Python312\Lib\asyncio\base_events.py", line 1880, in call_exception_handler
    self.default_exception_handler({
  File "C:\Users\Professional\AppData\Local\Programs\Python\Python312\Lib\asyncio\base_events.py", line 1821, in default_exception_handler
    logger.error('\n'.join(log_lines), exc_info=exc_info)
  File "C:\Users\Professional\AppData\Local\Programs\Python\Python312\Lib\logging\__init__.py", line 1568, in error
    self._log(ERROR, msg, args, **kwargs)
  File "C:\Users\Professional\AppData\Local\Programs\Python\Python312\Lib\logging\__init__.py", line 1684, in _log
    self.handle(record)
  File "C:\Users\Professional\AppData\Local\Programs\Python\Python312\Lib\logging\__init__.py", line 1700, in handle
    self.callHandlers(record)
  File "C:\Users\Professional\AppData\Local\Programs\Python\Python312\Lib\logging\__init__.py", line 1762, in callHandlers
    hdlr.handle(record)
  File "C:\Users\Professional\AppData\Local\Programs\Python\Python312\Lib\logging\__init__.py", line 1028, in handle
    self.emit(record)
  File "d:\Develop\Python\trade_bot\11.9.1\core\ui.py", line 32, in emit
    self.text_log.write(msg)
  File "C:\Users\Professional\AppData\Local\Programs\Python\Python312\Lib\site-packages\textual\widgets\_log.py", line 195, in write
    self.scroll_end(animate=False, immediate=True, x_axis=False)
  File "C:\Users\Professional\AppData\Local\Programs\Python\Python312\Lib\site-packages\textual\widget.py", line 2900, in scroll_end
    _lazily_scroll_end()
  File "C:\Users\Professional\AppData\Local\Programs\Python\Python312\Lib\site-packages\textual\widget.py", line 2883, in _lazily_scroll_end
    self._scroll_to(
  File "C:\Users\Professional\AppData\Local\Programs\Python\Python312\Lib\site-packages\textual\widget.py", line 2583, in _scroll_to
    animator = self.app.animator
               ^^^^^^^^
  File "C:\Users\Professional\AppData\Local\Programs\Python\Python312\Lib\site-packages\textual\message_pump.py", line 248, in app
    raise NoActiveAppError()
textual._context.NoActiveAppError

During handling of the above exception, another exception occurred:

Traceback (most recent call last):
  File "C:\Users\Professional\AppData\Local\Programs\Python\Python312\Lib\site-packages\textual\message_pump.py", line 241, in app
    return active_app.get()
           ^^^^^^^^^^^^^^^^
LookupError: <ContextVar name='active_app' at 0x00000264481AE5C0>

During handling of the above exception, another exception occurred:

Traceback (most recent call last):
  File "d:\Develop\Python\trade_bot\11.9.1\main.py", line 172, in <module>
    asyncio.run(main())
  File "C:\Users\Professional\AppData\Local\Programs\Python\Python312\Lib\asyncio\runners.py", line 193, in run
    with Runner(debug=debug, loop_factory=loop_factory) as runner:
  File "C:\Users\Professional\AppData\Local\Programs\Python\Python312\Lib\asyncio\runners.py", line 62, in __exit__
    self.close()
  File "C:\Users\Professional\AppData\Local\Programs\Python\Python312\Lib\asyncio\runners.py", line 70, in close
    _cancel_all_tasks(loop)
  File "C:\Users\Professional\AppData\Local\Programs\Python\Python312\Lib\asyncio\runners.py", line 211, in _cancel_all_tasks
    loop.call_exception_handler({
  File "C:\Users\Professional\AppData\Local\Programs\Python\Python312\Lib\asyncio\base_events.py", line 1890, in call_exception_handler
    logger.error('Exception in default exception handler '
  File "C:\Users\Professional\AppData\Local\Programs\Python\Python312\Lib\logging\__init__.py", line 1568, in error
    self._log(ERROR, msg, args, **kwargs)
  File "C:\Users\Professional\AppData\Local\Programs\Python\Python312\Lib\logging\__init__.py", line 1684, in _log
    self.handle(record)
  File "C:\Users\Professional\AppData\Local\Programs\Python\Python312\Lib\logging\__init__.py", line 1700, in handle
    self.callHandlers(record)
  File "C:\Users\Professional\AppData\Local\Programs\Python\Python312\Lib\logging\__init__.py", line 1762, in callHandlers
    hdlr.handle(record)
  File "C:\Users\Professional\AppData\Local\Programs\Python\Python312\Lib\logging\__init__.py", line 1028, in handle
    self.emit(record)
  File "d:\Develop\Python\trade_bot\11.9.1\core\ui.py", line 32, in emit
    self.text_log.write(msg)
  File "C:\Users\Professional\AppData\Local\Programs\Python\Python312\Lib\site-packages\textual\widgets\_log.py", line 195, in write
    self.scroll_end(animate=False, immediate=True, x_axis=False)
  File "C:\Users\Professional\AppData\Local\Programs\Python\Python312\Lib\site-packages\textual\widget.py", line 2900, in scroll_end
    _lazily_scroll_end()
  File "C:\Users\Professional\AppData\Local\Programs\Python\Python312\Lib\site-packages\textual\widget.py", line 2883, in _lazily_scroll_end
    self._scroll_to(
  File "C:\Users\Professional\AppData\Local\Programs\Python\Python312\Lib\site-packages\textual\widget.py", line 2583, in _scroll_to
    animator = self.app.animator
               ^^^^^^^^
  File "C:\Users\Professional\AppData\Local\Programs\Python\Python312\Lib\site-packages\textual\message_pump.py", line 248, in app
    raise NoActiveAppError()
textual._context.NoActiveAppError
[07-08  22:38:31] ERROR bot [mode=LOOP] : Loop-level exception
Traceback (most recent call last):
  File "d:\Develop\Python\trade_bot\11.9.1\core\tpsl_monitor.py", line 163, in _loop
    lq, lp, sq, sp =  await self._get_state()
                     ^^^^^^^^^^^^^^^^^^^^^^^
  File "d:\Develop\Python\trade_bot\11.9.1\core\tpsl_monitor.py", line 257, in _get_state
    resp = await self.rest.request("GET", "/api/v5/account/positions",params={"instId": self.inst}        )
           ^^^^^^^^^^^^^^^^^^^^^^^^^^^^^^^^^^^^^^^^^^^^^^^^^^^^^^^^^^^^^^^^^^^^^^^^^^^^^^^^^^^^^^^^^^^^^^^^
  File "d:\Develop\Python\trade_bot\11.9.1\core\rest_client.py", line 206, in request
    async with self.session.request(
  File "C:\Users\Professional\AppData\Local\Programs\Python\Python312\Lib\site-packages\aiohttp\client.py", line 1360, in __aenter__
    self._resp: _RetType = await self._coro
                           ^^^^^^^^^^^^^^^^
  File "C:\Users\Professional\AppData\Local\Programs\Python\Python312\Lib\site-packages\aiohttp\client.py", line 493, in _request
    raise RuntimeError("Session is closed")
RuntimeError: Session is closed

During handling of the above exception, another exception occurred:

Traceback (most recent call last):
  File "C:\Users\Professional\AppData\Local\Programs\Python\Python312\Lib\site-packages\textual\message_pump.py", line 241, in app
    return active_app.get()
           ^^^^^^^^^^^^^^^^
LookupError: <ContextVar name='active_app' at 0x000001F264E7E3E0>

During handling of the above exception, another exception occurred:

Traceback (most recent call last):
  File "d:\Develop\Python\trade_bot\11.9.1\core\tpsl_monitor.py", line 245, in _loop
    logger.warning("⚠️ TPSL loop terminated: HTTP session closed")
  File "C:\Users\Professional\AppData\Local\Programs\Python\Python312\Lib\logging\__init__.py", line 1551, in warning
    self._log(WARNING, msg, args, **kwargs)
  File "C:\Users\Professional\AppData\Local\Programs\Python\Python312\Lib\logging\__init__.py", line 1684, in _log
    self.handle(record)
  File "C:\Users\Professional\AppData\Local\Programs\Python\Python312\Lib\logging\__init__.py", line 1700, in handle
    self.callHandlers(record)
  File "C:\Users\Professional\AppData\Local\Programs\Python\Python312\Lib\logging\__init__.py", line 1762, in callHandlers
    hdlr.handle(record)
  File "C:\Users\Professional\AppData\Local\Programs\Python\Python312\Lib\logging\__init__.py", line 1028, in handle
    self.emit(record)
  File "d:\Develop\Python\trade_bot\11.9.1\core\ui.py", line 32, in emit
    self.text_log.write(msg)
  File "C:\Users\Professional\AppData\Local\Programs\Python\Python312\Lib\site-packages\textual\widgets\_log.py", line 195, in write
    self.scroll_end(animate=False, immediate=True, x_axis=False)
  File "C:\Users\Professional\AppData\Local\Programs\Python\Python312\Lib\site-packages\textual\widget.py", line 2900, in scroll_end
    _lazily_scroll_end()
  File "C:\Users\Professional\AppData\Local\Programs\Python\Python312\Lib\site-packages\textual\widget.py", line 2883, in _lazily_scroll_end
    self._scroll_to(
  File "C:\Users\Professional\AppData\Local\Programs\Python\Python312\Lib\site-packages\textual\widget.py", line 2583, in _scroll_to
    animator = self.app.animator
               ^^^^^^^^
  File "C:\Users\Professional\AppData\Local\Programs\Python\Python312\Lib\site-packages\textual\message_pump.py", line 248, in app
    raise NoActiveAppError()
textual._context.NoActiveAppError
[07-08  22:38:31] ERROR bot [mode=MAIN] : 💥 Fatal error: 
Traceback (most recent call last):
  File "C:\Users\Professional\AppData\Local\Programs\Python\Python312\Lib\site-packages\textual\message_pump.py", line 241, in app
    return active_app.get()
           ^^^^^^^^^^^^^^^^
LookupError: <ContextVar name='active_app' at 0x000001F264E7E3E0>

During handling of the above exception, another exception occurred:

Traceback (most recent call last):
  File "C:\Users\Professional\AppData\Local\Programs\Python\Python312\Lib\asyncio\base_events.py", line 1871, in call_exception_handler
    ctx.run(self._exception_handler, self, context)
  File "d:\Develop\Python\trade_bot\11.9.1\core\orchestrator.py", line 281, in _handle_loop_exception
    logger.error("Loop-level exception",
  File "C:\Users\Professional\AppData\Local\Programs\Python\Python312\Lib\logging\__init__.py", line 1568, in error
    self._log(ERROR, msg, args, **kwargs)
  File "C:\Users\Professional\AppData\Local\Programs\Python\Python312\Lib\logging\__init__.py", line 1684, in _log
    self.handle(record)
  File "C:\Users\Professional\AppData\Local\Programs\Python\Python312\Lib\logging\__init__.py", line 1700, in handle
    self.callHandlers(record)
  File "C:\Users\Professional\AppData\Local\Programs\Python\Python312\Lib\logging\__init__.py", line 1762, in callHandlers
    hdlr.handle(record)
  File "C:\Users\Professional\AppData\Local\Programs\Python\Python312\Lib\logging\__init__.py", line 1028, in handle
    self.emit(record)
  File "d:\Develop\Python\trade_bot\11.9.1\core\ui.py", line 32, in emit
    self.text_log.write(msg)
  File "C:\Users\Professional\AppData\Local\Programs\Python\Python312\Lib\site-packages\textual\widgets\_log.py", line 195, in write
    self.scroll_end(animate=False, immediate=True, x_axis=False)
  File "C:\Users\Professional\AppData\Local\Programs\Python\Python312\Lib\site-packages\textual\widget.py", line 2900, in scroll_end
    _lazily_scroll_end()
  File "C:\Users\Professional\AppData\Local\Programs\Python\Python312\Lib\site-packages\textual\widget.py", line 2883, in _lazily_scroll_end
    self._scroll_to(
  File "C:\Users\Professional\AppData\Local\Programs\Python\Python312\Lib\site-packages\textual\widget.py", line 2583, in _scroll_to
    animator = self.app.animator
               ^^^^^^^^
  File "C:\Users\Professional\AppData\Local\Programs\Python\Python312\Lib\site-packages\textual\message_pump.py", line 248, in app
    raise NoActiveAppError()
textual._context.NoActiveAppError

During handling of the above exception, another exception occurred:

Traceback (most recent call last):
  File "C:\Users\Professional\AppData\Local\Programs\Python\Python312\Lib\site-packages\textual\message_pump.py", line 241, in app
    return active_app.get()
           ^^^^^^^^^^^^^^^^
LookupError: <ContextVar name='active_app' at 0x000001F264E7E3E0>

During handling of the above exception, another exception occurred:

Traceback (most recent call last):
  File "C:\Users\Professional\AppData\Local\Programs\Python\Python312\Lib\asyncio\base_events.py", line 1880, in call_exception_handler
    self.default_exception_handler({
  File "C:\Users\Professional\AppData\Local\Programs\Python\Python312\Lib\asyncio\base_events.py", line 1821, in default_exception_handler
    logger.error('\n'.join(log_lines), exc_info=exc_info)
  File "C:\Users\Professional\AppData\Local\Programs\Python\Python312\Lib\logging\__init__.py", line 1568, in error
    self._log(ERROR, msg, args, **kwargs)
  File "C:\Users\Professional\AppData\Local\Programs\Python\Python312\Lib\logging\__init__.py", line 1684, in _log
    self.handle(record)
  File "C:\Users\Professional\AppData\Local\Programs\Python\Python312\Lib\logging\__init__.py", line 1700, in handle
    self.callHandlers(record)
  File "C:\Users\Professional\AppData\Local\Programs\Python\Python312\Lib\logging\__init__.py", line 1762, in callHandlers
    hdlr.handle(record)
  File "C:\Users\Professional\AppData\Local\Programs\Python\Python312\Lib\logging\__init__.py", line 1028, in handle
    self.emit(record)
  File "d:\Develop\Python\trade_bot\11.9.1\core\ui.py", line 32, in emit
    self.text_log.write(msg)
  File "C:\Users\Professional\AppData\Local\Programs\Python\Python312\Lib\site-packages\textual\widgets\_log.py", line 195, in write
    self.scroll_end(animate=False, immediate=True, x_axis=False)
  File "C:\Users\Professional\AppData\Local\Programs\Python\Python312\Lib\site-packages\textual\widget.py", line 2900, in scroll_end
    _lazily_scroll_end()
  File "C:\Users\Professional\AppData\Local\Programs\Python\Python312\Lib\site-packages\textual\widget.py", line 2883, in _lazily_scroll_end
    self._scroll_to(
  File "C:\Users\Professional\AppData\Local\Programs\Python\Python312\Lib\site-packages\textual\widget.py", line 2583, in _scroll_to
    animator = self.app.animator
               ^^^^^^^^
  File "C:\Users\Professional\AppData\Local\Programs\Python\Python312\Lib\site-packages\textual\message_pump.py", line 248, in app
    raise NoActiveAppError()
textual._context.NoActiveAppError

During handling of the above exception, another exception occurred:

Traceback (most recent call last):
  File "C:\Users\Professional\AppData\Local\Programs\Python\Python312\Lib\site-packages\textual\message_pump.py", line 241, in app
    return active_app.get()
           ^^^^^^^^^^^^^^^^
LookupError: <ContextVar name='active_app' at 0x000001F264E7E3E0>

During handling of the above exception, another exception occurred:

Traceback (most recent call last):
  File "d:\Develop\Python\trade_bot\11.9.1\main.py", line 172, in <module>
    asyncio.run(main())
  File "C:\Users\Professional\AppData\Local\Programs\Python\Python312\Lib\asyncio\runners.py", line 193, in run
    with Runner(debug=debug, loop_factory=loop_factory) as runner:
  File "C:\Users\Professional\AppData\Local\Programs\Python\Python312\Lib\asyncio\runners.py", line 62, in __exit__
    self.close()
  File "C:\Users\Professional\AppData\Local\Programs\Python\Python312\Lib\asyncio\runners.py", line 70, in close
    _cancel_all_tasks(loop)
  File "C:\Users\Professional\AppData\Local\Programs\Python\Python312\Lib\asyncio\runners.py", line 211, in _cancel_all_tasks
    loop.call_exception_handler({
  File "C:\Users\Professional\AppData\Local\Programs\Python\Python312\Lib\asyncio\base_events.py", line 1890, in call_exception_handler
    logger.error('Exception in default exception handler '
  File "C:\Users\Professional\AppData\Local\Programs\Python\Python312\Lib\logging\__init__.py", line 1568, in error
    self._log(ERROR, msg, args, **kwargs)
  File "C:\Users\Professional\AppData\Local\Programs\Python\Python312\Lib\logging\__init__.py", line 1684, in _log
    self.handle(record)
  File "C:\Users\Professional\AppData\Local\Programs\Python\Python312\Lib\logging\__init__.py", line 1700, in handle
    self.callHandlers(record)
  File "C:\Users\Professional\AppData\Local\Programs\Python\Python312\Lib\logging\__init__.py", line 1762, in callHandlers
    hdlr.handle(record)
  File "C:\Users\Professional\AppData\Local\Programs\Python\Python312\Lib\logging\__init__.py", line 1028, in handle
    self.emit(record)
  File "d:\Develop\Python\trade_bot\11.9.1\core\ui.py", line 32, in emit
    self.text_log.write(msg)
  File "C:\Users\Professional\AppData\Local\Programs\Python\Python312\Lib\site-packages\textual\widgets\_log.py", line 195, in write
    self.scroll_end(animate=False, immediate=True, x_axis=False)
  File "C:\Users\Professional\AppData\Local\Programs\Python\Python312\Lib\site-packages\textual\widget.py", line 2900, in scroll_end
    _lazily_scroll_end()
  File "C:\Users\Professional\AppData\Local\Programs\Python\Python312\Lib\site-packages\textual\widget.py", line 2883, in _lazily_scroll_end
    self._scroll_to(
  File "C:\Users\Professional\AppData\Local\Programs\Python\Python312\Lib\site-packages\textual\widget.py", line 2583, in _scroll_to
    animator = self.app.animator
               ^^^^^^^^
  File "C:\Users\Professional\AppData\Local\Programs\Python\Python312\Lib\site-packages\textual\message_pump.py", line 248, in app
    raise NoActiveAppError()
textual._context.NoActiveAppError
[07-08  23:39:30] ERROR bot [mode=LOOP] : Loop-level exception
Traceback (most recent call last):
  File "d:\Develop\Python\trade_bot\11.9.1\core\tpsl_monitor.py", line 163, in _loop
    lq, lp, sq, sp =  await self._get_state()
                     ^^^^^^^^^^^^^^^^^^^^^^^
  File "d:\Develop\Python\trade_bot\11.9.1\core\tpsl_monitor.py", line 257, in _get_state
    resp = await self.rest.request("GET", "/api/v5/account/positions",params={"instId": self.inst}        )
           ^^^^^^^^^^^^^^^^^^^^^^^^^^^^^^^^^^^^^^^^^^^^^^^^^^^^^^^^^^^^^^^^^^^^^^^^^^^^^^^^^^^^^^^^^^^^^^^^
  File "d:\Develop\Python\trade_bot\11.9.1\core\rest_client.py", line 206, in request
    async with self.session.request(
  File "C:\Users\Professional\AppData\Local\Programs\Python\Python312\Lib\site-packages\aiohttp\client.py", line 1360, in __aenter__
    self._resp: _RetType = await self._coro
                           ^^^^^^^^^^^^^^^^
  File "C:\Users\Professional\AppData\Local\Programs\Python\Python312\Lib\site-packages\aiohttp\client.py", line 493, in _request
    raise RuntimeError("Session is closed")
RuntimeError: Session is closed

During handling of the above exception, another exception occurred:

Traceback (most recent call last):
  File "C:\Users\Professional\AppData\Local\Programs\Python\Python312\Lib\site-packages\textual\message_pump.py", line 241, in app
    return active_app.get()
           ^^^^^^^^^^^^^^^^
LookupError: <ContextVar name='active_app' at 0x000001A14EF8E480>

During handling of the above exception, another exception occurred:

Traceback (most recent call last):
  File "d:\Develop\Python\trade_bot\11.9.1\core\tpsl_monitor.py", line 245, in _loop
    logger.warning("⚠️ TPSL loop terminated: HTTP session closed")
  File "C:\Users\Professional\AppData\Local\Programs\Python\Python312\Lib\logging\__init__.py", line 1551, in warning
    self._log(WARNING, msg, args, **kwargs)
  File "C:\Users\Professional\AppData\Local\Programs\Python\Python312\Lib\logging\__init__.py", line 1684, in _log
    self.handle(record)
  File "C:\Users\Professional\AppData\Local\Programs\Python\Python312\Lib\logging\__init__.py", line 1700, in handle
    self.callHandlers(record)
  File "C:\Users\Professional\AppData\Local\Programs\Python\Python312\Lib\logging\__init__.py", line 1762, in callHandlers
    hdlr.handle(record)
  File "C:\Users\Professional\AppData\Local\Programs\Python\Python312\Lib\logging\__init__.py", line 1028, in handle
    self.emit(record)
  File "d:\Develop\Python\trade_bot\11.9.1\core\ui.py", line 32, in emit
    self.status = TaskStatus()
    ^^^^^^^^^^^^^^^^^^^^^^^^
  File "C:\Users\Professional\AppData\Local\Programs\Python\Python312\Lib\site-packages\textual\widgets\_log.py", line 195, in write
    self.scroll_end(animate=False, immediate=True, x_axis=False)
  File "C:\Users\Professional\AppData\Local\Programs\Python\Python312\Lib\site-packages\textual\widget.py", line 2900, in scroll_end
    _lazily_scroll_end()
  File "C:\Users\Professional\AppData\Local\Programs\Python\Python312\Lib\site-packages\textual\widget.py", line 2883, in _lazily_scroll_end
    self._scroll_to(
  File "C:\Users\Professional\AppData\Local\Programs\Python\Python312\Lib\site-packages\textual\widget.py", line 2583, in _scroll_to
    animator = self.app.animator
               ^^^^^^^^
  File "C:\Users\Professional\AppData\Local\Programs\Python\Python312\Lib\site-packages\textual\message_pump.py", line 248, in app
    raise NoActiveAppError()
textual._context.NoActiveAppError
[07-08  23:39:30] ERROR bot [mode=MAIN] : 💥 Fatal error: 
Traceback (most recent call last):
  File "C:\Users\Professional\AppData\Local\Programs\Python\Python312\Lib\site-packages\textual\message_pump.py", line 241, in app
    return active_app.get()
           ^^^^^^^^^^^^^^^^
LookupError: <ContextVar name='active_app' at 0x000001A14EF8E480>

During handling of the above exception, another exception occurred:

Traceback (most recent call last):
  File "C:\Users\Professional\AppData\Local\Programs\Python\Python312\Lib\asyncio\base_events.py", line 1871, in call_exception_handler
    ctx.run(self._exception_handler, self, context)
  File "d:\Develop\Python\trade_bot\11.9.1\core\orchestrator.py", line 281, in _handle_loop_exception
    logger.error("Loop-level exception",
  File "C:\Users\Professional\AppData\Local\Programs\Python\Python312\Lib\logging\__init__.py", line 1568, in error
    self._log(ERROR, msg, args, **kwargs)
  File "C:\Users\Professional\AppData\Local\Programs\Python\Python312\Lib\logging\__init__.py", line 1684, in _log
    self.handle(record)
  File "C:\Users\Professional\AppData\Local\Programs\Python\Python312\Lib\logging\__init__.py", line 1700, in handle
    self.callHandlers(record)
  File "C:\Users\Professional\AppData\Local\Programs\Python\Python312\Lib\logging\__init__.py", line 1762, in callHandlers
    hdlr.handle(record)
  File "C:\Users\Professional\AppData\Local\Programs\Python\Python312\Lib\logging\__init__.py", line 1028, in handle
    self.emit(record)
  File "d:\Develop\Python\trade_bot\11.9.1\core\ui.py", line 32, in emit
    self.status = TaskStatus()
    ^^^^^^^^^^^^^^^^^^^^^^^^
  File "C:\Users\Professional\AppData\Local\Programs\Python\Python312\Lib\site-packages\textual\widgets\_log.py", line 195, in write
    self.scroll_end(animate=False, immediate=True, x_axis=False)
  File "C:\Users\Professional\AppData\Local\Programs\Python\Python312\Lib\site-packages\textual\widget.py", line 2900, in scroll_end
    _lazily_scroll_end()
  File "C:\Users\Professional\AppData\Local\Programs\Python\Python312\Lib\site-packages\textual\widget.py", line 2883, in _lazily_scroll_end
    self._scroll_to(
  File "C:\Users\Professional\AppData\Local\Programs\Python\Python312\Lib\site-packages\textual\widget.py", line 2583, in _scroll_to
    animator = self.app.animator
               ^^^^^^^^
  File "C:\Users\Professional\AppData\Local\Programs\Python\Python312\Lib\site-packages\textual\message_pump.py", line 248, in app
    raise NoActiveAppError()
textual._context.NoActiveAppError

During handling of the above exception, another exception occurred:

Traceback (most recent call last):
  File "C:\Users\Professional\AppData\Local\Programs\Python\Python312\Lib\site-packages\textual\message_pump.py", line 241, in app
    return active_app.get()
           ^^^^^^^^^^^^^^^^
LookupError: <ContextVar name='active_app' at 0x000001A14EF8E480>

During handling of the above exception, another exception occurred:

Traceback (most recent call last):
  File "C:\Users\Professional\AppData\Local\Programs\Python\Python312\Lib\asyncio\base_events.py", line 1880, in call_exception_handler
    self.default_exception_handler({
  File "C:\Users\Professional\AppData\Local\Programs\Python\Python312\Lib\asyncio\base_events.py", line 1821, in default_exception_handler
    logger.error('\n'.join(log_lines), exc_info=exc_info)
  File "C:\Users\Professional\AppData\Local\Programs\Python\Python312\Lib\logging\__init__.py", line 1568, in error
    self._log(ERROR, msg, args, **kwargs)
  File "C:\Users\Professional\AppData\Local\Programs\Python\Python312\Lib\logging\__init__.py", line 1684, in _log
    self.handle(record)
  File "C:\Users\Professional\AppData\Local\Programs\Python\Python312\Lib\logging\__init__.py", line 1700, in handle
    self.callHandlers(record)
  File "C:\Users\Professional\AppData\Local\Programs\Python\Python312\Lib\logging\__init__.py", line 1762, in callHandlers
    hdlr.handle(record)
  File "C:\Users\Professional\AppData\Local\Programs\Python\Python312\Lib\logging\__init__.py", line 1028, in handle
    self.emit(record)
  File "d:\Develop\Python\trade_bot\11.9.1\core\ui.py", line 32, in emit
    self.status = TaskStatus()
    ^^^^^^^^^^^^^^^^^^^^^^^^
  File "C:\Users\Professional\AppData\Local\Programs\Python\Python312\Lib\site-packages\textual\widgets\_log.py", line 195, in write
    self.scroll_end(animate=False, immediate=True, x_axis=False)
  File "C:\Users\Professional\AppData\Local\Programs\Python\Python312\Lib\site-packages\textual\widget.py", line 2900, in scroll_end
    _lazily_scroll_end()
  File "C:\Users\Professional\AppData\Local\Programs\Python\Python312\Lib\site-packages\textual\widget.py", line 2883, in _lazily_scroll_end
    self._scroll_to(
  File "C:\Users\Professional\AppData\Local\Programs\Python\Python312\Lib\site-packages\textual\widget.py", line 2583, in _scroll_to
    animator = self.app.animator
               ^^^^^^^^
  File "C:\Users\Professional\AppData\Local\Programs\Python\Python312\Lib\site-packages\textual\message_pump.py", line 248, in app
    raise NoActiveAppError()
textual._context.NoActiveAppError

During handling of the above exception, another exception occurred:

Traceback (most recent call last):
  File "C:\Users\Professional\AppData\Local\Programs\Python\Python312\Lib\site-packages\textual\message_pump.py", line 241, in app
    return active_app.get()
           ^^^^^^^^^^^^^^^^
LookupError: <ContextVar name='active_app' at 0x000001A14EF8E480>

During handling of the above exception, another exception occurred:

Traceback (most recent call last):
  File "d:\Develop\Python\trade_bot\11.9.1\main.py", line 172, in <module>
    asyncio.run(main())
  File "C:\Users\Professional\AppData\Local\Programs\Python\Python312\Lib\asyncio\runners.py", line 193, in run
    with Runner(debug=debug, loop_factory=loop_factory) as runner:
  File "C:\Users\Professional\AppData\Local\Programs\Python\Python312\Lib\asyncio\runners.py", line 62, in __exit__
    self.close()
  File "C:\Users\Professional\AppData\Local\Programs\Python\Python312\Lib\asyncio\runners.py", line 70, in close
    _cancel_all_tasks(loop)
  File "C:\Users\Professional\AppData\Local\Programs\Python\Python312\Lib\asyncio\runners.py", line 211, in _cancel_all_tasks
    loop.call_exception_handler({
  File "C:\Users\Professional\AppData\Local\Programs\Python\Python312\Lib\asyncio\base_events.py", line 1890, in call_exception_handler
    logger.error('Exception in default exception handler '
  File "C:\Users\Professional\AppData\Local\Programs\Python\Python312\Lib\logging\__init__.py", line 1568, in error
    self._log(ERROR, msg, args, **kwargs)
  File "C:\Users\Professional\AppData\Local\Programs\Python\Python312\Lib\logging\__init__.py", line 1684, in _log
    self.handle(record)
  File "C:\Users\Professional\AppData\Local\Programs\Python\Python312\Lib\logging\__init__.py", line 1700, in handle
    self.callHandlers(record)
  File "C:\Users\Professional\AppData\Local\Programs\Python\Python312\Lib\logging\__init__.py", line 1762, in callHandlers
    hdlr.handle(record)
  File "C:\Users\Professional\AppData\Local\Programs\Python\Python312\Lib\logging\__init__.py", line 1028, in handle
    self.emit(record)
  File "d:\Develop\Python\trade_bot\11.9.1\core\ui.py", line 32, in emit
    self.status = TaskStatus()
    ^^^^^^^^^^^^^^^^^^^^^^^^
  File "C:\Users\Professional\AppData\Local\Programs\Python\Python312\Lib\site-packages\textual\widgets\_log.py", line 195, in write
    self.scroll_end(animate=False, immediate=True, x_axis=False)
  File "C:\Users\Professional\AppData\Local\Programs\Python\Python312\Lib\site-packages\textual\widget.py", line 2900, in scroll_end
    _lazily_scroll_end()
  File "C:\Users\Professional\AppData\Local\Programs\Python\Python312\Lib\site-packages\textual\widget.py", line 2883, in _lazily_scroll_end
    self._scroll_to(
  File "C:\Users\Professional\AppData\Local\Programs\Python\Python312\Lib\site-packages\textual\widget.py", line 2583, in _scroll_to
    animator = self.app.animator
               ^^^^^^^^
  File "C:\Users\Professional\AppData\Local\Programs\Python\Python312\Lib\site-packages\textual\message_pump.py", line 248, in app
    raise NoActiveAppError()
textual._context.NoActiveAppError
