[20-08  02:11:25] ERROR bot [mode=MAIN] : 💥 Fatal error: maximum recursion depth exceeded
Traceback (most recent call last):
  File "C:\Users\Professional\AppData\Local\Programs\Python\Python312\Lib\asyncio\runners.py", line 194, in run
    return runner.run(main)
           ^^^^^^^^^^^^^^^^
  File "C:\Users\Professional\AppData\Local\Programs\Python\Python312\Lib\asyncio\runners.py", line 118, in run
    return self._loop.run_until_complete(task)
           ^^^^^^^^^^^^^^^^^^^^^^^^^^^^^^^^^^^
  File "C:\Users\Professional\AppData\Local\Programs\Python\Python312\Lib\asyncio\base_events.py", line 687, in run_until_complete
    return future.result()
           ^^^^^^^^^^^^^^^
  File "d:\Develop\Python\trade_bot\11.9.1\main.py", line 122, in main
    await task_manager.wait("orchestrator")
  File "d:\Develop\Python\trade_bot\11.9.1\core\task_manager.py", line 114, in wait
    await task
  File "d:\Develop\Python\trade_bot\11.9.1\core\orchestrator.py", line 174, in run
    await asyncio.sleep(self.poll_interval)
  File "C:\Users\Professional\AppData\Local\Programs\Python\Python312\Lib\asyncio\tasks.py", line 665, in sleep
    return await future
           ^^^^^^^^^^^^
asyncio.exceptions.CancelledError

During handling of the above exception, another exception occurred:

Traceback (most recent call last):
  File "d:\Develop\Python\trade_bot\11.9.1\main.py", line 180, in <module>
    asyncio.run(main())
  File "C:\Users\Professional\AppData\Local\Programs\Python\Python312\Lib\asyncio\runners.py", line 193, in run
    with Runner(debug=debug, loop_factory=loop_factory) as runner:
  File "C:\Users\Professional\AppData\Local\Programs\Python\Python312\Lib\asyncio\runners.py", line 62, in __exit__
    self.close()
  File "C:\Users\Professional\AppData\Local\Programs\Python\Python312\Lib\asyncio\runners.py", line 70, in close
    _cancel_all_tasks(loop)
  File "C:\Users\Professional\AppData\Local\Programs\Python\Python312\Lib\asyncio\runners.py", line 203, in _cancel_all_tasks
    task.cancel()
  File "C:\Users\Professional\AppData\Local\Programs\Python\Python312\Lib\asyncio\tasks.py", line 721, in cancel
    if child.cancel(msg=msg):
       ^^^^^^^^^^^^^^^^^^^^^
  File "C:\Users\Professional\AppData\Local\Programs\Python\Python312\Lib\asyncio\tasks.py", line 721, in cancel
    if child.cancel(msg=msg):
       ^^^^^^^^^^^^^^^^^^^^^
  File "C:\Users\Professional\AppData\Local\Programs\Python\Python312\Lib\asyncio\tasks.py", line 721, in cancel
    if child.cancel(msg=msg):
       ^^^^^^^^^^^^^^^^^^^^^
  [Previous line repeated 992 more times]
RecursionError: maximum recursion depth exceeded
[20-08  02:17:08] ERROR bot [mode=MAIN] : 💥 Fatal error: maximum recursion depth exceeded
Traceback (most recent call last):
  File "C:\Users\Professional\AppData\Local\Programs\Python\Python312\Lib\asyncio\runners.py", line 194, in run
    return runner.run(main)
           ^^^^^^^^^^^^^^^^
  File "C:\Users\Professional\AppData\Local\Programs\Python\Python312\Lib\asyncio\runners.py", line 118, in run
    return self._loop.run_until_complete(task)
           ^^^^^^^^^^^^^^^^^^^^^^^^^^^^^^^^^^^
  File "C:\Users\Professional\AppData\Local\Programs\Python\Python312\Lib\asyncio\base_events.py", line 687, in run_until_complete
    return future.result()
           ^^^^^^^^^^^^^^^
  File "d:\Develop\Python\trade_bot\11.9.1\main.py", line 122, in main
    await task_manager.wait("orchestrator")
  File "d:\Develop\Python\trade_bot\11.9.1\core\task_manager.py", line 114, in wait
    await task
  File "d:\Develop\Python\trade_bot\11.9.1\core\orchestrator.py", line 174, in run
    await asyncio.sleep(self.poll_interval)
  File "C:\Users\Professional\AppData\Local\Programs\Python\Python312\Lib\asyncio\tasks.py", line 665, in sleep
    return await future
           ^^^^^^^^^^^^
asyncio.exceptions.CancelledError

During handling of the above exception, another exception occurred:

Traceback (most recent call last):
  File "d:\Develop\Python\trade_bot\11.9.1\main.py", line 180, in <module>
    asyncio.run(main())
  File "C:\Users\Professional\AppData\Local\Programs\Python\Python312\Lib\asyncio\runners.py", line 193, in run
    with Runner(debug=debug, loop_factory=loop_factory) as runner:
  File "C:\Users\Professional\AppData\Local\Programs\Python\Python312\Lib\asyncio\runners.py", line 62, in __exit__
    self.close()
  File "C:\Users\Professional\AppData\Local\Programs\Python\Python312\Lib\asyncio\runners.py", line 70, in close
    _cancel_all_tasks(loop)
  File "C:\Users\Professional\AppData\Local\Programs\Python\Python312\Lib\asyncio\runners.py", line 203, in _cancel_all_tasks
    task.cancel()
  File "C:\Users\Professional\AppData\Local\Programs\Python\Python312\Lib\asyncio\tasks.py", line 721, in cancel
    if child.cancel(msg=msg):
       ^^^^^^^^^^^^^^^^^^^^^
  File "C:\Users\Professional\AppData\Local\Programs\Python\Python312\Lib\asyncio\tasks.py", line 721, in cancel
    if child.cancel(msg=msg):
       ^^^^^^^^^^^^^^^^^^^^^
  File "C:\Users\Professional\AppData\Local\Programs\Python\Python312\Lib\asyncio\tasks.py", line 721, in cancel
    if child.cancel(msg=msg):
       ^^^^^^^^^^^^^^^^^^^^^
  [Previous line repeated 992 more times]
RecursionError: maximum recursion depth exceeded
[20-08  02:19:19] ERROR bot [mode=MAIN] : 💥 Fatal error: maximum recursion depth exceeded
Traceback (most recent call last):
  File "C:\Users\Professional\AppData\Local\Programs\Python\Python312\Lib\asyncio\runners.py", line 194, in run
    return runner.run(main)
           ^^^^^^^^^^^^^^^^
  File "C:\Users\Professional\AppData\Local\Programs\Python\Python312\Lib\asyncio\runners.py", line 118, in run
    return self._loop.run_until_complete(task)
           ^^^^^^^^^^^^^^^^^^^^^^^^^^^^^^^^^^^
  File "C:\Users\Professional\AppData\Local\Programs\Python\Python312\Lib\asyncio\base_events.py", line 687, in run_until_complete
    return future.result()
           ^^^^^^^^^^^^^^^
  File "d:\Develop\Python\trade_bot\11.9.1\main.py", line 122, in main
    await task_manager.wait("orchestrator")
  File "d:\Develop\Python\trade_bot\11.9.1\core\task_manager.py", line 114, in wait
    await task
  File "d:\Develop\Python\trade_bot\11.9.1\core\orchestrator.py", line 174, in run
    await asyncio.sleep(self.poll_interval)
  File "C:\Users\Professional\AppData\Local\Programs\Python\Python312\Lib\asyncio\tasks.py", line 665, in sleep
    return await future
           ^^^^^^^^^^^^
asyncio.exceptions.CancelledError

During handling of the above exception, another exception occurred:

Traceback (most recent call last):
  File "d:\Develop\Python\trade_bot\11.9.1\main.py", line 180, in <module>
    asyncio.run(main())
  File "C:\Users\Professional\AppData\Local\Programs\Python\Python312\Lib\asyncio\runners.py", line 193, in run
    with Runner(debug=debug, loop_factory=loop_factory) as runner:
  File "C:\Users\Professional\AppData\Local\Programs\Python\Python312\Lib\asyncio\runners.py", line 62, in __exit__
    self.close()
  File "C:\Users\Professional\AppData\Local\Programs\Python\Python312\Lib\asyncio\runners.py", line 70, in close
    _cancel_all_tasks(loop)
  File "C:\Users\Professional\AppData\Local\Programs\Python\Python312\Lib\asyncio\runners.py", line 203, in _cancel_all_tasks
    task.cancel()
  File "C:\Users\Professional\AppData\Local\Programs\Python\Python312\Lib\asyncio\tasks.py", line 721, in cancel
    if child.cancel(msg=msg):
       ^^^^^^^^^^^^^^^^^^^^^
  File "C:\Users\Professional\AppData\Local\Programs\Python\Python312\Lib\asyncio\tasks.py", line 721, in cancel
    if child.cancel(msg=msg):
       ^^^^^^^^^^^^^^^^^^^^^
  File "C:\Users\Professional\AppData\Local\Programs\Python\Python312\Lib\asyncio\tasks.py", line 721, in cancel
    if child.cancel(msg=msg):
       ^^^^^^^^^^^^^^^^^^^^^
  [Previous line repeated 992 more times]
RecursionError: maximum recursion depth exceeded
[20-08  02:27:45] ERROR bot [mode=MAIN] : 💥 Fatal error: maximum recursion depth exceeded
Traceback (most recent call last):
  File "C:\Users\Professional\AppData\Local\Programs\Python\Python312\Lib\asyncio\runners.py", line 194, in run
    return runner.run(main)
           ^^^^^^^^^^^^^^^^
  File "C:\Users\Professional\AppData\Local\Programs\Python\Python312\Lib\asyncio\runners.py", line 118, in run
    return self._loop.run_until_complete(task)
           ^^^^^^^^^^^^^^^^^^^^^^^^^^^^^^^^^^^
  File "C:\Users\Professional\AppData\Local\Programs\Python\Python312\Lib\asyncio\base_events.py", line 687, in run_until_complete
    return future.result()
           ^^^^^^^^^^^^^^^
  File "d:\Develop\Python\trade_bot\11.9.1\main.py", line 122, in main
    await task_manager.wait("orchestrator")
  File "d:\Develop\Python\trade_bot\11.9.1\core\task_manager.py", line 114, in wait
    await task
  File "d:\Develop\Python\trade_bot\11.9.1\core\orchestrator.py", line 174, in run
    await asyncio.sleep(self.poll_interval)
  File "C:\Users\Professional\AppData\Local\Programs\Python\Python312\Lib\asyncio\tasks.py", line 665, in sleep
    return await future
           ^^^^^^^^^^^^
asyncio.exceptions.CancelledError

During handling of the above exception, another exception occurred:

Traceback (most recent call last):
  File "d:\Develop\Python\trade_bot\11.9.1\main.py", line 180, in <module>
    asyncio.run(main())
  File "C:\Users\Professional\AppData\Local\Programs\Python\Python312\Lib\asyncio\runners.py", line 193, in run
    with Runner(debug=debug, loop_factory=loop_factory) as runner:
  File "C:\Users\Professional\AppData\Local\Programs\Python\Python312\Lib\asyncio\runners.py", line 62, in __exit__
    self.close()
  File "C:\Users\Professional\AppData\Local\Programs\Python\Python312\Lib\asyncio\runners.py", line 70, in close
    _cancel_all_tasks(loop)
  File "C:\Users\Professional\AppData\Local\Programs\Python\Python312\Lib\asyncio\runners.py", line 203, in _cancel_all_tasks
    task.cancel()
  File "C:\Users\Professional\AppData\Local\Programs\Python\Python312\Lib\asyncio\tasks.py", line 721, in cancel
    if child.cancel(msg=msg):
       ^^^^^^^^^^^^^^^^^^^^^
  File "C:\Users\Professional\AppData\Local\Programs\Python\Python312\Lib\asyncio\tasks.py", line 721, in cancel
    if child.cancel(msg=msg):
       ^^^^^^^^^^^^^^^^^^^^^
  File "C:\Users\Professional\AppData\Local\Programs\Python\Python312\Lib\asyncio\tasks.py", line 721, in cancel
    if child.cancel(msg=msg):
       ^^^^^^^^^^^^^^^^^^^^^
  [Previous line repeated 992 more times]
RecursionError: maximum recursion depth exceeded
[20-08  02:29:12] ERROR bot [mode=REST] : [TimeoutError] POST https://www.okx.com/api/v5/trade/order, attempt 1/4, sleeping 1.1s before retry
Traceback (most recent call last):
  File "C:\Users\Professional\AppData\Local\Programs\Python\Python312\Lib\site-packages\aiohttp\client.py", line 663, in _request
    conn = await self._connector.connect(
           ^^^^^^^^^^^^^^^^^^^^^^^^^^^^^^
  File "C:\Users\Professional\AppData\Local\Programs\Python\Python312\Lib\site-packages\aiohttp\connector.py", line 538, in connect
    proto = await self._create_connection(req, traces, timeout)
            ^^^^^^^^^^^^^^^^^^^^^^^^^^^^^^^^^^^^^^^^^^^^^^^^^^^
  File "C:\Users\Professional\AppData\Local\Programs\Python\Python312\Lib\site-packages\aiohttp\connector.py", line 1050, in _create_connection
    _, proto = await self._create_direct_connection(req, traces, timeout)
               ^^^^^^^^^^^^^^^^^^^^^^^^^^^^^^^^^^^^^^^^^^^^^^^^^^^^^^^^^^
  File "C:\Users\Professional\AppData\Local\Programs\Python\Python312\Lib\site-packages\aiohttp\connector.py", line 1335, in _create_direct_connection
    hosts = await self._resolve_host(host, port, traces=traces)
            ^^^^^^^^^^^^^^^^^^^^^^^^^^^^^^^^^^^^^^^^^^^^^^^^^^^
  File "C:\Users\Professional\AppData\Local\Programs\Python\Python312\Lib\site-packages\aiohttp\connector.py", line 989, in _resolve_host
    return await asyncio.shield(resolved_host_task)
           ^^^^^^^^^^^^^^^^^^^^^^^^^^^^^^^^^^^^^^^^
asyncio.exceptions.CancelledError

The above exception was the direct cause of the following exception:

Traceback (most recent call last):
  File "d:\Develop\Python\trade_bot\11.9.1\core\rest_client.py", line 206, in request
    async with self.session.request(
  File "C:\Users\Professional\AppData\Local\Programs\Python\Python312\Lib\site-packages\aiohttp\client.py", line 1360, in __aenter__
    self._resp: _RetType = await self._coro
                           ^^^^^^^^^^^^^^^^
  File "C:\Users\Professional\AppData\Local\Programs\Python\Python312\Lib\site-packages\aiohttp\client.py", line 578, in _request
    with timer:
  File "C:\Users\Professional\AppData\Local\Programs\Python\Python312\Lib\site-packages\aiohttp\helpers.py", line 749, in __exit__
    raise asyncio.TimeoutError from exc_val
TimeoutError
[20-08  02:30:02] ERROR bot [mode=REST] : [TimeoutError] GET https://www.okx.com/api/v5/trade/orders-algo-pending, attempt 1/4, sleeping 1.0s before retry
Traceback (most recent call last):
  File "C:\Users\Professional\AppData\Local\Programs\Python\Python312\Lib\site-packages\aiohttp\client.py", line 663, in _request
    conn = await self._connector.connect(
           ^^^^^^^^^^^^^^^^^^^^^^^^^^^^^^
  File "C:\Users\Professional\AppData\Local\Programs\Python\Python312\Lib\site-packages\aiohttp\connector.py", line 538, in connect
    proto = await self._create_connection(req, traces, timeout)
            ^^^^^^^^^^^^^^^^^^^^^^^^^^^^^^^^^^^^^^^^^^^^^^^^^^^
  File "C:\Users\Professional\AppData\Local\Programs\Python\Python312\Lib\site-packages\aiohttp\connector.py", line 1050, in _create_connection
    _, proto = await self._create_direct_connection(req, traces, timeout)
               ^^^^^^^^^^^^^^^^^^^^^^^^^^^^^^^^^^^^^^^^^^^^^^^^^^^^^^^^^^
  File "C:\Users\Professional\AppData\Local\Programs\Python\Python312\Lib\site-packages\aiohttp\connector.py", line 1335, in _create_direct_connection
    hosts = await self._resolve_host(host, port, traces=traces)
            ^^^^^^^^^^^^^^^^^^^^^^^^^^^^^^^^^^^^^^^^^^^^^^^^^^^
  File "C:\Users\Professional\AppData\Local\Programs\Python\Python312\Lib\site-packages\aiohttp\connector.py", line 964, in _resolve_host
    await future
asyncio.exceptions.CancelledError

The above exception was the direct cause of the following exception:

Traceback (most recent call last):
  File "d:\Develop\Python\trade_bot\11.9.1\core\rest_client.py", line 206, in request
    async with self.session.request(
  File "C:\Users\Professional\AppData\Local\Programs\Python\Python312\Lib\site-packages\aiohttp\client.py", line 1360, in __aenter__
    self._resp: _RetType = await self._coro
                           ^^^^^^^^^^^^^^^^
  File "C:\Users\Professional\AppData\Local\Programs\Python\Python312\Lib\site-packages\aiohttp\client.py", line 578, in _request
    with timer:
  File "C:\Users\Professional\AppData\Local\Programs\Python\Python312\Lib\site-packages\aiohttp\helpers.py", line 749, in __exit__
    raise asyncio.TimeoutError from exc_val
TimeoutError
[20-08  02:52:15] ERROR bot [mode=MAIN] : 💥 Fatal error: maximum recursion depth exceeded
Traceback (most recent call last):
  File "C:\Users\Professional\AppData\Local\Programs\Python\Python312\Lib\asyncio\runners.py", line 194, in run
    return runner.run(main)
           ^^^^^^^^^^^^^^^^
  File "C:\Users\Professional\AppData\Local\Programs\Python\Python312\Lib\asyncio\runners.py", line 118, in run
    return self._loop.run_until_complete(task)
           ^^^^^^^^^^^^^^^^^^^^^^^^^^^^^^^^^^^
  File "C:\Users\Professional\AppData\Local\Programs\Python\Python312\Lib\asyncio\base_events.py", line 687, in run_until_complete
    return future.result()
           ^^^^^^^^^^^^^^^
  File "d:\Develop\Python\trade_bot\11.9.1\main.py", line 122, in main
    await task_manager.wait("orchestrator")
  File "d:\Develop\Python\trade_bot\11.9.1\core\task_manager.py", line 114, in wait
    await task
  File "d:\Develop\Python\trade_bot\11.9.1\core\orchestrator.py", line 174, in run
    await asyncio.sleep(self.poll_interval)
  File "C:\Users\Professional\AppData\Local\Programs\Python\Python312\Lib\asyncio\tasks.py", line 665, in sleep
    return await future
           ^^^^^^^^^^^^
asyncio.exceptions.CancelledError

During handling of the above exception, another exception occurred:

Traceback (most recent call last):
  File "d:\Develop\Python\trade_bot\11.9.1\main.py", line 180, in <module>
    asyncio.run(main())
  File "C:\Users\Professional\AppData\Local\Programs\Python\Python312\Lib\asyncio\runners.py", line 193, in run
    with Runner(debug=debug, loop_factory=loop_factory) as runner:
  File "C:\Users\Professional\AppData\Local\Programs\Python\Python312\Lib\asyncio\runners.py", line 62, in __exit__
    self.close()
  File "C:\Users\Professional\AppData\Local\Programs\Python\Python312\Lib\asyncio\runners.py", line 70, in close
    _cancel_all_tasks(loop)
  File "C:\Users\Professional\AppData\Local\Programs\Python\Python312\Lib\asyncio\runners.py", line 203, in _cancel_all_tasks
    task.cancel()
  File "C:\Users\Professional\AppData\Local\Programs\Python\Python312\Lib\asyncio\tasks.py", line 721, in cancel
    if child.cancel(msg=msg):
       ^^^^^^^^^^^^^^^^^^^^^
  File "C:\Users\Professional\AppData\Local\Programs\Python\Python312\Lib\asyncio\tasks.py", line 721, in cancel
    if child.cancel(msg=msg):
       ^^^^^^^^^^^^^^^^^^^^^
  File "C:\Users\Professional\AppData\Local\Programs\Python\Python312\Lib\asyncio\tasks.py", line 721, in cancel
    if child.cancel(msg=msg):
       ^^^^^^^^^^^^^^^^^^^^^
  [Previous line repeated 992 more times]
RecursionError: maximum recursion depth exceeded
[20-08  02:59:16] ERROR bot [mode=MAIN] : 💥 Fatal error: maximum recursion depth exceeded
Traceback (most recent call last):
  File "C:\Users\Professional\AppData\Local\Programs\Python\Python312\Lib\asyncio\runners.py", line 194, in run
    return runner.run(main)
           ^^^^^^^^^^^^^^^^
  File "C:\Users\Professional\AppData\Local\Programs\Python\Python312\Lib\asyncio\runners.py", line 118, in run
    return self._loop.run_until_complete(task)
           ^^^^^^^^^^^^^^^^^^^^^^^^^^^^^^^^^^^
  File "C:\Users\Professional\AppData\Local\Programs\Python\Python312\Lib\asyncio\base_events.py", line 687, in run_until_complete
    return future.result()
           ^^^^^^^^^^^^^^^
  File "d:\Develop\Python\trade_bot\11.9.1\main.py", line 122, in main
    await task_manager.wait("orchestrator")
  File "d:\Develop\Python\trade_bot\11.9.1\core\task_manager.py", line 114, in wait
    await task
  File "d:\Develop\Python\trade_bot\11.9.1\core\orchestrator.py", line 174, in run
    await asyncio.sleep(self.poll_interval)
  File "C:\Users\Professional\AppData\Local\Programs\Python\Python312\Lib\asyncio\tasks.py", line 665, in sleep
    return await future
           ^^^^^^^^^^^^
asyncio.exceptions.CancelledError

During handling of the above exception, another exception occurred:

Traceback (most recent call last):
  File "d:\Develop\Python\trade_bot\11.9.1\main.py", line 180, in <module>
    asyncio.run(main())
  File "C:\Users\Professional\AppData\Local\Programs\Python\Python312\Lib\asyncio\runners.py", line 193, in run
    with Runner(debug=debug, loop_factory=loop_factory) as runner:
  File "C:\Users\Professional\AppData\Local\Programs\Python\Python312\Lib\asyncio\runners.py", line 62, in __exit__
    self.close()
  File "C:\Users\Professional\AppData\Local\Programs\Python\Python312\Lib\asyncio\runners.py", line 70, in close
    _cancel_all_tasks(loop)
  File "C:\Users\Professional\AppData\Local\Programs\Python\Python312\Lib\asyncio\runners.py", line 203, in _cancel_all_tasks
    task.cancel()
  File "C:\Users\Professional\AppData\Local\Programs\Python\Python312\Lib\asyncio\tasks.py", line 721, in cancel
    if child.cancel(msg=msg):
       ^^^^^^^^^^^^^^^^^^^^^
  File "C:\Users\Professional\AppData\Local\Programs\Python\Python312\Lib\asyncio\tasks.py", line 721, in cancel
    if child.cancel(msg=msg):
       ^^^^^^^^^^^^^^^^^^^^^
  File "C:\Users\Professional\AppData\Local\Programs\Python\Python312\Lib\asyncio\tasks.py", line 721, in cancel
    if child.cancel(msg=msg):
       ^^^^^^^^^^^^^^^^^^^^^
  [Previous line repeated 992 more times]
RecursionError: maximum recursion depth exceeded
[20-08  03:16:16] ERROR bot [mode=-] : 💥 Fatal error: 
[20-08  09:18:58] ERROR bot [mode=REST] : [TimeoutError] GET https://www.okx.com/api/v5/account/positions, attempt 1/4, sleeping 1.0s before retry
[20-08  09:18:59] ERROR bot [mode=-] : ❌ [TPSL] loop error: Timeout on GET https://www.okx.com/api/v5/account/positions
Traceback (most recent call last):
  File "d:\Develop\Python\trade_bot\11.9.1\core\tpsl_monitor.py", line 161, in _loop
    lq, lp, sq, sp = await self._get_state()
                     ^^^^^^^^^^^^^^^^^^^^^^^
  File "d:\Develop\Python\trade_bot\11.9.1\core\tpsl_monitor.py", line 224, in _get_state
    resp = await self.rest.request(
           ^^^^^^^^^^^^^^^^^^^^^^^^
  File "d:\Develop\Python\trade_bot\11.9.1\core\rest_client.py", line 246, in request
    raise Exception(f"Timeout on {method} {url}") from None
Exception: Timeout on GET https://www.okx.com/api/v5/account/positions
[20-08  11:24:10] ERROR bot [mode=REST] : [TimeoutError] GET https://www.okx.com/api/v5/account/positions, attempt 1/4, sleeping 1.1s before retry
[20-08  11:24:11] ERROR bot [mode=-] : ❌ [TPSL] loop error: Timeout on GET https://www.okx.com/api/v5/account/positions
Traceback (most recent call last):
  File "d:\Develop\Python\trade_bot\11.9.1\core\tpsl_monitor.py", line 161, in _loop
    lq, lp, sq, sp = await self._get_state()
                     ^^^^^^^^^^^^^^^^^^^^^^^
  File "d:\Develop\Python\trade_bot\11.9.1\core\tpsl_monitor.py", line 224, in _get_state
    resp = await self.rest.request(
           ^^^^^^^^^^^^^^^^^^^^^^^^
  File "d:\Develop\Python\trade_bot\11.9.1\core\rest_client.py", line 246, in request
    raise Exception(f"Timeout on {method} {url}") from None
Exception: Timeout on GET https://www.okx.com/api/v5/account/positions
[20-08  11:57:48] ERROR bot [mode=REST] : [TimeoutError] GET https://www.okx.com/api/v5/account/positions, attempt 1/4, sleeping 1.1s before retry
[20-08  11:57:49] ERROR bot [mode=-] : ❌ [TPSL] loop error: Timeout on GET https://www.okx.com/api/v5/account/positions
Traceback (most recent call last):
  File "d:\Develop\Python\trade_bot\11.9.1\core\tpsl_monitor.py", line 161, in _loop
    lq, lp, sq, sp = await self._get_state()
                     ^^^^^^^^^^^^^^^^^^^^^^^
  File "d:\Develop\Python\trade_bot\11.9.1\core\tpsl_monitor.py", line 224, in _get_state
    resp = await self.rest.request(
           ^^^^^^^^^^^^^^^^^^^^^^^^
  File "d:\Develop\Python\trade_bot\11.9.1\core\rest_client.py", line 246, in request
    raise Exception(f"Timeout on {method} {url}") from None
Exception: Timeout on GET https://www.okx.com/api/v5/account/positions
[20-08  13:55:18] ERROR bot [mode=REST] : [TimeoutError] GET https://www.okx.com/api/v5/account/positions, attempt 1/4, sleeping 1.1s before retry
[20-08  13:55:19] ERROR bot [mode=-] : ❌ [TPSL] loop error: Timeout on GET https://www.okx.com/api/v5/account/positions
Traceback (most recent call last):
  File "d:\Develop\Python\trade_bot\11.9.1\core\tpsl_monitor.py", line 161, in _loop
    lq, lp, sq, sp = await self._get_state()
                     ^^^^^^^^^^^^^^^^^^^^^^^
  File "d:\Develop\Python\trade_bot\11.9.1\core\tpsl_monitor.py", line 224, in _get_state
    resp = await self.rest.request(
           ^^^^^^^^^^^^^^^^^^^^^^^^
  File "d:\Develop\Python\trade_bot\11.9.1\core\rest_client.py", line 246, in request
    raise Exception(f"Timeout on {method} {url}") from None
Exception: Timeout on GET https://www.okx.com/api/v5/account/positions
[20-08  15:07:30] ERROR bot [mode=-] : 💥 Fatal error: 
