[17-08  00:04:18] ERROR bot [mode=MAIN] : 💥 Fatal error: maximum recursion depth exceeded
Traceback (most recent call last):
  File "C:\Users\Professional\AppData\Local\Programs\Python\Python312\Lib\asyncio\runners.py", line 194, in run
    return runner.run(main)
           ^^^^^^^^^^^^^^^^
  File "C:\Users\Professional\AppData\Local\Programs\Python\Python312\Lib\asyncio\runners.py", line 118, in run
    return self._loop.run_until_complete(task)
           ^^^^^^^^^^^^^^^^^^^^^^^^^^^^^^^^^^^
  File "C:\Users\Professional\AppData\Local\Programs\Python\Python312\Lib\asyncio\base_events.py", line 687, in run_until_complete
    return future.result()
           ^^^^^^^^^^^^^^^
  File "d:\Develop\Python\trade_bot\11.9.1\main.py", line 116, in main
    await task_manager.wait("orchestrator")
  File "d:\Develop\Python\trade_bot\11.9.1\core\task_manager.py", line 108, in wait
    await task
  File "d:\Develop\Python\trade_bot\11.9.1\core\orchestrator.py", line 154, in run
    await asyncio.sleep(self.poll_interval)
  File "C:\Users\Professional\AppData\Local\Programs\Python\Python312\Lib\asyncio\tasks.py", line 665, in sleep
    return await future
           ^^^^^^^^^^^^
asyncio.exceptions.CancelledError

During handling of the above exception, another exception occurred:

Traceback (most recent call last):
  File "d:\Develop\Python\trade_bot\11.9.1\main.py", line 173, in <module>
    asyncio.run(main())
  File "C:\Users\Professional\AppData\Local\Programs\Python\Python312\Lib\asyncio\runners.py", line 193, in run
    with Runner(debug=debug, loop_factory=loop_factory) as runner:
  File "C:\Users\Professional\AppData\Local\Programs\Python\Python312\Lib\asyncio\runners.py", line 62, in __exit__
    self.close()
  File "C:\Users\Professional\AppData\Local\Programs\Python\Python312\Lib\asyncio\runners.py", line 70, in close
    _cancel_all_tasks(loop)
  File "C:\Users\Professional\AppData\Local\Programs\Python\Python312\Lib\asyncio\runners.py", line 203, in _cancel_all_tasks
    task.cancel()
  File "C:\Users\Professional\AppData\Local\Programs\Python\Python312\Lib\asyncio\tasks.py", line 721, in cancel
    if child.cancel(msg=msg):
       ^^^^^^^^^^^^^^^^^^^^^
  File "C:\Users\Professional\AppData\Local\Programs\Python\Python312\Lib\asyncio\tasks.py", line 721, in cancel
    if child.cancel(msg=msg):
       ^^^^^^^^^^^^^^^^^^^^^
  File "C:\Users\Professional\AppData\Local\Programs\Python\Python312\Lib\asyncio\tasks.py", line 721, in cancel
    if child.cancel(msg=msg):
       ^^^^^^^^^^^^^^^^^^^^^
  [Previous line repeated 992 more times]
RecursionError: maximum recursion depth exceeded
[17-08  00:04:18] ERROR bot [mode=LOOP] : Loop-level exception
[17-08  00:05:27] ERROR bot [mode=MAIN] : 💥 Fatal error: maximum recursion depth exceeded
Traceback (most recent call last):
  File "C:\Users\Professional\AppData\Local\Programs\Python\Python312\Lib\asyncio\runners.py", line 194, in run
    return runner.run(main)
           ^^^^^^^^^^^^^^^^
  File "C:\Users\Professional\AppData\Local\Programs\Python\Python312\Lib\asyncio\runners.py", line 118, in run
    return self._loop.run_until_complete(task)
           ^^^^^^^^^^^^^^^^^^^^^^^^^^^^^^^^^^^
  File "C:\Users\Professional\AppData\Local\Programs\Python\Python312\Lib\asyncio\base_events.py", line 687, in run_until_complete
    return future.result()
           ^^^^^^^^^^^^^^^
  File "d:\Develop\Python\trade_bot\11.9.1\main.py", line 116, in main
    await task_manager.wait("orchestrator")
  File "d:\Develop\Python\trade_bot\11.9.1\core\task_manager.py", line 108, in wait
    await task
  File "d:\Develop\Python\trade_bot\11.9.1\core\orchestrator.py", line 154, in run
    await asyncio.sleep(self.poll_interval)
  File "C:\Users\Professional\AppData\Local\Programs\Python\Python312\Lib\asyncio\tasks.py", line 665, in sleep
    return await future
           ^^^^^^^^^^^^
asyncio.exceptions.CancelledError

During handling of the above exception, another exception occurred:

Traceback (most recent call last):
  File "d:\Develop\Python\trade_bot\11.9.1\main.py", line 173, in <module>
    asyncio.run(main())
  File "C:\Users\Professional\AppData\Local\Programs\Python\Python312\Lib\asyncio\runners.py", line 193, in run
    with Runner(debug=debug, loop_factory=loop_factory) as runner:
  File "C:\Users\Professional\AppData\Local\Programs\Python\Python312\Lib\asyncio\runners.py", line 62, in __exit__
    self.close()
  File "C:\Users\Professional\AppData\Local\Programs\Python\Python312\Lib\asyncio\runners.py", line 70, in close
    _cancel_all_tasks(loop)
  File "C:\Users\Professional\AppData\Local\Programs\Python\Python312\Lib\asyncio\runners.py", line 203, in _cancel_all_tasks
    task.cancel()
  File "C:\Users\Professional\AppData\Local\Programs\Python\Python312\Lib\asyncio\tasks.py", line 721, in cancel
    if child.cancel(msg=msg):
       ^^^^^^^^^^^^^^^^^^^^^
  File "C:\Users\Professional\AppData\Local\Programs\Python\Python312\Lib\asyncio\tasks.py", line 721, in cancel
    if child.cancel(msg=msg):
       ^^^^^^^^^^^^^^^^^^^^^
  File "C:\Users\Professional\AppData\Local\Programs\Python\Python312\Lib\asyncio\tasks.py", line 721, in cancel
    if child.cancel(msg=msg):
       ^^^^^^^^^^^^^^^^^^^^^
  [Previous line repeated 992 more times]
RecursionError: maximum recursion depth exceeded
[17-08  00:05:27] ERROR bot [mode=LOOP] : Loop-level exception
[17-08  00:09:41] ERROR bot [mode=MAIN] : 💥 Fatal error: maximum recursion depth exceeded
Traceback (most recent call last):
  File "C:\Users\Professional\AppData\Local\Programs\Python\Python312\Lib\asyncio\runners.py", line 194, in run
    return runner.run(main)
           ^^^^^^^^^^^^^^^^
  File "C:\Users\Professional\AppData\Local\Programs\Python\Python312\Lib\asyncio\runners.py", line 118, in run
    return self._loop.run_until_complete(task)
           ^^^^^^^^^^^^^^^^^^^^^^^^^^^^^^^^^^^
  File "C:\Users\Professional\AppData\Local\Programs\Python\Python312\Lib\asyncio\base_events.py", line 687, in run_until_complete
    return future.result()
           ^^^^^^^^^^^^^^^
  File "d:\Develop\Python\trade_bot\11.9.1\main.py", line 116, in main
    await task_manager.wait("orchestrator")
  File "d:\Develop\Python\trade_bot\11.9.1\core\task_manager.py", line 108, in wait
    await task
  File "d:\Develop\Python\trade_bot\11.9.1\core\orchestrator.py", line 154, in run
    await asyncio.sleep(self.poll_interval)
  File "C:\Users\Professional\AppData\Local\Programs\Python\Python312\Lib\asyncio\tasks.py", line 665, in sleep
    return await future
           ^^^^^^^^^^^^
asyncio.exceptions.CancelledError

During handling of the above exception, another exception occurred:

Traceback (most recent call last):
  File "d:\Develop\Python\trade_bot\11.9.1\main.py", line 174, in <module>
    asyncio.run(main())
  File "C:\Users\Professional\AppData\Local\Programs\Python\Python312\Lib\asyncio\runners.py", line 193, in run
    with Runner(debug=debug, loop_factory=loop_factory) as runner:
  File "C:\Users\Professional\AppData\Local\Programs\Python\Python312\Lib\asyncio\runners.py", line 62, in __exit__
    self.close()
  File "C:\Users\Professional\AppData\Local\Programs\Python\Python312\Lib\asyncio\runners.py", line 70, in close
    _cancel_all_tasks(loop)
  File "C:\Users\Professional\AppData\Local\Programs\Python\Python312\Lib\asyncio\runners.py", line 203, in _cancel_all_tasks
    task.cancel()
  File "C:\Users\Professional\AppData\Local\Programs\Python\Python312\Lib\asyncio\tasks.py", line 721, in cancel
    if child.cancel(msg=msg):
       ^^^^^^^^^^^^^^^^^^^^^
  File "C:\Users\Professional\AppData\Local\Programs\Python\Python312\Lib\asyncio\tasks.py", line 721, in cancel
    if child.cancel(msg=msg):
       ^^^^^^^^^^^^^^^^^^^^^
  File "C:\Users\Professional\AppData\Local\Programs\Python\Python312\Lib\asyncio\tasks.py", line 721, in cancel
    if child.cancel(msg=msg):
       ^^^^^^^^^^^^^^^^^^^^^
  [Previous line repeated 992 more times]
RecursionError: maximum recursion depth exceeded
[17-08  00:09:41] ERROR bot [mode=LOOP] : Loop-level exception
[17-08  00:16:02] ERROR bot [mode=MAIN] : 💥 Fatal error: maximum recursion depth exceeded
Traceback (most recent call last):
  File "C:\Users\Professional\AppData\Local\Programs\Python\Python312\Lib\asyncio\runners.py", line 194, in run
    return runner.run(main)
           ^^^^^^^^^^^^^^^^
  File "C:\Users\Professional\AppData\Local\Programs\Python\Python312\Lib\asyncio\runners.py", line 118, in run
    return self._loop.run_until_complete(task)
           ^^^^^^^^^^^^^^^^^^^^^^^^^^^^^^^^^^^
  File "C:\Users\Professional\AppData\Local\Programs\Python\Python312\Lib\asyncio\base_events.py", line 687, in run_until_complete
    return future.result()
           ^^^^^^^^^^^^^^^
  File "d:\Develop\Python\trade_bot\11.9.1\main.py", line 116, in main
    await task_manager.wait("orchestrator")
  File "d:\Develop\Python\trade_bot\11.9.1\core\task_manager.py", line 108, in wait
    await task
  File "d:\Develop\Python\trade_bot\11.9.1\core\orchestrator.py", line 154, in run
    await asyncio.sleep(self.poll_interval)
  File "C:\Users\Professional\AppData\Local\Programs\Python\Python312\Lib\asyncio\tasks.py", line 665, in sleep
    return await future
           ^^^^^^^^^^^^
asyncio.exceptions.CancelledError

During handling of the above exception, another exception occurred:

Traceback (most recent call last):
  File "d:\Develop\Python\trade_bot\11.9.1\main.py", line 174, in <module>
    asyncio.run(main())
  File "C:\Users\Professional\AppData\Local\Programs\Python\Python312\Lib\asyncio\runners.py", line 193, in run
    with Runner(debug=debug, loop_factory=loop_factory) as runner:
  File "C:\Users\Professional\AppData\Local\Programs\Python\Python312\Lib\asyncio\runners.py", line 62, in __exit__
    self.close()
  File "C:\Users\Professional\AppData\Local\Programs\Python\Python312\Lib\asyncio\runners.py", line 70, in close
    _cancel_all_tasks(loop)
  File "C:\Users\Professional\AppData\Local\Programs\Python\Python312\Lib\asyncio\runners.py", line 203, in _cancel_all_tasks
    task.cancel()
  File "C:\Users\Professional\AppData\Local\Programs\Python\Python312\Lib\asyncio\tasks.py", line 721, in cancel
    if child.cancel(msg=msg):
       ^^^^^^^^^^^^^^^^^^^^^
  File "C:\Users\Professional\AppData\Local\Programs\Python\Python312\Lib\asyncio\tasks.py", line 721, in cancel
    if child.cancel(msg=msg):
       ^^^^^^^^^^^^^^^^^^^^^
  File "C:\Users\Professional\AppData\Local\Programs\Python\Python312\Lib\asyncio\tasks.py", line 721, in cancel
    if child.cancel(msg=msg):
       ^^^^^^^^^^^^^^^^^^^^^
  [Previous line repeated 992 more times]
RecursionError: maximum recursion depth exceeded
[17-08  00:16:03] ERROR bot [mode=LOOP] : Loop-level exception
[17-08  00:30:14] ERROR bot [mode=MAIN] : 💥 Fatal error: maximum recursion depth exceeded
Traceback (most recent call last):
  File "C:\Users\Professional\AppData\Local\Programs\Python\Python312\Lib\asyncio\runners.py", line 194, in run
    return runner.run(main)
           ^^^^^^^^^^^^^^^^
  File "C:\Users\Professional\AppData\Local\Programs\Python\Python312\Lib\asyncio\runners.py", line 118, in run
    return self._loop.run_until_complete(task)
           ^^^^^^^^^^^^^^^^^^^^^^^^^^^^^^^^^^^
  File "C:\Users\Professional\AppData\Local\Programs\Python\Python312\Lib\asyncio\base_events.py", line 687, in run_until_complete
    return future.result()
           ^^^^^^^^^^^^^^^
  File "d:\Develop\Python\trade_bot\11.9.1\main.py", line 117, in main
    await task_manager.wait("orchestrator")
  File "d:\Develop\Python\trade_bot\11.9.1\core\task_manager.py", line 108, in wait
    if task:
        ^^^^^
  File "d:\Develop\Python\trade_bot\11.9.1\core\orchestrator.py", line 154, in run
    await asyncio.sleep(self.poll_interval)
  File "C:\Users\Professional\AppData\Local\Programs\Python\Python312\Lib\asyncio\tasks.py", line 665, in sleep
    return await future
           ^^^^^^^^^^^^
asyncio.exceptions.CancelledError

During handling of the above exception, another exception occurred:

Traceback (most recent call last):
  File "d:\Develop\Python\trade_bot\11.9.1\main.py", line 175, in <module>
    asyncio.run(main())
  File "C:\Users\Professional\AppData\Local\Programs\Python\Python312\Lib\asyncio\runners.py", line 193, in run
    with Runner(debug=debug, loop_factory=loop_factory) as runner:
  File "C:\Users\Professional\AppData\Local\Programs\Python\Python312\Lib\asyncio\runners.py", line 62, in __exit__
    self.close()
  File "C:\Users\Professional\AppData\Local\Programs\Python\Python312\Lib\asyncio\runners.py", line 70, in close
    _cancel_all_tasks(loop)
  File "C:\Users\Professional\AppData\Local\Programs\Python\Python312\Lib\asyncio\runners.py", line 203, in _cancel_all_tasks
    task.cancel()
  File "C:\Users\Professional\AppData\Local\Programs\Python\Python312\Lib\asyncio\tasks.py", line 721, in cancel
    if child.cancel(msg=msg):
       ^^^^^^^^^^^^^^^^^^^^^
  File "C:\Users\Professional\AppData\Local\Programs\Python\Python312\Lib\asyncio\tasks.py", line 721, in cancel
    if child.cancel(msg=msg):
       ^^^^^^^^^^^^^^^^^^^^^
  File "C:\Users\Professional\AppData\Local\Programs\Python\Python312\Lib\asyncio\tasks.py", line 721, in cancel
    if child.cancel(msg=msg):
       ^^^^^^^^^^^^^^^^^^^^^
  [Previous line repeated 992 more times]
RecursionError: maximum recursion depth exceeded
[17-08  00:30:14] ERROR bot [mode=LOOP] : Loop-level exception
[17-08  00:33:09] ERROR bot [mode=MAIN] : 💥 Fatal error: maximum recursion depth exceeded
Traceback (most recent call last):
  File "C:\Users\Professional\AppData\Local\Programs\Python\Python312\Lib\asyncio\runners.py", line 194, in run
    return runner.run(main)
           ^^^^^^^^^^^^^^^^
  File "C:\Users\Professional\AppData\Local\Programs\Python\Python312\Lib\asyncio\runners.py", line 118, in run
    return self._loop.run_until_complete(task)
           ^^^^^^^^^^^^^^^^^^^^^^^^^^^^^^^^^^^
  File "C:\Users\Professional\AppData\Local\Programs\Python\Python312\Lib\asyncio\base_events.py", line 687, in run_until_complete
    return future.result()
           ^^^^^^^^^^^^^^^
  File "d:\Develop\Python\trade_bot\11.9.1\main.py", line 117, in main
    await task_manager.wait("orchestrator")
  File "d:\Develop\Python\trade_bot\11.9.1\core\task_manager.py", line 109, in wait
  File "d:\Develop\Python\trade_bot\11.9.1\core\orchestrator.py", line 154, in run
    await asyncio.sleep(self.poll_interval)
  File "C:\Users\Professional\AppData\Local\Programs\Python\Python312\Lib\asyncio\tasks.py", line 665, in sleep
    return await future
           ^^^^^^^^^^^^
asyncio.exceptions.CancelledError

During handling of the above exception, another exception occurred:

Traceback (most recent call last):
  File "d:\Develop\Python\trade_bot\11.9.1\main.py", line 175, in <module>
    asyncio.run(main())
  File "C:\Users\Professional\AppData\Local\Programs\Python\Python312\Lib\asyncio\runners.py", line 193, in run
    with Runner(debug=debug, loop_factory=loop_factory) as runner:
  File "C:\Users\Professional\AppData\Local\Programs\Python\Python312\Lib\asyncio\runners.py", line 62, in __exit__
    self.close()
  File "C:\Users\Professional\AppData\Local\Programs\Python\Python312\Lib\asyncio\runners.py", line 70, in close
    _cancel_all_tasks(loop)
  File "C:\Users\Professional\AppData\Local\Programs\Python\Python312\Lib\asyncio\runners.py", line 203, in _cancel_all_tasks
    task.cancel()
  File "C:\Users\Professional\AppData\Local\Programs\Python\Python312\Lib\asyncio\tasks.py", line 721, in cancel
    if child.cancel(msg=msg):
       ^^^^^^^^^^^^^^^^^^^^^
  File "C:\Users\Professional\AppData\Local\Programs\Python\Python312\Lib\asyncio\tasks.py", line 721, in cancel
    if child.cancel(msg=msg):
       ^^^^^^^^^^^^^^^^^^^^^
  File "C:\Users\Professional\AppData\Local\Programs\Python\Python312\Lib\asyncio\tasks.py", line 721, in cancel
    if child.cancel(msg=msg):
       ^^^^^^^^^^^^^^^^^^^^^
  [Previous line repeated 992 more times]
RecursionError: maximum recursion depth exceeded
[17-08  00:33:09] ERROR bot [mode=LOOP] : Loop-level exception
[17-08  00:57:51] ERROR bot [mode=MAIN] : 💥 Fatal error: maximum recursion depth exceeded
Traceback (most recent call last):
  File "C:\Users\Professional\AppData\Local\Programs\Python\Python312\Lib\asyncio\runners.py", line 194, in run
    return runner.run(main)
           ^^^^^^^^^^^^^^^^
  File "C:\Users\Professional\AppData\Local\Programs\Python\Python312\Lib\asyncio\runners.py", line 118, in run
    return self._loop.run_until_complete(task)
           ^^^^^^^^^^^^^^^^^^^^^^^^^^^^^^^^^^^
  File "C:\Users\Professional\AppData\Local\Programs\Python\Python312\Lib\asyncio\base_events.py", line 687, in run_until_complete
    return future.result()
           ^^^^^^^^^^^^^^^
  File "d:\Develop\Python\trade_bot\11.9.1\main.py", line 117, in main
    await task_manager.wait("orchestrator")
  File "d:\Develop\Python\trade_bot\11.9.1\core\task_manager.py", line 107, in wait
    await task
  File "d:\Develop\Python\trade_bot\11.9.1\core\orchestrator.py", line 154, in run
    await asyncio.sleep(self.poll_interval)
  File "C:\Users\Professional\AppData\Local\Programs\Python\Python312\Lib\asyncio\tasks.py", line 665, in sleep
    return await future
           ^^^^^^^^^^^^
asyncio.exceptions.CancelledError

During handling of the above exception, another exception occurred:

Traceback (most recent call last):
  File "d:\Develop\Python\trade_bot\11.9.1\main.py", line 175, in <module>
    asyncio.run(main())
  File "C:\Users\Professional\AppData\Local\Programs\Python\Python312\Lib\asyncio\runners.py", line 193, in run
    with Runner(debug=debug, loop_factory=loop_factory) as runner:
  File "C:\Users\Professional\AppData\Local\Programs\Python\Python312\Lib\asyncio\runners.py", line 62, in __exit__
    self.close()
  File "C:\Users\Professional\AppData\Local\Programs\Python\Python312\Lib\asyncio\runners.py", line 70, in close
    _cancel_all_tasks(loop)
  File "C:\Users\Professional\AppData\Local\Programs\Python\Python312\Lib\asyncio\runners.py", line 203, in _cancel_all_tasks
    task.cancel()
  File "C:\Users\Professional\AppData\Local\Programs\Python\Python312\Lib\asyncio\tasks.py", line 721, in cancel
    if child.cancel(msg=msg):
       ^^^^^^^^^^^^^^^^^^^^^
  File "C:\Users\Professional\AppData\Local\Programs\Python\Python312\Lib\asyncio\tasks.py", line 721, in cancel
    if child.cancel(msg=msg):
       ^^^^^^^^^^^^^^^^^^^^^
  File "C:\Users\Professional\AppData\Local\Programs\Python\Python312\Lib\asyncio\tasks.py", line 721, in cancel
    if child.cancel(msg=msg):
       ^^^^^^^^^^^^^^^^^^^^^
  [Previous line repeated 992 more times]
RecursionError: maximum recursion depth exceeded
[17-08  01:06:51] ERROR bot [mode=MAIN] : 💥 Fatal error: maximum recursion depth exceeded
Traceback (most recent call last):
  File "C:\Users\Professional\AppData\Local\Programs\Python\Python312\Lib\asyncio\runners.py", line 194, in run
    return runner.run(main)
           ^^^^^^^^^^^^^^^^
  File "C:\Users\Professional\AppData\Local\Programs\Python\Python312\Lib\asyncio\runners.py", line 118, in run
    return self._loop.run_until_complete(task)
           ^^^^^^^^^^^^^^^^^^^^^^^^^^^^^^^^^^^
  File "C:\Users\Professional\AppData\Local\Programs\Python\Python312\Lib\asyncio\base_events.py", line 687, in run_until_complete
    return future.result()
           ^^^^^^^^^^^^^^^
  File "d:\Develop\Python\trade_bot\11.9.1\main.py", line 117, in main
    await task_manager.wait("orchestrator")
  File "d:\Develop\Python\trade_bot\11.9.1\core\task_manager.py", line 107, in wait
    async def wait(self, name: str):
    ^^^^^^^^^^
  File "d:\Develop\Python\trade_bot\11.9.1\core\orchestrator.py", line 154, in run
    await asyncio.sleep(self.poll_interval)
  File "C:\Users\Professional\AppData\Local\Programs\Python\Python312\Lib\asyncio\tasks.py", line 665, in sleep
    return await future
           ^^^^^^^^^^^^
asyncio.exceptions.CancelledError

During handling of the above exception, another exception occurred:

Traceback (most recent call last):
  File "d:\Develop\Python\trade_bot\11.9.1\main.py", line 175, in <module>
    asyncio.run(main())
  File "C:\Users\Professional\AppData\Local\Programs\Python\Python312\Lib\asyncio\runners.py", line 193, in run
    with Runner(debug=debug, loop_factory=loop_factory) as runner:
  File "C:\Users\Professional\AppData\Local\Programs\Python\Python312\Lib\asyncio\runners.py", line 62, in __exit__
    self.close()
  File "C:\Users\Professional\AppData\Local\Programs\Python\Python312\Lib\asyncio\runners.py", line 70, in close
    _cancel_all_tasks(loop)
  File "C:\Users\Professional\AppData\Local\Programs\Python\Python312\Lib\asyncio\runners.py", line 203, in _cancel_all_tasks
    task.cancel()
  File "C:\Users\Professional\AppData\Local\Programs\Python\Python312\Lib\asyncio\tasks.py", line 721, in cancel
    if child.cancel(msg=msg):
       ^^^^^^^^^^^^^^^^^^^^^
  File "C:\Users\Professional\AppData\Local\Programs\Python\Python312\Lib\asyncio\tasks.py", line 721, in cancel
    if child.cancel(msg=msg):
       ^^^^^^^^^^^^^^^^^^^^^
  File "C:\Users\Professional\AppData\Local\Programs\Python\Python312\Lib\asyncio\tasks.py", line 721, in cancel
    if child.cancel(msg=msg):
       ^^^^^^^^^^^^^^^^^^^^^
  [Previous line repeated 992 more times]
RecursionError: maximum recursion depth exceeded
[17-08  01:12:08] ERROR bot [mode=MAIN] : 💥 Fatal error: maximum recursion depth exceeded
Traceback (most recent call last):
  File "C:\Users\Professional\AppData\Local\Programs\Python\Python312\Lib\asyncio\runners.py", line 194, in run
    return runner.run(main)
           ^^^^^^^^^^^^^^^^
  File "C:\Users\Professional\AppData\Local\Programs\Python\Python312\Lib\asyncio\runners.py", line 118, in run
    return self._loop.run_until_complete(task)
           ^^^^^^^^^^^^^^^^^^^^^^^^^^^^^^^^^^^
  File "C:\Users\Professional\AppData\Local\Programs\Python\Python312\Lib\asyncio\base_events.py", line 687, in run_until_complete
    return future.result()
           ^^^^^^^^^^^^^^^
  File "d:\Develop\Python\trade_bot\11.9.1\main.py", line 117, in main
    await task_manager.wait("orchestrator")
  File "d:\Develop\Python\trade_bot\11.9.1\core\task_manager.py", line 110, in wait
    await task
  File "d:\Develop\Python\trade_bot\11.9.1\core\orchestrator.py", line 154, in run
    await asyncio.sleep(self.poll_interval)
  File "C:\Users\Professional\AppData\Local\Programs\Python\Python312\Lib\asyncio\tasks.py", line 665, in sleep
    return await future
           ^^^^^^^^^^^^
asyncio.exceptions.CancelledError

During handling of the above exception, another exception occurred:

Traceback (most recent call last):
  File "d:\Develop\Python\trade_bot\11.9.1\main.py", line 175, in <module>
    asyncio.run(main())
  File "C:\Users\Professional\AppData\Local\Programs\Python\Python312\Lib\asyncio\runners.py", line 193, in run
    with Runner(debug=debug, loop_factory=loop_factory) as runner:
  File "C:\Users\Professional\AppData\Local\Programs\Python\Python312\Lib\asyncio\runners.py", line 62, in __exit__
    self.close()
  File "C:\Users\Professional\AppData\Local\Programs\Python\Python312\Lib\asyncio\runners.py", line 70, in close
    _cancel_all_tasks(loop)
  File "C:\Users\Professional\AppData\Local\Programs\Python\Python312\Lib\asyncio\runners.py", line 203, in _cancel_all_tasks
    task.cancel()
  File "C:\Users\Professional\AppData\Local\Programs\Python\Python312\Lib\asyncio\tasks.py", line 721, in cancel
    if child.cancel(msg=msg):
       ^^^^^^^^^^^^^^^^^^^^^
  File "C:\Users\Professional\AppData\Local\Programs\Python\Python312\Lib\asyncio\tasks.py", line 721, in cancel
    if child.cancel(msg=msg):
       ^^^^^^^^^^^^^^^^^^^^^
  File "C:\Users\Professional\AppData\Local\Programs\Python\Python312\Lib\asyncio\tasks.py", line 721, in cancel
    if child.cancel(msg=msg):
       ^^^^^^^^^^^^^^^^^^^^^
  [Previous line repeated 992 more times]
RecursionError: maximum recursion depth exceeded
[17-08  08:17:10] ERROR bot [mode=REST] : API error code=1 response={'code': '1', 'data': [{'algoClOrdId': '', 'algoId': '', 'clOrdId': '', 'sCode': '51277', 'sMsg': 'TP trigger price cannot be higher than the last price ', 'tag': ''}], 'msg': ''}
[17-08  08:17:10] ERROR bot [mode=-] : ❌ [TPSL] conditional failed for SDOGEUSDTSWAP: API error 1
[17-08  12:10:51] ERROR bot [mode=MAIN] : 💥 Fatal error: maximum recursion depth exceeded
Traceback (most recent call last):
  File "C:\Users\Professional\AppData\Local\Programs\Python\Python312\Lib\asyncio\runners.py", line 194, in run
    return runner.run(main)
           ^^^^^^^^^^^^^^^^
  File "C:\Users\Professional\AppData\Local\Programs\Python\Python312\Lib\asyncio\runners.py", line 118, in run
    return self._loop.run_until_complete(task)
           ^^^^^^^^^^^^^^^^^^^^^^^^^^^^^^^^^^^
  File "C:\Users\Professional\AppData\Local\Programs\Python\Python312\Lib\asyncio\base_events.py", line 687, in run_until_complete
    return future.result()
           ^^^^^^^^^^^^^^^
  File "d:\Develop\Python\trade_bot\11.9.1\main.py", line 117, in main
    await task_manager.wait("orchestrator")
  File "d:\Develop\Python\trade_bot\11.9.1\core\task_manager.py", line 110, in wait
    task = self._tasks.get(name)
        ^^^^^^^^^^
  File "d:\Develop\Python\trade_bot\11.9.1\core\orchestrator.py", line 154, in run
    await asyncio.sleep(self.poll_interval)
  File "C:\Users\Professional\AppData\Local\Programs\Python\Python312\Lib\asyncio\tasks.py", line 665, in sleep
    return await future
           ^^^^^^^^^^^^
asyncio.exceptions.CancelledError

During handling of the above exception, another exception occurred:

Traceback (most recent call last):
  File "d:\Develop\Python\trade_bot\11.9.1\main.py", line 175, in <module>
    asyncio.run(main())
  File "C:\Users\Professional\AppData\Local\Programs\Python\Python312\Lib\asyncio\runners.py", line 193, in run
    with Runner(debug=debug, loop_factory=loop_factory) as runner:
  File "C:\Users\Professional\AppData\Local\Programs\Python\Python312\Lib\asyncio\runners.py", line 62, in __exit__
    self.close()
  File "C:\Users\Professional\AppData\Local\Programs\Python\Python312\Lib\asyncio\runners.py", line 70, in close
    _cancel_all_tasks(loop)
  File "C:\Users\Professional\AppData\Local\Programs\Python\Python312\Lib\asyncio\runners.py", line 203, in _cancel_all_tasks
    task.cancel()
  File "C:\Users\Professional\AppData\Local\Programs\Python\Python312\Lib\asyncio\tasks.py", line 721, in cancel
    if child.cancel(msg=msg):
       ^^^^^^^^^^^^^^^^^^^^^
  File "C:\Users\Professional\AppData\Local\Programs\Python\Python312\Lib\asyncio\tasks.py", line 721, in cancel
    if child.cancel(msg=msg):
       ^^^^^^^^^^^^^^^^^^^^^
  File "C:\Users\Professional\AppData\Local\Programs\Python\Python312\Lib\asyncio\tasks.py", line 721, in cancel
    if child.cancel(msg=msg):
       ^^^^^^^^^^^^^^^^^^^^^
  [Previous line repeated 992 more times]
RecursionError: maximum recursion depth exceeded
[17-08  12:14:28] ERROR bot [mode=MAIN] : 💥 Fatal error: maximum recursion depth exceeded
Traceback (most recent call last):
  File "C:\Users\Professional\AppData\Local\Programs\Python\Python312\Lib\asyncio\runners.py", line 194, in run
    return runner.run(main)
           ^^^^^^^^^^^^^^^^
  File "C:\Users\Professional\AppData\Local\Programs\Python\Python312\Lib\asyncio\runners.py", line 118, in run
    return self._loop.run_until_complete(task)
           ^^^^^^^^^^^^^^^^^^^^^^^^^^^^^^^^^^^
  File "C:\Users\Professional\AppData\Local\Programs\Python\Python312\Lib\asyncio\base_events.py", line 687, in run_until_complete
    return future.result()
           ^^^^^^^^^^^^^^^
  File "d:\Develop\Python\trade_bot\11.9.1\main.py", line 117, in main
    await task_manager.wait("orchestrator")
  File "d:\Develop\Python\trade_bot\11.9.1\core\task_manager.py", line 112, in wait
    await task
  File "d:\Develop\Python\trade_bot\11.9.1\core\orchestrator.py", line 154, in run
    await asyncio.sleep(self.poll_interval)
  File "C:\Users\Professional\AppData\Local\Programs\Python\Python312\Lib\asyncio\tasks.py", line 665, in sleep
    return await future
           ^^^^^^^^^^^^
asyncio.exceptions.CancelledError

During handling of the above exception, another exception occurred:

Traceback (most recent call last):
  File "d:\Develop\Python\trade_bot\11.9.1\main.py", line 175, in <module>
    asyncio.run(main())
  File "C:\Users\Professional\AppData\Local\Programs\Python\Python312\Lib\asyncio\runners.py", line 193, in run
    with Runner(debug=debug, loop_factory=loop_factory) as runner:
  File "C:\Users\Professional\AppData\Local\Programs\Python\Python312\Lib\asyncio\runners.py", line 62, in __exit__
    self.close()
  File "C:\Users\Professional\AppData\Local\Programs\Python\Python312\Lib\asyncio\runners.py", line 70, in close
    _cancel_all_tasks(loop)
  File "C:\Users\Professional\AppData\Local\Programs\Python\Python312\Lib\asyncio\runners.py", line 203, in _cancel_all_tasks
    task.cancel()
  File "C:\Users\Professional\AppData\Local\Programs\Python\Python312\Lib\asyncio\tasks.py", line 721, in cancel
    if child.cancel(msg=msg):
       ^^^^^^^^^^^^^^^^^^^^^
  File "C:\Users\Professional\AppData\Local\Programs\Python\Python312\Lib\asyncio\tasks.py", line 721, in cancel
    if child.cancel(msg=msg):
       ^^^^^^^^^^^^^^^^^^^^^
  File "C:\Users\Professional\AppData\Local\Programs\Python\Python312\Lib\asyncio\tasks.py", line 721, in cancel
    if child.cancel(msg=msg):
       ^^^^^^^^^^^^^^^^^^^^^
  [Previous line repeated 992 more times]
RecursionError: maximum recursion depth exceeded
[17-08  12:16:16] ERROR bot [mode=MAIN] : 💥 Fatal error: maximum recursion depth exceeded
Traceback (most recent call last):
  File "C:\Users\Professional\AppData\Local\Programs\Python\Python312\Lib\asyncio\runners.py", line 194, in run
    return runner.run(main)
           ^^^^^^^^^^^^^^^^
  File "C:\Users\Professional\AppData\Local\Programs\Python\Python312\Lib\asyncio\runners.py", line 118, in run
    return self._loop.run_until_complete(task)
           ^^^^^^^^^^^^^^^^^^^^^^^^^^^^^^^^^^^
  File "C:\Users\Professional\AppData\Local\Programs\Python\Python312\Lib\asyncio\base_events.py", line 687, in run_until_complete
    return future.result()
           ^^^^^^^^^^^^^^^
  File "d:\Develop\Python\trade_bot\11.9.1\main.py", line 117, in main
    await task_manager.wait("orchestrator")
  File "d:\Develop\Python\trade_bot\11.9.1\core\task_manager.py", line 112, in wait
    await task
  File "d:\Develop\Python\trade_bot\11.9.1\core\orchestrator.py", line 154, in run
    await asyncio.sleep(self.poll_interval)
  File "C:\Users\Professional\AppData\Local\Programs\Python\Python312\Lib\asyncio\tasks.py", line 665, in sleep
    return await future
           ^^^^^^^^^^^^
asyncio.exceptions.CancelledError

During handling of the above exception, another exception occurred:

Traceback (most recent call last):
  File "d:\Develop\Python\trade_bot\11.9.1\main.py", line 175, in <module>
    asyncio.run(main())
  File "C:\Users\Professional\AppData\Local\Programs\Python\Python312\Lib\asyncio\runners.py", line 193, in run
    with Runner(debug=debug, loop_factory=loop_factory) as runner:
  File "C:\Users\Professional\AppData\Local\Programs\Python\Python312\Lib\asyncio\runners.py", line 62, in __exit__
    self.close()
  File "C:\Users\Professional\AppData\Local\Programs\Python\Python312\Lib\asyncio\runners.py", line 70, in close
    _cancel_all_tasks(loop)
  File "C:\Users\Professional\AppData\Local\Programs\Python\Python312\Lib\asyncio\runners.py", line 203, in _cancel_all_tasks
    task.cancel()
  File "C:\Users\Professional\AppData\Local\Programs\Python\Python312\Lib\asyncio\tasks.py", line 721, in cancel
    if child.cancel(msg=msg):
       ^^^^^^^^^^^^^^^^^^^^^
  File "C:\Users\Professional\AppData\Local\Programs\Python\Python312\Lib\asyncio\tasks.py", line 721, in cancel
    if child.cancel(msg=msg):
       ^^^^^^^^^^^^^^^^^^^^^
  File "C:\Users\Professional\AppData\Local\Programs\Python\Python312\Lib\asyncio\tasks.py", line 721, in cancel
    if child.cancel(msg=msg):
       ^^^^^^^^^^^^^^^^^^^^^
  [Previous line repeated 992 more times]
RecursionError: maximum recursion depth exceeded
