[15-08  17:58:14] ERROR bot [mode=REST] : HTTP 503 error: {"code":"50001","data":[],"inTime":"1755269893707081","msg":"Service temporarily unavailable. Please try again later.","outTime":"1755269893707137"}
[15-08  17:58:14] ERROR bot [mode=ORDER] : ❌ [OrderMode] place error: HTTP 503
[15-08  17:58:14] ERROR bot [mode=REST] : HTTP 503 error: {"code":"50001","data":[],"inTime":"1755269893961176","msg":"Service temporarily unavailable. Please try again later.","outTime":"1755269893961246"}
[15-08  17:58:25] ERROR bot [mode=REST] : HTTP 503 error: {"code":"50001","data":[],"inTime":"1755269904827663","msg":"Service temporarily unavailable. Please try again later.","outTime":"1755269904827810"}
[15-08  17:58:25] ERROR bot [mode=ORDER] : ❌ [OrderMode] place error: HTTP 503
[15-08  17:58:25] ERROR bot [mode=REST] : HTTP 503 error: {"code":"50001","data":[],"inTime":"1755269904848587","msg":"Service temporarily unavailable. Please try again later.","outTime":"1755269904848883"}
[15-08  17:58:36] ERROR bot [mode=REST] : HTTP 503 error: {"code":"50001","data":[],"inTime":"1755269915823786","msg":"Service temporarily unavailable. Please try again later.","outTime":"1755269915823837"}
[15-08  17:58:36] ERROR bot [mode=ORDER] : ❌ [OrderMode] place error: HTTP 503
[15-08  17:58:36] ERROR bot [mode=REST] : HTTP 503 error: {"code":"50001","data":[],"inTime":"1755269915863805","msg":"Service temporarily unavailable. Please try again later.","outTime":"1755269915863853"}
[15-08  17:59:38] ERROR bot [mode=REST] : HTTP 503 error: {"code":"50001","data":[],"inTime":"1755269977533439","msg":"Service temporarily unavailable. Please try again later.","outTime":"1755269977533485"}
[15-08  17:59:38] ERROR bot [mode=ORDER] : ❌ [OrderMode] place error: HTTP 503
[15-08  17:59:38] ERROR bot [mode=REST] : HTTP 503 error: {"code":"50001","data":[],"inTime":"1755269977877398","msg":"Service temporarily unavailable. Please try again later.","outTime":"1755269977877469"}
[15-08  18:00:24] ERROR bot [mode=REST] : HTTP 503 error: {"code":"50001","data":[],"inTime":"1755270023595960","msg":"Service temporarily unavailable. Please try again later.","outTime":"1755270023596047"}
[15-08  18:00:24] ERROR bot [mode=ORDER] : ❌ [OrderMode] place error: HTTP 503
[15-08  18:00:25] ERROR bot [mode=REST] : HTTP 503 error: {"code":"50001","data":[],"inTime":"1755270024463950","msg":"Service temporarily unavailable. Please try again later.","outTime":"1755270024464056"}
[15-08  18:59:48] ERROR bot [mode=REST] : API error code=1 response={'code': '1', 'data': [{'algoClOrdId': '', 'algoId': '', 'clOrdId': '', 'sCode': '51279', 'sMsg': 'TP trigger price cannot be lower than the last price ', 'tag': ''}], 'msg': ''}
[15-08  18:59:48] ERROR bot [mode=-] : ❌ [TPSL] conditional failed for LDOGEUSDTSWAP: API error 1
[15-08  19:12:30] ERROR bot [mode=REST] : API error code=1 response={'code': '1', 'data': [{'algoClOrdId': '', 'algoId': '', 'clOrdId': '', 'sCode': '51277', 'sMsg': 'TP trigger price cannot be higher than the last price ', 'tag': ''}], 'msg': ''}
[15-08  19:12:30] ERROR bot [mode=-] : ❌ [TPSL] conditional failed for SDOGEUSDTSWAP: API error 1
[15-08  19:12:37] ERROR bot [mode=REST] : API error code=1 response={'code': '1', 'data': [{'algoClOrdId': '', 'algoId': '', 'clOrdId': '', 'sCode': '51277', 'sMsg': 'TP trigger price cannot be higher than the last price ', 'tag': ''}], 'msg': ''}
[15-08  19:12:37] ERROR bot [mode=-] : ❌ [TPSL] conditional failed for SDOGEUSDTSWAP: API error 1
[15-08  19:12:44] ERROR bot [mode=REST] : API error code=1 response={'code': '1', 'data': [{'algoClOrdId': '', 'algoId': '', 'clOrdId': '', 'sCode': '51277', 'sMsg': 'TP trigger price cannot be higher than the last price ', 'tag': ''}], 'msg': ''}
[15-08  19:12:44] ERROR bot [mode=-] : ❌ [TPSL] conditional failed for SDOGEUSDTSWAP: API error 1
[15-08  19:12:50] ERROR bot [mode=REST] : API error code=1 response={'code': '1', 'data': [{'algoClOrdId': '', 'algoId': '', 'clOrdId': '', 'sCode': '51277', 'sMsg': 'TP trigger price cannot be higher than the last price ', 'tag': ''}], 'msg': ''}
[15-08  19:12:50] ERROR bot [mode=-] : ❌ [TPSL] conditional failed for SDOGEUSDTSWAP: API error 1
[15-08  19:12:57] ERROR bot [mode=REST] : API error code=1 response={'code': '1', 'data': [{'algoClOrdId': '', 'algoId': '', 'clOrdId': '', 'sCode': '51277', 'sMsg': 'TP trigger price cannot be higher than the last price ', 'tag': ''}], 'msg': ''}
[15-08  19:12:57] ERROR bot [mode=-] : ❌ [TPSL] conditional failed for SDOGEUSDTSWAP: API error 1
[15-08  19:13:04] ERROR bot [mode=REST] : API error code=1 response={'code': '1', 'data': [{'algoClOrdId': '', 'algoId': '', 'clOrdId': '', 'sCode': '51277', 'sMsg': 'TP trigger price cannot be higher than the last price ', 'tag': ''}], 'msg': ''}
[15-08  19:13:04] ERROR bot [mode=-] : ❌ [TPSL] conditional failed for SDOGEUSDTSWAP: API error 1
[15-08  19:13:11] ERROR bot [mode=REST] : API error code=1 response={'code': '1', 'data': [{'algoClOrdId': '', 'algoId': '', 'clOrdId': '', 'sCode': '51277', 'sMsg': 'TP trigger price cannot be higher than the last price ', 'tag': ''}], 'msg': ''}
[15-08  19:13:11] ERROR bot [mode=-] : ❌ [TPSL] conditional failed for SDOGEUSDTSWAP: API error 1
[15-08  21:12:47] ERROR bot [mode=-] : Критическая ошибка в оркестраторе: Session is closed
Traceback (most recent call last):
  File "d:\Develop\Python\trade_bot\11.9.1\main.py", line 131, in main
    await orchestration_task
  File "d:\Develop\Python\trade_bot\11.9.1\core\orchestrator.py", line 83, in run
    await self.snapshot.sync_from_rest()
  File "d:\Develop\Python\trade_bot\11.9.1\core\position_snapshot.py", line 45, in sync_from_rest
    await self._fetch_and_store()
  File "d:\Develop\Python\trade_bot\11.9.1\core\position_snapshot.py", line 115, in _fetch_and_store
    long_q, long_px = await self._rest_position("long")
                      ^^^^^^^^^^^^^^^^^^^^^^^^^^^^^^^^^
  File "d:\Develop\Python\trade_bot\11.9.1\core\position_snapshot.py", line 145, in _rest_position
    resp = await self.rest.request(
           ^^^^^^^^^^^^^^^^^^^^^^^^
  File "d:\Develop\Python\trade_bot\11.9.1\core\rest_client.py", line 206, in request
    async with self.session.request(
  File "C:\Users\Professional\AppData\Local\Programs\Python\Python312\Lib\site-packages\aiohttp\client.py", line 1360, in __aenter__
    self._resp: _RetType = await self._coro
                           ^^^^^^^^^^^^^^^^
  File "C:\Users\Professional\AppData\Local\Programs\Python\Python312\Lib\site-packages\aiohttp\client.py", line 493, in _request
    raise RuntimeError("Session is closed")
RuntimeError: Session is closed
[15-08  21:26:46] ERROR bot [mode=REST] : [TimeoutError] GET https://www.okx.com/api/v5/account/positions, attempt 1/4, sleeping 1.1s before retry
Traceback (most recent call last):
  File "C:\Users\Professional\AppData\Local\Programs\Python\Python312\Lib\site-packages\aiohttp\client.py", line 663, in _request
    conn = await self._connector.connect(
           ^^^^^^^^^^^^^^^^^^^^^^^^^^^^^^
  File "C:\Users\Professional\AppData\Local\Programs\Python\Python312\Lib\site-packages\aiohttp\connector.py", line 538, in connect
    proto = await self._create_connection(req, traces, timeout)
            ^^^^^^^^^^^^^^^^^^^^^^^^^^^^^^^^^^^^^^^^^^^^^^^^^^^
  File "C:\Users\Professional\AppData\Local\Programs\Python\Python312\Lib\site-packages\aiohttp\connector.py", line 1050, in _create_connection
    _, proto = await self._create_direct_connection(req, traces, timeout)
               ^^^^^^^^^^^^^^^^^^^^^^^^^^^^^^^^^^^^^^^^^^^^^^^^^^^^^^^^^^
  File "C:\Users\Professional\AppData\Local\Programs\Python\Python312\Lib\site-packages\aiohttp\connector.py", line 1353, in _create_direct_connection
    transp, proto = await self._wrap_create_connection(
                    ^^^^^^^^^^^^^^^^^^^^^^^^^^^^^^^^^^^
  File "C:\Users\Professional\AppData\Local\Programs\Python\Python312\Lib\site-packages\aiohttp\connector.py", line 1109, in _wrap_create_connection
    sock = await aiohappyeyeballs.start_connection(
           ^^^^^^^^^^^^^^^^^^^^^^^^^^^^^^^^^^^^^^^^
  File "C:\Users\Professional\AppData\Local\Programs\Python\Python312\Lib\site-packages\aiohappyeyeballs\impl.py", line 87, in start_connection
    sock, _, _ = await _staggered.staggered_race(
                 ^^^^^^^^^^^^^^^^^^^^^^^^^^^^^^^^
  File "C:\Users\Professional\AppData\Local\Programs\Python\Python312\Lib\site-packages\aiohappyeyeballs\_staggered.py", line 165, in staggered_race
    done = await _wait_one(
           ^^^^^^^^^^^^^^^^
  File "C:\Users\Professional\AppData\Local\Programs\Python\Python312\Lib\site-packages\aiohappyeyeballs\_staggered.py", line 46, in _wait_one
    return await wait_next
           ^^^^^^^^^^^^^^^
asyncio.exceptions.CancelledError

The above exception was the direct cause of the following exception:

Traceback (most recent call last):
  File "d:\Develop\Python\trade_bot\11.9.1\core\rest_client.py", line 206, in request
    async with self.session.request(
  File "C:\Users\Professional\AppData\Local\Programs\Python\Python312\Lib\site-packages\aiohttp\client.py", line 1360, in __aenter__
    self._resp: _RetType = await self._coro
                           ^^^^^^^^^^^^^^^^
  File "C:\Users\Professional\AppData\Local\Programs\Python\Python312\Lib\site-packages\aiohttp\client.py", line 578, in _request
    with timer:
  File "C:\Users\Professional\AppData\Local\Programs\Python\Python312\Lib\site-packages\aiohttp\helpers.py", line 749, in __exit__
    raise asyncio.TimeoutError from exc_val
TimeoutError
